Workbook

Sheet Instrucciones
B15: Objetivo: Identificar los insumos necesarios para pruebas de aceptación de usuario, a través de los casos de prueba, ambientes requeridos, especificación de los datos, cobertura de escenarios y atributos relacionados, a fin de contar con la integración de datos suficientes para la ejecución de las pruebas de la solución tecnológica con el usuario.
B17: Guía de Uso: 1.- Las pestañas "Casos de Prueba" y "Ambientes Requeridos" serán llenadas por la Administración Central de Soluciones de Negocio (ACSN), en la Fase Análisis, Etapa Especificación Funcional. 2.- Las pestañas "Interfaz de Usuario" y "Cobertura" serán llenadas en la Fase Desarrollo por las áreas ténicas que deban participar. En la primera también participará la ACSN en la Fase Pruebas, Etapa Pruebas Funcionales (AVL), por tema de Lineamientos Gráficos del SIAT, y para reflejar resultado de dichas pruebas. 3.- El documento está firmado por los responsables del llenado, incluyendo por el negocio cuando participa en la autorización. 4.- Si la pestaña "Casos de Prueba" incluye varias páginas, debe imprimirse sólo la página que contienen las firmas. Una vez firmado, debe digitalizarse y almacenarse en el repositorio como sustento junto con el archivo de Excel que corresponda a todo el documento. 5.- Si fuera necesario reservar información generada en esta plantilla, se hará bajo lo estipulado en la Ley General de Transparencia y Acceso a la Información Pública vigente (LGTAIP), pudiendo consultar a la ACPPI para su aplicación. (Ver abajo "Nota acerca de Irformación Reservada"). 6.- La aplicación de la sección de Firmas es opcional,dependiendo de las necesidades del consumidor, pero al contener temas de usuario de Negocio es importante la firma de éste.
B18: Nota acerca de Información Reservada Es reponsabilidad de cada requisitador la identificación de la información que se genere en este formato y así determinar si se cuenta con causas que originen la reserva de la misma, apegándose estrictamente a lo señalado en los ordenamientos jurídicos vigentes en materia de Transparencia. En caso de detectar información sensible (Reservada), se tendrá que indicar en la sección u hoja que lo amerite de este documento, en la parte inferior del texto, con la siguiente señalización: [Área dueña de la Información XX, clasificada como Reservada con Fundamento Legal XX, Motivación XX, Fecha de clasificación XX y Periodo de la reserva XX]. Ejemplo: "La información contenida en este documento pertenece a la Administración Central de Soluciones de Negocio, teniendo carácter de Reservada a partir del 01 de abril de 2018, con un periodo de reserva de 5 años, por tratarse de información que de revelarse puede causar un serio perjuicio a la recaudación de las contribuciones. Lo anterior tiene su fundamento en el artículo 113, fracción IV, de la Ley General de Transparencia y Acceso a la Información Pública."
B20: Hoja | D20: Descripción
B21: Casos de Prueba | D21: Esta hoja se utiliza para la documentación detallada de los casos de pruebas que serán utilizados en la ejecución de pruebas.
D22: Registra varios casos de prueba, con la finalidad de agrupar en un solo documento una cantidad suficiente de casos que pueda ser aprovechada para la importación de casos de prueba en alguna herramienta automatizada, o bien, para obtener de ella la información de casos de prueba. También se utiliza para especificar los elementos donde se emplearán los datos (Datos de Prueba)
D23: Criterios de Aceptación
D24: • El documento es utilizado de acuerdo al formato establecido. El documento cumple con el Marco Documental vigente. • El documento no contiene faltas de ortografía. • Cuando no se llene un renglón-columna, se deberá especificar el motivo por el cual no se registra la información, conteniendo al menos un "N/A". Ningún campo debe estar vacío. ●No se combinan celdas (exceptuando la sección de firmas) ●No incluye fórmulas en ningún renglón-columna • El documento describe detalladamente paso a paso las actividades a seguir para la validación de requerimientos del sistema. • El documento describe en cada paso una acción y una respuesta esperada que puede ser evaluada. El documento está firmado por los responsables del llenado, incluyendo por el negocio cuando participa en la autorización.
B26: Hoja | D26: Descripción
B27: Ambientes Requeridos | D27: Registra elementos de información sobre repositorios y ambientes necesarios para las pruebas y sus características, relacionadas con criterios que debe cubrir la información que se requiere para las pruebas; cantidad de datos requeridos para la ejecución de la prueba; datos o campos solicitados; condiciones que se deben cubrir para la extracción de datos y comentarios adicionales.
D28: Criterios de Aceptación
D29: * El documento es utilizado de acuerdo al formato establecido. * El documento cumple con el Marco Documental vigente. * El documento no contiene faltas de ortografía. * Cuando no se llene un renglón-columna, se deberá especificar el motivo por el cual no se registra la información, conteniendo al menos un "N/A". Ningún campo debe estar vacío. * El documento está firmado por los responsables del llenado, incluyendo por el negocio cuando participa en la autorización.
B31: Hoja | D31: Descripción
B32: Interfaz de Usuario | D32: Esta hoja aplica por la naturaleza de la solución tecnológica integrada que haya sido requerida. Se utiliza para validar que se cumplan los criterios definidos para la Interfaz de Usuario, incluyendo la aplicación y verificación de los Lineamientos Gráficos del SIAT, cuando sea el caso.
D33: Se detallan los puntos a validar de interfaz de usuario (interfaz gráfica) de las aplicaciones, como encabezados, pie de página, colores, alineación, etiquetas, listas desplegables, áreas de búsqueda, etc, etc.
D34: Criterios de Aceptación
D35: • El documento es utilizado de acuerdo al formato establecido. • El documento no contiene faltas de ortografía. • Cuando no se llene un renglón-columna, se deberá especificar el motivo por el cual no se registra la información. • Cada una de las características consideradas en esta pestaña estarán asociadas al contenido del artefacto "Especificación de Interacción de Usuario", en caso de ajustes o situaciones que expongan desviación al documento en comento, deberá ajustarse. • Cada defecto detectado deberá registrarse en la herramienta correspondiente para su atención y cierre.
B37: Hoja | D37: Descripción
B38: Cobertura | D38: Esta hoja se utiliza para identificar y detallar la cobertura de la prueba basada en complejidad ciclomática, para asegurar que se diseñen tantos casos de prueba como sean necesarios para que cada condición se ejecute al menos una vez con un valor verdadero, y al menos una vez uno falso.
D40: Criterios de Aceptación
D41: • El documento es utilizado de acuerdo al formato establecido. • El documento no contiene faltas de ortografía. • Cuando no se llene un renglón-columna, se deberá especificar el motivo por el cual no se registra la información. • El documento describe detalladamente los escenarios de prueba necesarios para que cada condición se ejecute al menos una vez con un valor verdadero y al menos una vez uno falso.
B43: Hoja | D43: Descripción
B44: Encabezado_Imagen | D44: En artefactos tipo Excel, la inserción del Encabezado como imagen en el mismo documento, puede hacerse como una alternativa cuando por la naturaleza y cantidad de información registrada en él, se hace necesario ampliar significativamente el tamaño de las celdas, ocasionando con ello distorsión o inadecuada distribución de la estructura del Encabezado del artefacto. Si ese fuera el caso, en esta hoja puede configurarse el Encabezado del artefacto y después insertarlo como imagen en cualquier otra sección del mismo, siguiendo las instrucciones allí descritas.
B46: Hoja | D46: Descripción
B47: Firmas Conformidad_Imagen | D47: En artefactos tipo Excel, la inserción de la Sección FIRMAS DE CONFORMIDAD como imagen en el mismo documento, puede hacerse como una alternativa cuando por la naturaleza y cantidad de información registrada en él, se hace necesario ampliar significativamente el tamaño de las celdas, ocasionando con ello distorsión o inadecuada distribución de la estructura de la sección de firmas localizada en la parte inferior del artefacto. Si ese fuera el caso, en esta hoja puede capturarse la información de las personas que participan en la elaboración y aprobación del artefacto, y después insertarla como imagen en cualquier otra sección del documento, siguiendo los pasos que allí se describen.

Sheet Versionamiento
B12: Tabla de Versiones y Modificaciones
B13: En la tabla siguiente se deben listar las versiones y descripciones hechas a este documento, desde el momento de su creación y cada vez que se llene y/o actualice alguna de sus pestañas. La descripción debe incluir una síntesis del cambio hecho.
B14: Para la Versión, especificar un número entero consecutivo, iniciando con 1 para la creación del documento e incrementar en decimales conforme se actualice (1.1, 1.2, 1.3, Etc.). Al terminarlo, especificar la versión final para firma, en caso necesario.
B15: Para futuros proyectos donde este documento se reutilice, el versionamiento reiniciará en versión 2, incrementando las actualizaciones igualmente con decimales (2.1, 2.2, 2.3, etc.). Posteriores reutilizaciones iniciarían entonces con versión 3, 4, etc.
C19: Versión | D19: Descripción del Cambio | E19: Responsable de la Versión | F19: Fecha
C20: 0.1 | D20: Creación del documento. | E20: Alma Quetzabeth Torres González | F20: 45604
C21: 0.2 | D21: Ajustes Se agregar "Recuperar descargas Detalle de consulta de incidencias" | E21: Alma Quetzabeth Torres González | F21: 45607
C22: 1 | D22: Versión aprobada para firma | E22: Alma Quetzabeth Torres González Mario Alberto Huerta Velázquez Roberto Benjamín Monroy Vargas

Sheet ListadoCP DTA
B10: Portal Consulta de Incidentes
B11: Casos de Prueba
B13: 1.- Seguridad
B14: CP01/Autenticación
B15: CP02/Autenticación_Cer_Key_Incorrecto
B16: CP03/Autenticación_Contraseña_Incorrecto
B17: CP04/Autenticacion_MSGError_Sin_Privilegios
B18: CP05/Autenticacion_MSGError_Certificado_Invalido
B19: CP06/Autenticacion_MSGError_E.firma_Revocada
B20: CP07/Autenticacion_ROL
B21: CP08/Cerrar Sesion
B23: 2.- DTA_Empleado
... B91: CP76/DTA/Reporte_Estadisticos/XMLcon Incidencia

Sheet ListadoCP DPA-DTA
B10: Portal Consulta de Incidentes
B11: Casos de Prueba
B13: 1.- Seguridad
B14: CP01/Autenticación
B15: CP02/Autenticación_Cer_Key_Incorrecto
B16: CP03/Autenticación_Contraseña_Incorrecto
B17: CP04/Autenticacion_MSGError_Sin_Privilegios
B18: CP05/Autenticacion_MSGError_Certificado_Invalido
B19: CP06/Autenticacion_MSGError_E.firma_Revocada
B20: CP07/Autenticacion_ROL
B21: CP08/Cerrar Sesion
B23: 2.- DPA_Empleado_Linea de Captura
... B248: CP227/DTA/Reporte_Estadisticos/XMLcon Incidencia

Sheet ListadoCP DPA
B10: Portal Consulta de Incidentes
B11: Casos de Prueba
B13: 1.- Seguridad
B14: CP01/Autenticación
B15: CP02/Autenticación_Cer_Key_Incorrecto
B16: CP03/Autenticación_Contraseña_Incorrecto
B17: CP04/Autenticacion_MSGError_Sin_Privilegios
B18: CP05/Autenticacion_MSGError_Certificado_Invalido
B19: CP06/Autenticacion_MSGError_E.firma_Revocada
B20: CP07/Autenticacion_ROL
B21: CP08/Cerrar Sesion
B23: 2.- DPA_Empleado_Linea de Captura
... B156: CP139/DPA/Reporte_Estadisticos/XMLcon Incidencia

Sheet Casos de Prueba
D10: Casos de Prueba
A12: Código del Aplicativo:
A13: ID de Requerimiento: | C13: 8211
A14: Nombre de Requerimiento: | C14: Consulta de incidentes registrado en recepción
A15: [Fase: Análisis] [Etapa: Especificación Funcional] (ACSN)
A17: ID del Caso | B17: CP | C17: Nombre del Caso | D17: Paso | E17: Descripción de Paso | F17: Resultado Esperado | G17: Comentarios | H17: Perfil de usuario para su ejecución | I17: Datos de Prueba | J17: Resultado
B18: CP01 | C18: /Autenticación
A19: POL_8211\Recepción_Consulta_Incidentes_CFDI | C19: /Autenticación | D19: 1 | E19: PAC abre explorador | H19: .PAC | I19: e.firma vigentes
A20: POL_8211\Recepción_Consulta_Incidentes_CFDI | C20: /Autenticación | D20: 2 | E20: PAC ingresa a la URL correspondiente al Portal | F20: Se muestran los datos para ingresar: Certificado (.cer) Clave privada (.Key) Contraseña de clave privada: Se muestra el campo RFC | G20: Se requiere que el PAC al ingresar al aplicativo cuente con una opción que le permita autenticarse mediante su e.firma para lo cual: • Se deberá visualizar el componente para el firmado electrónico, el cual debe apegarse a los lineamientos institucionales vigentes por el área de Seguridad del SAT. • Se solicitarán los archivos del certificado, clave privada y contraseña vigentes. • Se mostrarán los mensajes de validación de los campos proporcionados por el PAC conforme a los lineamientos institucionales vigentes por el área de Seguridad del SAT. El PAC debe tener asignado el rol | I20: El PAC debe tener asignado el rol
A21: POL_8211\Recepción_Consulta_Incidentes_CFDI | C21: /Autenticación | D21: 3 | E21: PAC da clic en buscar y selecciona el archivo correspondiente a su certificado | F21: Se muestra el dato en el campo certificado y en el campo RFC el dato del RFC del PAC
A22: POL_8211\Recepción_Consulta_Incidentes_CFDI | C22: /Autenticación | D22: 4 | E22: PAC da clic en buscar y selecciona el archivo correspondiente a su clave privada | F22: Se muestra el dato en el campo clave privada
A23: POL_8211\Recepción_Consulta_Incidentes_CFDI | C23: /Autenticación | D23: 5 | E23: PAC ingresa su contraseña | F23: Se muestra oculto el dato en el campo contraseña
A24: POL_8211\Recepción_Consulta_Incidentes_CFDI | C24: /Autenticación | D24: 6 | E24: Da clic en enviar | F24: Si la autenticación es correcta, el aplicativo abre la página principal del Portal Contribuyente con las opciones: - Consultar Facturas Emitidas - Consultar Facturas Recibidas - Recuperar Descargas de CFDI - Consultar Solicitudes de Cancelación - Consulta incidentes CFDI - Consulta incidentes CFDI Retenciones - Recuperar descargas Detalle de consulta de incidencias | G24: En caso de que el PAC no cuente con los permisos asignados conforme a los roles establecidos, el aplicativo mostrará el mensaje: “El PAC no cuenta con los privilegios de acceso” y no se va a permitir su acceso.
B25: CP02 | C25: /Autenticación_Cer_Key_Incorrecto
A26: POL_8211\Recepción_Consulta_Incidentes_CFDI | C26: /Autenticación_Cer_Key_Incorrecto | D26: 1 | E26: PAC abre explorador . | H26: .PAC | I26: e.firma vigentes
A27: POL_8211\Recepción_Consulta_Incidentes_CFDI | C27: /Autenticación_Cer_Key_Incorrecto | D27: 2 | E27: PAC ingresa a la URL correspondiente al Portal | F27: Se muestran los datos para ingresar: Certificado (.cer) Clave privada (.Key) Contraseña de clave privada: Se muestra el campo RFC | G27: Para efectos de este caso de prueba se requiere un archivo .cer o un archivo .Key sean incorrectos. | I27: El PAC debe tener asignado el rol Para efectos de este caso de prueba se requiere un archivo .cer o un archivo .Key sean incorrectos.
A28: POL_8211\Recepción_Consulta_Incidentes_CFDI | C28: /Autenticación_Cer_Key_Incorrecto | D28: 3 | E28: PAC da clic en buscar y selecciona el archivo correspondiente a su certificado | F28: Se muestra el dato en el campo certificado y en el campo RFC el dato del RFC del PAC
A29: POL_8211\Recepción_Consulta_Incidentes_CFDI | C29: /Autenticación_Cer_Key_Incorrecto | D29: 4 | E29: PAC da clic en buscar y selecciona el archivo correspondiente a su clave privada | F29: Se muestra el dato en el campo clave privada
A30: POL_8211\Recepción_Consulta_Incidentes_CFDI | C30: /Autenticación_Cer_Key_Incorrecto | D30: 5 | E30: PAC ingresa su contraseña | F30: Se muestra oculto el dato en el campo contraseña
A31: POL_8211\Recepción_Consulta_Incidentes_CFDI | C31: /Autenticación_Cer_Key_Incorrecto | D31: 6 | E31: Da clic en enviar | F31: El sistema muestra mensaje: El certificado no corresponde con la llave privada. Y no permite el acceso al Portal de Incidentes
B32: CP03 | C32: /Autenticación_Contraseña_Incorrecto
A33: POL_8211\Recepción_Consulta_Incidentes_CFDI | C33: /Autenticación_Contraseña_Incorrecto | D33: 1 | E33: PAC abre explorador | H33: .PAC | I33: e.firma vigentes
A34: POL_8211\Recepción_Consulta_Incidentes_CFDI | C34: /Autenticación_Contraseña_Incorrecto | D34: 2 | E34: PAC ingresa a la URL correspondiente al Portal | F34: Se muestran los datos para ingresar: Certificado (.cer) Clave privada (.Key) Contraseña de clave privada: Se muestra el campo RFC | G34: Para efectos de este caso de prueba se requiere ingresar una contraseña incorrecta. | I34: El PAC debe tener asignado el rol Para efectos de este caso de prueba se requiere ingresar una contraseña incorrecta.
A35: POL_8211\Recepción_Consulta_Incidentes_CFDI | C35: /Autenticación_Contraseña_Incorrecto | D35: 3 | E35: PAC da clic en buscar y selecciona el archivo correspondiente a su certificado | F35: Se muestra el dato en el campo certificado y en el campo RFC el dato del RFC del PAC
A36: POL_8211\Recepción_Consulta_Incidentes_CFDI | C36: /Autenticación_Contraseña_Incorrecto | D36: 4 | E36: PAC da clic en buscar y selecciona el archivo correspondiente a su clave privada | F36: Se muestra el dato en el campo clave privada
A37: POL_8211\Recepción_Consulta_Incidentes_CFDI | C37: /Autenticación_Contraseña_Incorrecto | D37: 5 | E37: PAC ingresa su contraseña incorrecta | F37: Se muestra oculto el dato en el campo contraseña
A38: POL_8211\Recepción_Consulta_Incidentes_CFDI | C38: /Autenticación_Contraseña_Incorrecto | D38: 6 | E38: Da clic en enviar | F38: El sistema muestra mensaje: Certificado, clave privada o contraseña de clave privada inválidos, inténtelo nuevamente.
B39: CP04 | C39: /Inactividad
A40: POL_8211\Recepción_Consulta_Incidentes_CFDI | C40: /Inactividad | D40: 1 | E40: PAC ingresa al Portal Contribuyente CFDI | F40: El sistema muestra las siguientes opciones: - Consultar Facturas Emitidas - Consultar Facturas Recibidas - Recuperar Descargas de CFDI - Consultar Solicitudes de Cancelación - Consulta incidentes CFDI - Consulta incidentes CFDI Retenciones -Recuperar descargas Detalle de consulta de incidencias’ | G40: El PAC previamente se autenticó y accedió al Portal Contribuyente CFDI | H40: .PAC | I40: e.firma vigentes El PAC debe tener asignado el rol Comprobante Fiscal CFDI versión 4.0
A41: POL_8211\Recepción_Consulta_Incidentes_CFDI | C41: /Inactividad | D41: 2 | E41: Da clic en "Consulta incidentes CFDI" | F41: El sistema muestra el RFC del PAC autenticado con la opción Salir. El sistema muestra las opciones: Tipo de consulta Lista desplegable (Opciones inhabilitadas) Folio Fiscal Por Fechas Fecha Inicial de Recepción* Fecha Final de Recepción* Versión del comprobante (Valor es por default 4.0) Botón "Consultar Incidentes"
A42: POL_8211\Recepción_Consulta_Incidentes_CFDI | C42: /Inactividad | D42: 3 | E42: Dejar la sesión abierta | F42: La sesión debe cerrarse de forma automática cuando esta se encuentre inactiva por el PAC y permanezca abierta en un plazo mayor a 10 minutos
B43: CP05 | C43: /Salir
A44: POL_8211\Recepción_Consulta_Incidentes_CFDI | C44: /Salir | D44: 1 | E44: PAC ingresa al Portal Contribuyente CFDI | F44: El sistema muestra las siguientes opciones: - Consultar Facturas Emitidas - Consultar Facturas Recibidas - Recuperar Descargas de CFDI - Consultar Solicitudes de Cancelación - Consulta incidentes CFDI - Consulta incidentes CFDI Retenciones -Recuperar descargas Detalle de consulta de incidencias’ | G44: El PAC previamente se autenticó y accedió al portal de Cancelaciones | H44: .PAC | I44: Comprobante Fiscal CFDI versión 4.0
A45: POL_8211\Recepción_Consulta_Incidentes_CFDI | C45: /Salir | D45: 2 | E45: Da clic en "Consulta Incidentes CFDI" | F45: El sistema muestra el RFC del PAC autenticado con la opción Salir. El sistema muestra las opciones: Tipo de consulta Lista desplegable (Opciones inhabilitadas) Folio Fiscal Por Fechas Fecha Inicial de Recepción* Fecha Final de Recepción* Versión del comprobante (Valor es por default 4.0) Botón "Consultar Incidentes"
A46: POL_8211\Recepción_Consulta_Incidentes_CFDI | C46: /Salir | D46: 3 | E46: Da clic en Salir | F46: Cierra la sesión del RFC
B47: CP06 | C47: /FolioFiscalConsulta
A48: POL_8211\Recepción_Consulta_Incidentes_CFDI | C48: /FolioFiscalConsulta | D48: 1 | E48: PAC ingresa al Portal Contribuyente CFDI | F48: El sistema muestra las siguientes opciones: - Consultar Facturas Emitidas - Consultar Facturas Recibidas - Recuperar Descargas de CFDI - Consultar Solicitudes de Cancelación - Consulta incidentes CFDI - Consulta incidentes CFDI Retenciones -Recuperar descargas Detalle de consulta de incidencias’ | G48: El PAC previamente se autenticó y accedió al portal Contribuyente CFDI | H48: .PAC | I48: e.firma vigentes El PAC debe tener asignado el rol Para este caso de prueba se requiere un Comprobante Fiscal CFDI versión 4.0
A49: POL_8211\Recepción_Consulta_Incidentes_CFDI | C49: /FolioFiscalConsulta | D49: 2 | E49: Da clic en "Consulta incidentes CFDI" | F49: El sistema muestra el RFC del PAC autenticado con la opción Salir. El sistema muestra las opciones: Tipo de consulta Lista desplegable (Opciones inhabilitadas) Folio Fiscal Por Fechas Fecha Inicial de Recepción* Fecha Final de Recepción* Versión del comprobante (Valor es por default 4.0) Botón "Consultar Incidentes" | G49: Al seleccionar esta opción el sistema permitirá la consulta de los registros de incidencias para los CFDI en su version 4.0 al momento de su envío por el servicio del SAT y proveedores autorizados
A50: POL_8211\Recepción_Consulta_Incidentes_CFDI | C50: /FolioFiscalConsulta | D50: 3 | E50: Selecciona en el campo "Tipo de Consulta": Incidentes Servicio de Recepción | F50: El sistema muestra el RFC del PAC autenticado con la opción Salir. Los campos marcados con (*) son obligatorios Tipo de consulta: Incidentes Servicio de Recepción Opción: Folio Fiscal Textbox: Folio Fiscal Digital* Opción: Por Fechas Tooltip Checkbox (Comprobantes Rechazados). Fecha Inicial de Recepción* Fecha Final de Recepción* Versión del comprobante (Valor es por default 4.0) Botón "Consultar Incidentes" | G50: Al seleccionar la opción por Folio Fiscal y al colocar el cursor en el tooltip “?” el sistema deberá mostrar el siguiente mensaje y el sistema aplicará lo que menciona el mismo: "En esta opción sólo se podrán visualizar las incidencias de los comprobantes que fueron recibidos".
A51: POL_8211\Recepción_Consulta_Incidentes_CFDI | C51: /FolioFiscalConsulta | D51: 4 | E51: Selecciona el campo Folio Fiscal e ingresa el UUID del comprobante del cual se desea conocer los incidentes registrados | F51: El sistema muestra los datos que se van ingresando
...

Sheet Devops
B19: Test Case | C19: =IF('Casos de Prueba'!B18<>0,'Casos de Prueba'!B18&"-"&'Casos de Prueba'!C18:E18,"") -> CP01-/Autenticación
C20: =IF('Casos de Prueba'!B19<>0,'Casos de Prueba'!B19&"-"&'Casos de Prueba'!C19:E19,"") | D20: =IF(LEN($C20)>0,"",'Casos de Prueba'!D19) -> 1 | E20: =IF(LEN($C20)>0,"",'Casos de Prueba'!E19) -> PAC abre explorador | F20: =IF(LEN($C20)>0,"",'Casos de Prueba'!F19&CHAR(10)&'Casos de Prueba'!G19)
A21: =LEN(E21) -> 46 | B21: =LEN(F21) -> 719 | C21: =IF('Casos de Prueba'!B20<>0,'Casos de Prueba'!B20&"-"&'Casos de Prueba'!C20:E20,"") | D21: =IF(LEN($C21)>0,"",'Casos de Prueba'!D20) -> 2 | E21: =IF(LEN($C21)>0,"",'Casos de Prueba'!E20) -> PAC ingresa a la URL correspondiente al Portal | F21: =IF(LEN($C21)>0,"",'Casos de Prueba'!F20&CHAR(10)&'Casos de Prueba'!G20) -> Se muestran los datos para ingresar: Certificado (.cer) Clave privada (.Key) Contraseña de clave privada: Se muestra el campo RFC Se requiere que el PAC al ingresar al aplicativo cuente con una opción que le permita autenticarse mediante su e.firma para lo cual: • Se deberá visualizar el componente para el firmado electrónico, el cual debe apegarse a los lineamientos institucionales vigentes por el área de Seguridad del SAT. • Se solicitarán los archivos del certificado, clave privada y contraseña vigentes. • Se mostrarán los mensajes de validación de los campos proporcionados por el PAC conforme a los lineamientos institucionales vigentes por el área de Seguridad del SAT. El PAC debe tener asignado el rol
A22: =LEN(E22) -> 78 | B22: =LEN(F22) -> 86 | C22: =IF('Casos de Prueba'!B21<>0,'Casos de Prueba'!B21&"-"&'Casos de Prueba'!C21:E21,"") | D22: =IF(LEN($C22)>0,"",'Casos de Prueba'!D21) -> 3 | E22: =IF(LEN($C22)>0,"",'Casos de Prueba'!E21) -> PAC da clic en buscar y selecciona el archivo correspondiente a su certificado | F22: =IF(LEN($C22)>0,"",'Casos de Prueba'!F21&CHAR(10)&'Casos de Prueba'!G21) -> Se muestra el dato en el campo certificado y en el campo RFC el dato del RFC del PAC
A23: =LEN(E23) -> 80 | B23: =LEN(F23) -> 45 | C23: =IF('Casos de Prueba'!B22<>0,'Casos de Prueba'!B22&"-"&'Casos de Prueba'!C22:E22,"") | D23: =IF(LEN($C23)>0,"",'Casos de Prueba'!D22) -> 4 | E23: =IF(LEN($C23)>0,"",'Casos de Prueba'!E22) -> PAC da clic en buscar y selecciona el archivo correspondiente a su clave privada | F23: =IF(LEN($C23)>0,"",'Casos de Prueba'!F22&CHAR(10)&'Casos de Prueba'!G22) -> Se muestra el dato en el campo clave privada
A24: =LEN(E24) -> 25 | B24: =LEN(F24) -> 49 | C24: =IF('Casos de Prueba'!B23<>0,'Casos de Prueba'!B23&"-"&'Casos de Prueba'!C23:E23,"") | D24: =IF(LEN($C24)>0,"",'Casos de Prueba'!D23) -> 5 | E24: =IF(LEN($C24)>0,"",'Casos de Prueba'!E23) -> PAC ingresa su contraseña | F24: =IF(LEN($C24)>0,"",'Casos de Prueba'!F23&CHAR(10)&'Casos de Prueba'!G23) -> Se muestra oculto el dato en el campo contraseña
A25: =LEN(E25) -> 17 | B25: =LEN(F25) -> 579 | C25: =IF('Casos de Prueba'!B24<>0,'Casos de Prueba'!B24&"-"&'Casos de Prueba'!C24:E24,"") | D25: =IF(LEN($C25)>0,"",'Casos de Prueba'!D24) -> 6 | E25: =IF(LEN($C25)>0,"",'Casos de Prueba'!E24) -> Da clic en enviar | F25: =IF(LEN($C25)>0,"",'Casos de Prueba'!F24&CHAR(10)&'Casos de Prueba'!G24) -> Si la autenticación es correcta, el aplicativo abre la página principal del Portal Contribuyente con las opciones: - Consultar Facturas Emitidas - Consultar Facturas Recibidas - Recuperar Descargas de CFDI - Consultar Solicitudes de Cancelación - Consulta incidentes CFDI - Consulta incidentes CFDI Retenciones - Recuperar descargas Detalle de consulta de incidencias En caso de que el PAC no cuente con los permisos asignados conforme a los roles establecidos, el aplicativo mostrará el mensaje: “El PAC no cuenta con los privilegios de acceso” y no se va a permitir su acceso.
A26: =LEN(E26) -> 0 | B26: =LEN(F26) -> 0 | C26: =IF('Casos de Prueba'!B25<>0,'Casos de Prueba'!B25&"-"&'Casos de Prueba'!C25:E25,"") -> CP02-/Autenticación_Cer_Key_Incorrecto | D26: =IF(LEN($C26)>0,"",'Casos de Prueba'!D25) | E26: =IF(LEN($C26)>0,"",'Casos de Prueba'!E25) | F26: =IF(LEN($C26)>0,"",'Casos de Prueba'!F25&CHAR(10)&'Casos de Prueba'!G25)
A27: =LEN(E27) -> 22 | B27: =LEN(F27) -> 1 | C27: =IF('Casos de Prueba'!B26<>0,'Casos de Prueba'!B26&"-"&'Casos de Prueba'!C26:E26,"") | D27: =IF(LEN($C27)>0,"",'Casos de Prueba'!D26) -> 1 | E27: =IF(LEN($C27)>0,"",'Casos de Prueba'!E26) -> PAC abre explorador . | F27: =IF(LEN($C27)>0,"",'Casos de Prueba'!F26&CHAR(10)&'Casos de Prueba'!G26)
A28: =LEN(E28) -> 46 | B28: =LEN(F28) -> 231 | C28: =IF('Casos de Prueba'!B27<>0,'Casos de Prueba'!B27&"-"&'Casos de Prueba'!C27:E27,"") | D28: =IF(LEN($C28)>0,"",'Casos de Prueba'!D27) -> 2 | E28: =IF(LEN($C28)>0,"",'Casos de Prueba'!E27) -> PAC ingresa a la URL correspondiente al Portal | F28: =IF(LEN($C28)>0,"",'Casos de Prueba'!F27&CHAR(10)&'Casos de Prueba'!G27) -> Se muestran los datos para ingresar: Certificado (.cer) Clave privada (.Key) Contraseña de clave privada: Se muestra el campo RFC Para efectos de este caso de prueba se requiere un archivo .cer o un archivo .Key sean incorrectos.
A29: =LEN(E29) -> 78 | B29: =LEN(F29) -> 86 | C29: =IF('Casos de Prueba'!B28<>0,'Casos de Prueba'!B28&"-"&'Casos de Prueba'!C28:E28,"") | D29: =IF(LEN($C29)>0,"",'Casos de Prueba'!D28) -> 3 | E29: =IF(LEN($C29)>0,"",'Casos de Prueba'!E28) -> PAC da clic en buscar y selecciona el archivo correspondiente a su certificado | F29: =IF(LEN($C29)>0,"",'Casos de Prueba'!F28&CHAR(10)&'Casos de Prueba'!G28) -> Se muestra el dato en el campo certificado y en el campo RFC el dato del RFC del PAC
A30: =LEN(E30) -> 80 | B30: =LEN(F30) -> 45 | C30: =IF('Casos de Prueba'!B29<>0,'Casos de Prueba'!B29&"-"&'Casos de Prueba'!C29:E29,"") | D30: =IF(LEN($C30)>0,"",'Casos de Prueba'!D29) -> 4 | E30: =IF(LEN($C30)>0,"",'Casos de Prueba'!E29) -> PAC da clic en buscar y selecciona el archivo correspondiente a su clave privada | F30: =IF(LEN($C30)>0,"",'Casos de Prueba'!F29&CHAR(10)&'Casos de Prueba'!G29) -> Se muestra el dato en el campo clave privada
A31: =LEN(E31) -> 25 | B31: =LEN(F31) -> 49 | C31: =IF('Casos de Prueba'!B30<>0,'Casos de Prueba'!B30&"-"&'Casos de Prueba'!C30:E30,"") | D31: =IF(LEN($C31)>0,"",'Casos de Prueba'!D30) -> 5 | E31: =IF(LEN($C31)>0,"",'Casos de Prueba'!E30) -> PAC ingresa su contraseña | F31: =IF(LEN($C31)>0,"",'Casos de Prueba'!F30&CHAR(10)&'Casos de Prueba'!G30) -> Se muestra oculto el dato en el campo contraseña
A32: =LEN(E32) -> 17 | B32: =LEN(F32) -> 127 | C32: =IF('Casos de Prueba'!B31<>0,'Casos de Prueba'!B31&"-"&'Casos de Prueba'!C31:E31,"") | D32: =IF(LEN($C32)>0,"",'Casos de Prueba'!D31) -> 6 | E32: =IF(LEN($C32)>0,"",'Casos de Prueba'!E31) -> Da clic en enviar | F32: =IF(LEN($C32)>0,"",'Casos de Prueba'!F31&CHAR(10)&'Casos de Prueba'!G31) -> El sistema muestra mensaje: El certificado no corresponde con la llave privada. Y no permite el acceso al Portal de Incidentes
... A102: =LEN(E102) -> 16 | B102: =LEN(F102) -> 37 | C102: =IF('Casos de Prueba'!B101<>0,'Casos de Prueba'!B101&"-"&'Casos de Prueba'!C101:E101,"") | D102: =IF(LEN($C102)>0,"",'Casos de Prueba'!D101) -> 5 | E102: =IF(LEN($C102)>0,"",'Casos de Prueba'!E101) -> Da clic en Salir | F102: =IF(LEN($C102)>0,"",'Casos de Prueba'!F101&CHAR(10)&'Casos de Prueba'!G101) -> Cierra la sesión del RFC Fin del caso
A103: =LEN(E103) -> #REF! | B103: =LEN(F103) -> #REF! | C103: =IF('Casos de Prueba'!#REF!<>0,'Casos de Prueba'!#REF!&"-"&_xlfn.SINGLE('Casos de Prueba'!#REF!),"") -> #REF! | D103: =IF(LEN($C103)>0,"",'Casos de Prueba'!#REF!) -> #REF! | E103: =IF(LEN($C103)>0,"",'Casos de Prueba'!#REF!) -> #REF! | F103: =IF(LEN($C103)>0,"",'Casos de Prueba'!#REF!&CHAR(10)&'Casos de Prueba'!#REF!) -> #REF!
A104: =LEN(E104) -> #REF! | B104: =LEN(F104) -> #REF! | C104: =IF('Casos de Prueba'!#REF!<>0,'Casos de Prueba'!#REF!&"-"&_xlfn.SINGLE('Casos de Prueba'!#REF!),"") -> #REF! | D104: =IF(LEN($C104)>0,"",'Casos de Prueba'!#REF!) -> #REF! | E104: =IF(LEN($C104)>0,"",'Casos de Prueba'!#REF!) -> #REF! | F104: =IF(LEN($C104)>0,"",'Casos de Prueba'!#REF!&CHAR(10)&'Casos de Prueba'!#REF!) -> #REF!
A105: =LEN(E105) -> #REF! | B105: =LEN(F105) -> #REF! | C105: =IF('Casos de Prueba'!#REF!<>0,'Casos de Prueba'!#REF!&"-"&_xlfn.SINGLE('Casos de Prueba'!#REF!),"") -> #REF! | D105: =IF(LEN($C105)>0,"",'Casos de Prueba'!#REF!) -> #REF! | E105: =IF(LEN($C105)>0,"",'Casos de Prueba'!#REF!) -> #REF! | F105: =IF(LEN($C105)>0,"",'Casos de Prueba'!#REF!&CHAR(10)&'Casos de Prueba'!#REF!) -> #REF!
A106: =LEN(E106) -> #REF! | B106: =LEN(F106) -> #REF! | C106: =IF('Casos de Prueba'!#REF!<>0,'Casos de Prueba'!#REF!&"-"&_xlfn.SINGLE('Casos de Prueba'!#REF!),"") -> #REF! | D106: =IF(LEN($C106)>0,"",'Casos de Prueba'!#REF!) -> #REF! | E106: =IF(LEN($C106)>0,"",'Casos de Prueba'!#REF!) -> #REF! | F106: =IF(LEN($C106)>0,"",'Casos de Prueba'!#REF!&CHAR(10)&'Casos de Prueba'!#REF!) -> #REF!
A107: =LEN(E107) -> #REF! | B107: =LEN(F107) -> #REF! | C107: =IF('Casos de Prueba'!#REF!<>0,'Casos de Prueba'!#REF!&"-"&_xlfn.SINGLE('Casos de Prueba'!#REF!),"") -> #REF! | D107: =IF(LEN($C107)>0,"",'Casos de Prueba'!#REF!) -> #REF! | E107: =IF(LEN($C107)>0,"",'Casos de Prueba'!#REF!) -> #REF! | F107: =IF(LEN($C107)>0,"",'Casos de Prueba'!#REF!&CHAR(10)&'Casos de Prueba'!#REF!) -> #REF!
A108: =LEN(E108) -> #REF! | B108: =LEN(F108) -> #REF! | C108: =IF('Casos de Prueba'!#REF!<>0,'Casos de Prueba'!#REF!&"-"&_xlfn.SINGLE('Casos de Prueba'!#REF!),"") -> #REF! | D108: =IF(LEN($C108)>0,"",'Casos de Prueba'!#REF!) -> #REF! | E108: =IF(LEN($C108)>0,"",'Casos de Prueba'!#REF!) -> #REF! | F108: =IF(LEN($C108)>0,"",'Casos de Prueba'!#REF!&CHAR(10)&'Casos de Prueba'!#REF!) -> #REF!
A109: =LEN(E109) -> 0 | B109: =LEN(F109) -> 0 | C109: =IF('Casos de Prueba'!B102<>0,'Casos de Prueba'!B102&"-"&'Casos de Prueba'!C102:E102,"") -> CP14-/FechaExportarPDF | D109: =IF(LEN($C109)>0,"",'Casos de Prueba'!D102) | E109: =IF(LEN($C109)>0,"",'Casos de Prueba'!E102) | F109: =IF(LEN($C109)>0,"",'Casos de Prueba'!F102&CHAR(10)&'Casos de Prueba'!G102)
A110: =LEN(E110) -> 40 | B110: =LEN(F110) -> 363 | C110: =IF('Casos de Prueba'!B103<>0,'Casos de Prueba'!B103&"-"&'Casos de Prueba'!C103:E103,"") | D110: =IF(LEN($C110)>0,"",'Casos de Prueba'!D103) -> 1 | E110: =IF(LEN($C110)>0,"",'Casos de Prueba'!E103) -> PAC ingresa al Portal Contribuyente CFDI | F110: =IF(LEN($C110)>0,"",'Casos de Prueba'!F103&CHAR(10)&'Casos de Prueba'!G103) -> El sistema muestra las siguientes opciones: - Consultar Facturas Emitidas - Consultar Facturas Recibidas - Recuperar Descargas de CFDI - Consultar Solicitudes de Cancelación - Consulta incidentes CFDI - Consulta incidentes CFDI Retenciones -Recuperar descargas Detalle de consulta de incidencias’ El PAC previamente se autenticó y accedió al portal de Incidentes
A111: =LEN(E111) -> 37 | B111: =LEN(F111) -> 321 | C111: =IF('Casos de Prueba'!B104<>0,'Casos de Prueba'!B104&"-"&'Casos de Prueba'!C104:E104,"") | D111: =IF(LEN($C111)>0,"",'Casos de Prueba'!D104) -> 2 | E111: =IF(LEN($C111)>0,"",'Casos de Prueba'!E104) -> Da clic en "Consulta incidentes CFDI" | F111: =IF(LEN($C111)>0,"",'Casos de Prueba'!F104&CHAR(10)&'Casos de Prueba'!G104) -> El sistema muestra el RFC del PAC autenticado con la opción Salir. El sistema muestra las opciones: Tipo de consulta Lista desplegable (Opciones inhabilitadas) Folio Fiscal Por Fechas Fecha Inicial de Recepción* Fecha Final de Recepción* Versión del comprobante (Valor es por default 4.0) Botón "Consultar Incidentes"
A112: =LEN(E112) -> 75 | B112: =LEN(F112) -> 795 | C112: =IF('Casos de Prueba'!B105<>0,'Casos de Prueba'!B105&"-"&'Casos de Prueba'!C105:E105,"") | D112: =IF(LEN($C112)>0,"",'Casos de Prueba'!D105) -> 3 | E112: =IF(LEN($C112)>0,"",'Casos de Prueba'!E105) -> Selecciona en el campo "Tipo de Consulta": Incidentes Servicio de Recepción | F112: =IF(LEN($C112)>0,"",'Casos de Prueba'!F105&CHAR(10)&'Casos de Prueba'!G105) -> El sistema muestra las opciones: Los campos marcados con (*) son obligatorios Tipo de consulta: Incidentes Servicio de Recepción Opción: Folio Fiscal Textbox: Folio Fiscal Digital* Opción: Por Fechas Tooltip Checkbox (Comprobantes Rechazados). Fecha Inicial de Recepción* Fecha Final de Recepción* Versión del comprobante (Valor es por default 4.0) Botón "Consultar Incidentes" Al seleccionar el botón para la consulta por periodo de fecha el sistema mostrará un Checkbox "Comprobantes Rechazados” y seleccionando esta opción solo se podrán visualizar los comprobantes que fueron rechazados por el servicio de recepción La consulta por fecha con el Checkbox desactivado, permitirá realizar solo la búsqueda de los comprobantes recibidos por el servicio de recepción Version por default 4.0
A113: =LEN(E113) -> 216 | B113: =LEN(F113) -> 406 | C113: =IF('Casos de Prueba'!B106<>0,'Casos de Prueba'!B106&"-"&'Casos de Prueba'!C106:E106,"") | D113: =IF(LEN($C113)>0,"",'Casos de Prueba'!D106) -> 4 | E113: =IF(LEN($C113)>0,"",'Casos de Prueba'!E106) -> Seleccionar la opcion Por Fechas y agregar los valores: Campo Fecha Inicial de Recepción* Campo Fecha Final de Recepción.* Los campos marcados con (*) son obligatorios Dar clic en el botón "Consultar Incidentes". | F113: =IF(LEN($C113)>0,"",'Casos de Prueba'!F106&CHAR(10)&'Casos de Prueba'!G106) -> El campo Folio Fiscal se deshabilita. El resultado de la consulta deberá mostrarse en una tabla con el título “Resultado de consulta” y la información: • RFC del PAC • Nombre o Razón Social • Evento • Mensaje • Total • Detalle (Boton) Importante mencionar que, el resultado se debe agrupar por tipo de error y presentarse de forma general, Campo "Versión del comprobante" por default tiene el valor 4.0
A114: =LEN(E114) -> 87 | B114: =LEN(F114) -> 701 | C114: =IF('Casos de Prueba'!B107<>0,'Casos de Prueba'!B107&"-"&'Casos de Prueba'!C107:E107,"") | D114: =IF(LEN($C114)>0,"",'Casos de Prueba'!D107) -> 5 | E114: =IF(LEN($C114)>0,"",'Casos de Prueba'!E107) -> De los resultados, se selecciona un registro y se da clic en el boton de "Ver detalle". | F114: =IF(LEN($C114)>0,"",'Casos de Prueba'!F107&CHAR(10)&'Casos de Prueba'!G107) -> El sistema muestra una subpantalla con la siguiente información: • RFC PAC: El RFC del PAC. • Nombre o Razón Social: La razón social del PAC. • Fecha incidente: La fecha de registro de incidente • Clave de evento: Número de evento • Evento: Descripción del evento que corresponde al incidente por el cual se recibió o rechazó el CFDI. Tabla: (Registros de Incidentes) o UUID: Folio Fiscal de los comprobantes asociados al incidente o Fecha de registro del incidente: Fecha en que se recibió el incidente.* Botones: .Exportar Detalle a PDF .Exportar Resultados a JSON El orden de los registros es ordenada por el valor del campo “Fecha de registro del incidente” del más reciente a los más antiguos.
A115: =LEN(E115) -> 45 | B115: =LEN(F115) -> 323 | C115: =IF('Casos de Prueba'!B108<>0,'Casos de Prueba'!B108&"-"&'Casos de Prueba'!C108:E108,"") | D115: =IF(LEN($C115)>0,"",'Casos de Prueba'!D108) -> 6 | E115: =IF(LEN($C115)>0,"",'Casos de Prueba'!E108) -> Dar clic en el botón "Exportar Detalle a PDF" | F115: =IF(LEN($C115)>0,"",'Casos de Prueba'!F108&CHAR(10)&'Casos de Prueba'!G108) -> Al seleccionar este botón se debe generar una petición de descarga para los registros de incidentes que se muestran en la ventana ‘Detalle de Consulta’ en formato JSON. A. Máximo 100 registros de incidencias. Al seleccionar el botón ‘Exportar Detalle a PDF se debe mostrar que el PDF se encuentra en proceso de descarga.
A116: =LEN(E116) -> 16 | B116: =LEN(F116) -> 37 | C116: =IF('Casos de Prueba'!B109<>0,'Casos de Prueba'!B109&"-"&'Casos de Prueba'!C109:E109,"") | D116: =IF(LEN($C116)>0,"",'Casos de Prueba'!D109) -> 7 | E116: =IF(LEN($C116)>0,"",'Casos de Prueba'!E109) -> Da clic en Salir | F116: =IF(LEN($C116)>0,"",'Casos de Prueba'!F109&CHAR(10)&'Casos de Prueba'!G109) -> Cierra la sesión del RFC Fin del caso
A117: =LEN(E117) -> 0 | B117: =LEN(F117) -> 0 | C117: =IF('Casos de Prueba'!B110<>0,'Casos de Prueba'!B110&"-"&'Casos de Prueba'!C110:E110,"") -> CP15-/FechaExportarJSON | D117: =IF(LEN($C117)>0,"",'Casos de Prueba'!D110) | E117: =IF(LEN($C117)>0,"",'Casos de Prueba'!E110) | F117: =IF(LEN($C117)>0,"",'Casos de Prueba'!F110&CHAR(10)&'Casos de Prueba'!G110)
A118: =LEN(E118) -> 40 | B118: =LEN(F118) -> 363 | C118: =IF('Casos de Prueba'!B111<>0,'Casos de Prueba'!B111&"-"&'Casos de Prueba'!C111:E111,"") | D118: =IF(LEN($C118)>0,"",'Casos de Prueba'!D111) -> 1 | E118: =IF(LEN($C118)>0,"",'Casos de Prueba'!E111) -> PAC ingresa al Portal Contribuyente CFDI | F118: =IF(LEN($C118)>0,"",'Casos de Prueba'!F111&CHAR(10)&'Casos de Prueba'!G111) -> El sistema muestra las siguientes opciones: - Consultar Facturas Emitidas - Consultar Facturas Recibidas - Recuperar Descargas de CFDI - Consultar Solicitudes de Cancelación - Consulta incidentes CFDI - Consulta incidentes CFDI Retenciones -Recuperar descargas Detalle de consulta de incidencias’ El PAC previamente se autenticó y accedió al portal de Incidentes
A119: =LEN(E119) -> 37 | B119: =LEN(F119) -> 321 | C119: =IF('Casos de Prueba'!B112<>0,'Casos de Prueba'!B112&"-"&'Casos de Prueba'!C112:E112,"") | D119: =IF(LEN($C119)>0,"",'Casos de Prueba'!D112) -> 2 | E119: =IF(LEN($C119)>0,"",'Casos de Prueba'!E112) -> Da clic en "Consulta incidentes CFDI" | F119: =IF(LEN($C119)>0,"",'Casos de Prueba'!F112&CHAR(10)&'Casos de Prueba'!G112) -> El sistema muestra el RFC del PAC autenticado con la opción Salir. El sistema muestra las opciones: Tipo de consulta Lista desplegable (Opciones inhabilitadas) Folio Fiscal Por Fechas Fecha Inicial de Recepción* Fecha Final de Recepción* Versión del comprobante (Valor es por default 4.0) Botón "Consultar Incidentes"
A120: =LEN(E120) -> 75 | B120: =LEN(F120) -> 795 | C120: =IF('Casos de Prueba'!B113<>0,'Casos de Prueba'!B113&"-"&'Casos de Prueba'!C113:E113,"") | D120: =IF(LEN($C120)>0,"",'Casos de Prueba'!D113) -> 3 | E120: =IF(LEN($C120)>0,"",'Casos de Prueba'!E113) -> Selecciona en el campo "Tipo de Consulta": Incidentes Servicio de Recepción | F120: =IF(LEN($C120)>0,"",'Casos de Prueba'!F113&CHAR(10)&'Casos de Prueba'!G113) -> El sistema muestra las opciones: Los campos marcados con (*) son obligatorios Tipo de consulta: Incidentes Servicio de Recepción Opción: Folio Fiscal Textbox: Folio Fiscal Digital* Opción: Por Fechas Tooltip Checkbox (Comprobantes Rechazados). Fecha Inicial de Recepción* Fecha Final de Recepción* Versión del comprobante (Valor es por default 4.0) Botón "Consultar Incidentes" Al seleccionar el botón para la consulta por periodo de fecha el sistema mostrará un Checkbox "Comprobantes Rechazados” y seleccionando esta opción solo se podrán visualizar los comprobantes que fueron rechazados por el servicio de recepción La consulta por fecha con el Checkbox desactivado, permitirá realizar solo la búsqueda de los comprobantes recibidos por el servicio de recepción Version por default 4.0
... A145: =LEN(E145) -> 40 | B145: =LEN(F145) -> 440 | C145: =IF('Casos de Prueba'!B138<>0,'Casos de Prueba'!B138&"-"&'Casos de Prueba'!C138:E138,"") | D145: =IF(LEN($C145)>0,"",'Casos de Prueba'!D138) -> 1 | E145: =IF(LEN($C145)>0,"",'Casos de Prueba'!E138) -> PAC ingresa al Portal Contribuyente CFDI | F145: =IF(LEN($C145)>0,"",'Casos de Prueba'!F138&CHAR(10)&'Casos de Prueba'!G138) -> El sistema muestra las siguientes opciones: - Consultar Facturas Emitidas - Consultar Facturas Recibidas - Recuperar Descargas de CFDI - Consultar Solicitudes de Cancelación - Consulta incidentes CFDI - Consulta incidentes CFDI Retenciones -Recuperar descargas Detalle de consulta de incidencias’ El PAC previamente se autenticó y accedió al portal de Incidentes Para este caso de prueba se requiere un Comprobante Fiscal CFDI versión 4.0
A146: =LEN(E146) -> 49 | B146: =LEN(F146) -> 578 | C146: =IF('Casos de Prueba'!B139<>0,'Casos de Prueba'!B139&"-"&'Casos de Prueba'!C139:E139,"") | D146: =IF(LEN($C146)>0,"",'Casos de Prueba'!D139) -> 2 | E146: =IF(LEN($C146)>0,"",'Casos de Prueba'!E139) -> Da clic en "Consulta Incidentes CFDI Retenciones" | F146: =IF(LEN($C146)>0,"",'Casos de Prueba'!F139&CHAR(10)&'Casos de Prueba'!G140) -> El sistema muestra el RFC del PAC autenticado con la opción Salir. El sistema muestra las opciones: Tipo de consulta Opciones inhabilitadas Folio Fiscal Por Fechas Fecha Inicial de Recepción* Fecha Final de Recepción* Versión del comprobante (Valor es por default 2.0) Botón "Consultar Incidentes" Al seleccionar la opción por Folio Fiscal y al colocar el cursor en el tooltip “?” el sistema deberá mostrar el siguiente mensaje y el sistema aplicará lo que menciona el mismo: "En esta opción sólo se podrán visualizar las incidencias de los comprobantes que fueron recibidos".
A147: =LEN(E147) -> 75 | B147: =LEN(F147) -> #REF! | C147: =IF('Casos de Prueba'!B140<>0,'Casos de Prueba'!B140&"-"&'Casos de Prueba'!C140:E140,"") | D147: =IF(LEN($C147)>0,"",'Casos de Prueba'!D140) -> 3 | E147: =IF(LEN($C147)>0,"",'Casos de Prueba'!E140) -> Selecciona en el campo "Tipo de Consulta": Incidentes Servicio de Recepción | F147: =IF(LEN($C147)>0,"",'Casos de Prueba'!F140&CHAR(10)&'Casos de Prueba'!#REF!) -> #REF!
A148: =LEN(E148) -> 140 | B148: =LEN(F148) -> 231 | C148: =IF('Casos de Prueba'!B141<>0,'Casos de Prueba'!B141&"-"&'Casos de Prueba'!C141:E141,"") | D148: =IF(LEN($C148)>0,"",'Casos de Prueba'!D141) -> 4 | E148: =IF(LEN($C148)>0,"",'Casos de Prueba'!E141) -> Selecciona el campo Folio Fiscal e ingresa el UUID del comprobante y es de tipo CFDI ver 4.0 y selecciona la opción "Consultar Incidentes". | F148: =IF(LEN($C148)>0,"",'Casos de Prueba'!F141&CHAR(10)&'Casos de Prueba'!G141) -> El aplicativo muestra el siguiente mensaje: “ERROR: El Folio Fiscal que desea consultar no se encuentra en la BD.”. Nota: Este mensaje de error aparece porque se quiere consultar un comprobante CFDI que no es de tipo Retenciones
A149: =LEN(E149) -> 16 | B149: =LEN(F149) -> 37 | C149: =IF('Casos de Prueba'!B142<>0,'Casos de Prueba'!B142&"-"&'Casos de Prueba'!C142:E142,"") | D149: =IF(LEN($C149)>0,"",'Casos de Prueba'!D142) -> 5 | E149: =IF(LEN($C149)>0,"",'Casos de Prueba'!E142) -> Da clic en Salir | F149: =IF(LEN($C149)>0,"",'Casos de Prueba'!F142&CHAR(10)&'Casos de Prueba'!G142) -> Cierra la sesión del RFC Fin del caso
A150: =LEN(E150) -> 0 | B150: =LEN(F150) -> 0 | C150: =IF('Casos de Prueba'!B143<>0,'Casos de Prueba'!B143&"-"&'Casos de Prueba'!C143:E143,"") -> CP20-/Retenciones/FolioFiscalExportarPDF | D150: =IF(LEN($C150)>0,"",'Casos de Prueba'!D143) | E150: =IF(LEN($C150)>0,"",'Casos de Prueba'!E143) | F150: =IF(LEN($C150)>0,"",'Casos de Prueba'!F143&CHAR(10)&'Casos de Prueba'!G143)
A151: =LEN(E151) -> 40 | B151: =LEN(F151) -> 452 | C151: =IF('Casos de Prueba'!B144<>0,'Casos de Prueba'!B144&"-"&'Casos de Prueba'!C144:E144,"") | D151: =IF(LEN($C151)>0,"",'Casos de Prueba'!D144) -> 1 | E151: =IF(LEN($C151)>0,"",'Casos de Prueba'!E144) -> PAC ingresa al Portal Contribuyente CFDI | F151: =IF(LEN($C151)>0,"",'Casos de Prueba'!F144&CHAR(10)&'Casos de Prueba'!G144) -> El sistema muestra las siguientes opciones: - Consultar Facturas Emitidas - Consultar Facturas Recibidas - Recuperar Descargas de CFDI - Consultar Solicitudes de Cancelación - Consulta incidentes CFDI - Consulta incidentes CFDI Retenciones -Recuperar descargas Detalle de consulta de incidencias’ El PAC previamente se autenticó y accedió al portal de Incidentes Para este caso de prueba se requiere un Comprobante Fiscal CFDI Retenciones versión 2.0
...

Sheet Devops_Carga
B1: Work Item type | C1: Title | D1: Test Step | E1: Step Action | F1: Step expected
B2: Test Case | C2: CP01-/Autenticación
D3: 1 | E3: PAC abre explorador
D4: 2 | E4: PAC ingresa a la URL correspondiente al Portal | F4: Se muestran los datos para ingresar: Certificado (.cer) Clave privada (.Key) Contraseña de clave privada: Se muestra el campo RFC Se requiere que el PAC al ingresar al aplicativo cuente con una opción que le permita autenticarse mediante su e.firma para lo cual: • Se deberá visualizar el componente para el firmado electrónico, el cual debe apegarse a los lineamientos institucionales vigentes por el área de Seguridad del SAT. • Se solicitarán los archivos del certificado, clave privada y contraseña vigentes. • Se mostrarán los mensajes de validación de los campos proporcionados por el PAC conforme a los lineamientos institucionales vigentes por el área de Seguridad del SAT. El PAC debe tener asignado el rol
D5: 3 | E5: PAC da clic en buscar y selecciona el archivo correspondiente a su certificado | F5: Se muestra el dato en el campo certificado y en el campo RFC el dato del RFC del PAC
D6: 4 | E6: PAC da clic en buscar y selecciona el archivo correspondiente a su clave privada | F6: Se muestra el dato en el campo clave privada
D7: 5 | E7: PAC ingresa su contraseña | F7: Se muestra oculto el dato en el campo contraseña
D8: 6 | E8: Da clic en enviar | F8: Si la autenticación es correcta, el aplicativo abre la página principal del Portal de Incidencias con las opciones: - Consulta incidentes CFDI - Consulta incidentes CFDI Retenciones En caso de que el PAC no cuente con los permisos asignados conforme a los roles establecidos, el aplicativo mostrará el mensaje: “El PAC no cuenta con los privilegios de acceso” y no se va a permitir su acceso.
C9: CP02-/Autenticación_Cer_Key_Incorrecto
D10: 1 | E10: PAC abre explorador .
D11: 2 | E11: PAC ingresa a la URL correspondiente al Portal | F11: Se muestran los datos para ingresar: Certificado (.cer) Clave privada (.Key) Contraseña de clave privada: Se muestra el campo RFC Para efectos de este caso de prueba se requiere un archivo .cer o un archivo .Key sean incorrectos.
D12: 3 | E12: PAC da clic en buscar y selecciona el archivo correspondiente a su certificado | F12: Se muestra el dato en el campo certificado y en el campo RFC el dato del RFC del PAC El PAC previamente se autenticó y accedió al portal
D13: 4 | E13: PAC da clic en buscar y selecciona el archivo correspondiente a su clave privada | F13: Se muestra el dato en el campo clave privada
D14: 5 | E14: PAC ingresa su contraseña | F14: Se muestra oculto el dato en el campo contraseña
D15: 6 | E15: Da clic en enviar | F15: El sistema muestra mensaje: El certificado no corresponde con la llave privada. Y no permite el acceso al Portal de Incidentes Se debe permitir el cierre de sesión de forma manual cuando el PAC seleccione la opción "cerrar sesión" y se debe redirigir la página al módulo de autenticación.
C16: CP03-/Autenticación_Contraseña_Incorrecto
D17: 1 | E17: PAC abre explorador
D18: 2 | E18: PAC ingresa a la URL correspondiente al Portal | F18: Se muestran los datos para ingresar: Certificado (.cer) Clave privada (.Key) Contraseña de clave privada: Se muestra el campo RFC Para efectos de este caso de prueba se requiere ingresar una contraseña incorrecta.
D19: 3 | E19: PAC da clic en buscar y selecciona el archivo correspondiente a su certificado | F19: Se muestra el dato en el campo certificado y en el campo RFC el dato del RFC del PAC
D20: 4 | E20: PAC da clic en buscar y selecciona el archivo correspondiente a su clave privada | F20: Se muestra el dato en el campo clave privada
D21: 5 | E21: PAC ingresa su contraseña incorrecta | F21: Se muestra oculto el dato en el campo contraseña
D22: 6 | E22: Da clic en enviar | F22: El sistema muestra mensaje: Certificado, clave privada o contraseña de clave privada inválidos, inténtelo nuevamente. Se debe permitir el cierre de sesión de forma manual cuando el PAC seleccione la opción "cerrar sesión" y se debe redirigir la página al módulo de autenticación.
C23: CP04-/Inactividad
D24: 1 | E24: PAC ingresa al Portal de Incidentes | F24: El sistema muestra las siguientes opciones: - Consulta incidentes CFDI - Consulta incidentes CFDI Retenciones -Recuperar descargas Detalle de consulta de incidencias’ El PAC previamente se autenticó y accedió al portal de Incidentes
D25: 2 | E25: Da clic en "Consulta incidentes CFDI" | F25: El sistema muestra el RFC del PAC autenticado con la opción Salir. El sistema muestra las opciones: .Tipo de consulta Opción: Folio Fiscal* Opción: Fecha .Fecha Inicial de Recepción* .Fecha Final de Recepción* .Versión del comprobante* Botón "Consultar Incidentes"
D26: 3 | E26: Dejar la sesión abierta | F26: La sesión debe cerrarse de forma automática cuando esta se encuentre inactiva por el PAC y permanezca abierta en un plazo mayor a 30 minutos, al cerrarse debe redirigir la página al Módulo de autentificación.
C27: CP05-/Salir
D28: 1 | E28: PAC ingresa al Portal de Incidentes | F28: El sistema muestra las siguientes opciones: - Consulta incidentes CFDI - Consulta incidentes CFDI Retenciones -Recuperar descargas Detalle de consulta de incidencias’ El PAC previamente se autenticó y accedió al portal de Cancelaciones
D29: 2 | E29: Da clic en "Consultar Facturas Emitidas" | F29: El sistema muestra el RFC del PAC autenticado con la opción Salir. El sistema muestra las opciones: .Tipo de consulta Opción: Folio Fiscal* Opción: Fecha .Fecha Inicial de Recepción* .Fecha Final de Recepción* .Versión del comprobante* Botón "Consultar Incidentes"
D30: 3 | E30: Da clic en Salir | F30: Cierra la sesión del RFC
C31: CP06-/FolioFiscalConsulta
D32: 1 | E32: PAC ingresa al Portal de Incidentes | F32: El sistema muestra las siguientes opciones: - Consulta incidentes CFDI - Consulta incidentes CFDI Retenciones -Recuperar descargas Detalle de consulta de incidencias’ El PAC previamente se autenticó y accedió al portal de Incidentes
D33: 2 | E33: Da clic en "Consulta incidentes CFDI" | F33: Al seleccionar esta opción el sistema permitirá la consulta de los registros de incidencias para los CFDI en sus versiones 3.3 y 4.0 al momento de su envío por el servicio del SAT y proveedores autorizados
D34: 3 | E34: Selecciona en el campo "Tipo de Consulta": Incidentes Servicio de Recepción | F34: El sistema muestra el RFC del PAC autenticado con la opción Salir. El sistema muestra las opciones: .Tipo de consulta Opción: Folio Fiscal* Opción: Fecha .Fecha Inicial de Recepción* .Fecha Final de Recepción* .Versión del comprobante* Botón "Consultar Incidentes" El campo Versión desplegará por default para CFDI la v4.0..
D35: 4 | E35: Selecciona el campo Folio Fiscal e ingresa el UUID del comprobante del cual se desea conocer los incidentes registrados | F35: El sistema muestra los datos que se van ingresando
D36: 5 | E36: Se da clic en el botón "Consultar Incidentes" | F36: El servicio inhabilita la sección de Fecha Inicial y Final de Recepción. El sistema deberá mostrar en una tabla los resultados obtenidos de la consulta: • RFC del PAC • Nombre o Razón Social • Evento • Mensaje • Total • Detalle (Link)
D37: 6 | E37: Da clic en Salir | F37: Cierra la sesión del RFC Fin del caso
C38: CP07-/MsgErrorConsultaCFDIVacío
D39: 1 | E39: PAC ingresa al Portal de Incidentes | F39: El sistema muestra las siguientes opciones: - Consulta incidentes CFDI - Consulta incidentes CFDI Retenciones -Recuperar descargas Detalle de consulta de incidencias’ El PAC previamente se autenticó y accedió al portal de Incidentes
D40: 2 | E40: Da clic en "Consulta incidentes CFDI" | F40: El sistema muestra el RFC del PAC autenticado con la opción Salir. El sistema muestra las opciones: .Tipo de consulta Opción: Folio Fiscal* Opción: Fecha .Fecha Inicial de Recepción* .Fecha Final de Recepción* .Versión del comprobante* Botón "Consultar Incidentes" Al seleccionar esta opción el sistema permitirá la consulta de los registros de incidencias para los CFDI en sus versiones 3.3 y 4.0 al momento de su envío por el servicio del SAT y proveedores autorizados
...

Sheet Firmas Conformidad
B2: El uso de la siguiente Sección de Firmas de Conformidad es opcional, dependiendo de la necesidad del consumidor de la información.
B3: Instrucciones:
B4: Registrar en la tabla la información de los participantes en la elaboración, revisión, aprobación, etc. del artefacto.
B8: FIRMAS DE CONFORMIDAD
B9: Autorizó | C9: Autorizó
B10: Nombre: Pedro López Bernal. | C10: Nombre: Diana Maribel Velazquez Barroso
B11: Puesto: Administrador de Gestión de Servicios y Trámites con Medios Electrónicos 3 | C11: Puesto: Administradora de Soluciones de Negocio 3
B12: Fecha: | C12: Fecha:
B13: ‍
B14: Revisó | C14: Revisó
B15: Nombre: Mario Alberto Huerta Velazquez | C15: Nombre: Roberto Benjamín Monroy Vargas
B16: Puesto: Subadministrador de Gestión de Servicios y Trámites con Medios Electrónicos | C16: Puesto: Subadministrador de Soluciones de Negocio
B17: Fecha: | C17: Fecha:
B19: Elaboró | C19: Elaboró
B20: Nombre: Nadia Anahí Ortega Nava | C20: Nombre: Alma Quetzabeth Torres González
B21: Puesto: Jefe de Departamento de Gestión de Servicios y Trámites con Medios Electrónicos | C21: Puesto: Jefe de Departamento de Soluciones de Negocio
B22: Fecha: | C22: Fecha:

Sheet Encabezado
C1: Tomar como referencia el siguiente Encabezado para edición:
H4: Administración General de Comunicaciones y Tecnologías de la Información
H6: Marco Documental 7.0
C7: Fecha de aprobación del Template: 01/11/2021 | E7: Requerimientos de Pruebas Clave del Documento XX_RDP_REQPRUEBAS.xlsx [Nomenclatura del artefacto, punto, extensión del archivo actual] Servicio Administración del Ciclo de Vida de Aplicaciones de TIC Central Dueña: Administración Central de Soluciones de Negocio (ACSN) Central que Elabora: ACSN Central Consumidora: ACDMA | J7: Versión del template: 7.00
H13: Administración General de Comunicaciones y Tecnologías de la Información
H15: Marco Documental 7.0
C16: Fecha de aprobación del Template: 01/11/2021 | E16: Requerimientos de Pruebas RDP-Consulta_Incidentes_PAC.xlsx | J16: Versión del template: 7.00
