Workbook

Sheet Versionamiento
B12: Tabla de Versiones y Modificaciones
B13: En la tabla siguiente se deben listar las versiones y descripciones hechas a este documento, desde el momento de su creación y cada vez que se llene y/o actualice alguna de sus pestañas. La descripción debe incluir una síntesis del cambio hecho.
B14: Para la Versión, especificar un número entero consecutivo, iniciando con 1 para la creación del documento e incrementar en decimales conforme se actualice (1.1, 1.2, 1.3, Etc.). Al terminarlo, especificar la versión final para firma, en caso necesario.
B15: Para futuros proyectos donde este documento se reutilice, el versionamiento reiniciará en versión 2, incrementando las actualizaciones igualmente con decimales (2.1, 2.2, 2.3, etc.). Posteriores reutilizaciones iniciarían entonces con versión 3, 4, etc.
C18: Versión | D18: Descripción del Cambio | E18: Responsable de la Versión | F18: Fecha
C19: 1 | D19: Creación del documento. | E19: Alma Q. Torres González | F19: 46112
C20: 1.1 | D20: Ajustes Se agrega Matriz de erorres CFDI | E20: Alma Q. Torres González | F20: 46121
C21: 2 | D21: Formalización de documento | E21: Roberto Benjamín Monroy Vargas Maria Luisa Flores Barron

Sheet Indice
A11: Indice | B11: Observaciones
A12: Matriz de errores para complemento Comercio Exterior 2.0 | B12: Matriz de errores para complemento Comercio Exterior 2.0
A13: Errores para CFDI versión 4.0 que incluye el complemento Comercio Exterior 2.0
A14: CP01-CFDI | B14: TipoDeComprobante CCE101
A15: CP02-CFDI | B15: TipoDeComprobante CCE102
A16: CP03-CFDI | B16: TipoDeComprobante CCE103
A17: CP04-CFDI | B17: Exportación CCE104
A18: CP05-CFDI | B18: Exportación CCE105
A19: CP06-CFDI | B19: InformacionGlobal
A20: CP07-CFDI | B20: Receptor:Rfc CCE107
A21: CP08-CFDI | B21: Receptor:Rfc CCE108
A22: CP09-CFDI | B22: Conceptos:Concepto:ObjetoImp CCE109
A23: CP10-CFDI | B23: Conceptos:Concepto:ObjetoImp CCE110
A24: CP11-CFDI | B24: AcuentaTerceros
A25: CP12-CFDI | B25: CuentaPredial
... A86: CP73-ComercioExterior | B86: Otro error
A88: Matriz de códigos de error del Complemento para Recepción de Pagos 2.0 Revisión B
A89: Códigos de error del comprobante base CFDI 4.0
A90: CP74-Comprobante | B90: TipoDeComprobante
A91: CP75-Comprobante | B91: Exportacion
A92: CP76-Comprobante | B92: SubTotal
A93: CP77-Comprobante | B93: Moneda
A94: CP78-Comprobante | B94: FormaPago
A95: CP79-Comprobante | B95: MetodoPago
A96: CP80-Comprobante | B96: CondicionesDePago
A97: CP81-Comprobante | B97: Descuento CRP20108
A98: CP82-Comprobante | B98: TipoCambio
A99: CP83-Comprobante | B99: Total
A100: CP84-cfdi:Conceptos/Concepto | B100: cfdi:Conceptos/Concepto CRP20111
A101: CP85-cfdi:Conceptos/Concepto | B101: cfdi:Conceptos/Concepto CRP20112
... A159: CP143-Pagos/pago10:Pago/pago10:DoctoRelacionado | B159: ObjetoImpDR CRP20247
A160: CP144-Pagos/pago10:Pago/pago10:DoctoRelacionado/ImpuestosDR
A161: CP145-Pagos/pago10:Pago/pago10:DoctoRelacionado/ImpuestosDR:RetencionesDR/RetencionDR | B161: BaseDR CRP20249
A162: CP146-Pagos/pago10:Pago/pago10:DoctoRelacionado/ImpuestosDR:RetencionesDR/RetencionDR | B162: ImpuestoDR CRP20250
A163: CP147-Pagos/pago10:Pago/pago10:DoctoRelacionado/ImpuestosDR:RetencionesDR/RetencionDR | B163: TipoFactorDR CRP20251
A164: CP148-Pagos/pago10:Pago/pago10:DoctoRelacionado/ImpuestosDR:RetencionesDR/RetencionDR | B164: TipoFactorDR CRP20252
A165: CP149-Pagos/pago10:Pago/pago10:DoctoRelacionado/ImpuestosDR:RetencionesDR/RetencionDR | B165: TasaOCuotaDR CRP20253
A166: CP150-Pagos/pago10:Pago/pago10:DoctoRelacionado/ImpuestosDR:RetencionesDR/RetencionDR | B166: ImporteDR CRP20254
A167: CP151-Pagos/pago10:Pago/pago10:DoctoRelacionado/ImpuestosDR:TrasladosDR/TrasladoDR | B167: BaseDR CRP20255
A168: CP152-Pagos/pago10:Pago/pago10:DoctoRelacionado/ImpuestosDR:TrasladosDR/TrasladoDR | B168: ImpuestoDR CRP20256
...

Sheet CP
E10: Casos de Prueba
A12: Código del Aplicativo: | D12: 611.2
A13: ID de Requerimiento: | D13: POL_8211
A14: Nombre de Requerimiento: | D14: Validaciones Adicionales con el Complemento Complemento Comercio Exterior y Complemento para Recepción de Pagos 2.0
A18: ID del Caso | B18: CP | C18: Nombre del Caso | D18: Paso | E18: Descripción de Paso | F18: Resultado Esperado | G18: Comentarios | H18: Perfil de usuario para su ejecución | I18: Datos de Prueba | J18: Resultado
A19: POL_8211\CC066_Validaciones_CE_Comprobante | B19: CP01-CFDI | C19: TipoDeComprobante CCE101 | D19: 1 | E19: Este atributo puede tener los valores "I", "E" o "T". Los XML para probar el mensaje esperado de error son con el código de error: CCE101 El servicio será invocado: .Entes publicos .Servicios Gratuitos de Facturación | F19: El resultado esperado: El atributo cfdi:Comprobante:TipoDeComprobante no cumple con alguno de los valores permitidos para este complemento. En caso de error: La respuesta de los mensajes viene en el archivo de Response del XML con marcado en los campos de la estructura: <CodigoError> <MensajeIncidencia> Para esta prueba se espera la respuesta de los códigos de error: CCE101 | G19: Los mensajes de error se encuentran en el archivo anexo Matriz_de_Errores_CCE_v2 Columna E - CÓDIGO ERROR Columna F - ERROR ver pestaña "Anexos" | I19: Se debe contar con la siguiente información: CFDI 4.0 con Complemento Comercio Exterior
A20: POL_8211\CC066_Validaciones_CE_Comprobante | B20: CP02-CFDI | C20: TipoDeComprobante CCE102 | D20: 1 | E20: Si el valor es "T", se debe registrar el atributo MotivoTraslado y, si el MotivoTraslado tiene la clave "05", se debe registrar el nodo Propietario. Los XML para probar el mensaje esperado de error son con el código de error: CCE102 El servicio será invocado: .Entes publicos .Servicios Gratuitos de Facturación | F20: El resultado esperado: El nodo Propietario se debe registrar cuando el atributo cfdi:Comprobante:TipoDeComprobante tiene el valor "T" y MotivoTraslado tiene la clave "05". En caso de error: La respuesta de los mensajes viene en el archivo de Response del XML con marcado en los campos de la estructura: <CodigoError> <MensajeIncidencia> Para esta prueba se espera la respuesta de los códigos de error: CCE102 | G20: Los mensajes de error se encuentran en el archivo anexo Matriz_de_Errores_CCE_v2 Columna E - CÓDIGO ERROR Columna F - ERROR ver pestaña "Anexos" | I20: Se debe contar con la siguiente información: CFDI 4.0 con Complemento Comercio Exterior
A21: POL_8211\CC066_Validaciones_CE_Comprobante | B21: CP03-CFDI | C21: Exportación CCE104 | D21: 1 | E21: El complemento de Comercio Exterior debe existir cuando el atributo “CFDI:Comprobante:Exportacion” contenga el valor “02”. de acuerdo al catCFDI:c_Exportacion, por lo que debe existir el complemento de Comercio Exterior. Cuando el valor del campo sea “04” puede o no existir. Los XML para probar el mensaje esperado de error son con el código de error: CCE104 El servicio será invocado: .Entes publicos .Servicios Gratuitos de Facturación | F21: El resultado esperado: La clave registrada en el atributo Exportacion contiene el valor "02" y no existe el complemento de Comercio Exterior. En caso de error: La respuesta de los mensajes viene en el archivo de Response del XML con marcado en los campos de la estructura: <CodigoError> <MensajeIncidencia> Para esta prueba se espera la respuesta de los códigos de error: CCE104 | G21: Los mensajes de error se encuentran en el archivo anexo Matriz_de_Errores_CCE_v2 Columna E - CÓDIGO ERROR Columna F - ERROR ver pestaña "Anexos" | I21: Se debe contar con la siguiente información: CFDI 4.0 con Complemento Comercio Exterior
A22: POL_8211\CC066_Validaciones_CE_Comprobante | B22: CP04-CFDI | C22: Receptor:Rfc CCE107 | D22: 1 | E22: Si el atributo TipoDeComprobante tiene el valor "I" este atributo puede tener un RFC registrado en la lista de RFC inscritos no cancelados del SAT (l_RFC) o el valor"XEXX010101000". Los XML para probar el mensaje esperado de error son con el código de error: CCE107 El servicio será invocado: .Entes publicos .Servicios Gratuitos de Facturación | F22: El resultado esperado: El atributo cfdi:Comprobante:Receptor:Rfc no tiene un RFC registrado en la lista de RFC inscritos no cancelados del SAT (l_RFC), ni el valor "XEXX010101000" o se encuentra vacío. En caso de error: La respuesta de los mensajes viene en el archivo de Response del XML con marcado en los campos de la estructura: <CodigoError> <MensajeIncidencia> Para esta prueba se espera la respuesta de los códigos de error: CCE107 | G22: Los mensajes de error se encuentran en el archivo anexo Matriz_de_Errores_CCE_v2 Columna E - CÓDIGO ERROR Columna F - ERROR ver pestaña "Anexos" | I22: Se debe contar con la siguiente información: CFDI 4.0 con Complemento Comercio Exterior
A23: POL_8211\CC066_Validaciones_CE_Comprobante | B23: CP05-CFDI | C23: Receptor:Rfc CCE108 | D23: 1 | E23: Si el atributo TipoDeComprobante tiene el valor "T", entonces este atributo debe ser igual al valor del atributo Emisor:Rfc; Los XML para probar el mensaje esperado de error son con el código de error: CCE108 El servicio será invocado: .Entes publicos .Servicios Gratuitos de Facturación | F23: El resultado esperado: El atributo cfdi:Comprobante:Receptor:Rfc tiene un valor diferente al registrado en el atributo cfdi:Comprobante:Emisor:Rfc o se encuentra vacío. En caso de error: La respuesta de los mensajes viene en el archivo de Response del XML con marcado en los campos de la estructura: <CodigoError> <MensajeIncidencia> Para esta prueba se espera la respuesta de los códigos de error: CCE108 | G23: Los mensajes de error se encuentran en el archivo anexo Matriz_de_Errores_CCE_v2 Columna E - CÓDIGO ERROR Columna F - ERROR ver pestaña "Anexos" | I23: Se debe contar con la siguiente información: CFDI 4.0 con Complemento Comercio Exterior
A24: POL_8211\CC066_Validaciones_CE_Comprobante | B24: CP06-CFDI | C24: AcuentaTerceros | D24: 1 | E24: El nodo "ACuentaTerceros" no debe existir. Los XML para probar el mensaje esperado de error son con el código de error: CCE111 El servicio será invocado: .Entes publicos .Servicios Gratuitos de Facturación | F24: El resultado esperado: Se registró información en el nodo "ACuentaTerceros" y no debe existir. En caso de error: La respuesta de los mensajes viene en el archivo de Response del XML con marcado en los campos de la estructura: <CodigoError> <MensajeIncidencia> Para esta prueba se espera la respuesta de los códigos de error: CCE111 | G24: Los mensajes de error se encuentran en el archivo anexo Matriz_de_Errores_CCE_v2 Columna E - CÓDIGO ERROR Columna F - ERROR ver pestaña "Anexos" | I24: Se debe contar con la siguiente información: CFDI 4.0 con Complemento Comercio Exterior
A25: POL_8211\CC066_Validaciones_CE_Comprobante | B25: CP07-CFDI | C25: CuentaPredial | D25: 1 | E25: El nodo "CuentaPredial" no debe existir. Los XML para probar el mensaje esperado de error son con el código de error: CCE112 El servicio será invocado: .Entes publicos .Servicios Gratuitos de Facturación | F25: El resultado esperado: Se registró información en el nodo "CuentaPredial" y no debe existir. En caso de error: La respuesta de los mensajes viene en el archivo de Response del XML con marcado en los campos de la estructura: <CodigoError> <MensajeIncidencia> Para esta prueba se espera la respuesta de los códigos de error: CCE112 | G25: Los mensajes de error se encuentran en el archivo anexo Matriz_de_Errores_CCE_v2 Columna E - CÓDIGO ERROR Columna F - ERROR ver pestaña "Anexos" | I25: Se debe contar con la siguiente información: CFDI 4.0 con Complemento Comercio Exterior
A26: POL_8211\CC066_Validaciones_CE_Complemento | B26: CP08-ComercioExterior | C26: ComercioExterior CCE114 | D26: 1 | E26: El nodo cce20:ComercioExterior se debe registrar como un nodo hijo del nodo Complemento en el CFDI. Los XML para probar el mensaje esperado de error son con el código de error: CCE114 El servicio será invocado: .Entes publicos .Servicios Gratuitos de Facturación | F26: El resultado esperado: El nodo cce20:ComercioExterior debe registrarse como un nodo hijo del nodo Complemento en el CFDI. En caso de error: La respuesta de los mensajes viene en el archivo de Response del XML con marcado en los campos de la estructura: <CodigoError> <MensajeIncidencia> Para esta prueba se espera la respuesta de los códigos de error: CCE114 | G26: Los mensajes de error se encuentran en el archivo anexo Matriz_de_Errores_CCE_v2 Columna E - CÓDIGO ERROR Columna F - ERROR ver pestaña "Anexos" | I26: Se debe contar con la siguiente información: CFDI 4.0 con Complemento Comercio Exterior
A27: POL_8211\CC066_Validaciones_CE_Complemento | B27: CP09-ComercioExterior | C27: ComercioExterior CCE115 | D27: 1 | E27: El nodo cce20:ComercioExterior solo puede coexistir con los complementos Timbre Fiscal Digital, otros derechos e impuestos, leyendas fiscales, CFDI registro fiscal y Carta Porte. Los XML para probar el mensaje esperado de error son con el código de error: CCE115 El servicio será invocado: .Entes publicos .Servicios Gratuitos de Facturación | F27: El resultado esperado: El nodo cce20:ComercioExterior solo puede coexistir con los complementos Timbre Fiscal Digital, otros derechos e impuestos, leyendas fiscales, CFDI registro fiscal y Carta Porte. En caso de error: La respuesta de los mensajes viene en el archivo de Response del XML con marcado en los campos de la estructura: <CodigoError> <MensajeIncidencia> Para esta prueba se espera la respuesta de los códigos de error: CCE115 | G27: Los mensajes de error se encuentran en el archivo anexo Matriz_de_Errores_CCE_v2 Columna E - CÓDIGO ERROR Columna F - ERROR ver pestaña "Anexos" | I27: Se debe contar con la siguiente información: CFDI 4.0 con Complemento Comercio Exterior
A28: POL_8211\CC066_Validaciones_CE_Complemento | B28: CP10-ComercioExterior | C28: MotivoTraslado CCE117 | D28: 1 | E28: El atributo cce20:ComercioExterior:MotivoTraslado contiene el valor "05" y debe contener al menos un nodo "Propietario", en caso contrario no deben existir nodos "Propietario". Los XML para probar el mensaje esperado de error son con el código de error: CCE117 El servicio será invocado: .Entes publicos .Servicios Gratuitos de Facturación | F28: El resultado esperado: Se registró la clave "05" en el atributo cce20:ComercioExterior:MotivoTraslado y no existe al menos un nodo "Propietario". En caso de error: La respuesta de los mensajes viene en el archivo de Response del XML con marcado en los campos de la estructura: <CodigoError> <MensajeIncidencia> Para esta prueba se espera la respuesta de los códigos de error: CCE117 | G28: Los mensajes de error se encuentran en el archivo anexo Matriz_de_Errores_CCE_v2 Columna E - CÓDIGO ERROR Columna F - ERROR ver pestaña "Anexos" | I28: Se debe contar con la siguiente información: CFDI 4.0 con Complemento Comercio Exterior
A29: POL_8211\CC066_Validaciones_CE_Complemento | B29: CP11-ComercioExterior | C29: NumCertificadoOrigen | D29: 1 | E29: Si el valor registrado en el campo CertificadoOrigen es 1 este campo deberá registrarse, en caso contrario no deberá existir. Los XML para probar el mensaje esperado de error son con el código de error: CCE118 El servicio será invocado: .Entes publicos .Servicios Gratuitos de Facturación | F29: El resultado esperado: El valor de cce20:ComercioExterior:CertificadoOrigen es "0" y se registró el atributo cce20:ComercioExterior:NumCertificadoOrigen En caso de error: La respuesta de los mensajes viene en el archivo de Response del XML con marcado en los campos de la estructura: <CodigoError> <MensajeIncidencia> Para esta prueba se espera la respuesta de los códigos de error: CCE118 | G29: Los mensajes de error se encuentran en el archivo anexo Matriz_de_Errores_CCE_v2 Columna E - CÓDIGO ERROR Columna F - ERROR ver pestaña "Anexos" | I29: Se debe contar con la siguiente información: CFDI 4.0 con Complemento Comercio Exterior
A30: POL_8211\CC066_Validaciones_CE_Complemento | B30: CP12-ComercioExterior | C30: NumeroExportadorConfiable | D30: 1 | E30: El atributo cce20:ComercioExterior:NumeroExportadorConfiable no debe registrarse si la clave de país del receptor o del destinatario no corresponde a un país del catálogo catCFDI:c_Pais donde la columna Agrupación tenga el valor Unión Europea. Los XML para probar el mensaje esperado de error son con el código de error: CCE119 El servicio será invocado: .Entes publicos .Servicios Gratuitos de Facturación | F30: El resultado esperado: Se registró el atributo cce20:ComercioExterior:NumeroExportadorConfiable y la clave de país del receptor o del destinatario no corresponde a un país del catálogo catCFDI:c_Pais donde la columna Agrupación tenga el valor Unión Europea. En caso de error: La respuesta de los mensajes viene en el archivo de Response del XML con marcado en los campos de la estructura: <CodigoError> <MensajeIncidencia> Para esta prueba se espera la respuesta de los códigos de error: CCE119 | G30: Los mensajes de error se encuentran en el archivo anexo Matriz_de_Errores_CCE_v2 Columna E - CÓDIGO ERROR Columna F - ERROR ver pestaña "Anexos" | I30: Se debe contar con la siguiente información: CFDI 4.0 con Complemento Comercio Exterior
... A191: POL_8211\CC066_Validaciones_CFDI_v40 | B191: CP173-Error no clasificado | C191: No clasificado | D191: 1 | E191: Error no clasificado. Los XML para probar el mensaje esperado de error son con el código de error: CFDI40999 El servicio será invocado: .Entes publicos .Servicios Gratuitos de Facturación | F191: Error no clasificado. En caso de error: La respuesta de los mensajes viene en el archivo de Response del XML con marcado en los campos de la estructura: <CodigoError> <MensajeIncidencia> Para esta prueba se espera la respuesta de los códigos de error: CFDI40999 | G191: Los mensajes de error se encuentran en el archivo anexo MatrizDeErrores_CFDI_v40_20260325 Columna E - CÓDIGO ERROR Columna F - ERROR ver pestaña "Anexos" | I191: Se debe contar con la siguiente información: CFDI 4.0 con Complemento para Recepción de Pagos

Sheet Devops
A19: Test Case | B19: =IF(CP!B19<>0,CP!B19&"-"&_xlfn.SINGLE(CP!C19),"") -> CP01-CFDI-TipoDeComprobante CCE101 | C19: =IF(LEN($B19)<0,"",CP!D19) -> 1 | D19: =IF(LEN($A19)<0,"",CP!E19) -> Este atributo puede tener los valores "I", "E" o "T". Los XML para probar el mensaje esperado de error son con el código de error: CCE101 El servicio será invocado: .Entes publicos .Servicios Gratuitos de Facturación | E19: =IF(LEN($A19)<0,"",CP!F19) -> El resultado esperado: El atributo cfdi:Comprobante:TipoDeComprobante no cumple con alguno de los valores permitidos para este complemento. En caso de error: La respuesta de los mensajes viene en el archivo de Response del XML con marcado en los campos de la estructura: <CodigoError> <MensajeIncidencia> Para esta prueba se espera la respuesta de los códigos de error: CCE101 | F19: =IF(LEN($A19)<0,"",CP!G19&CHAR(10)&CP!H19) -> Los mensajes de error se encuentran en el archivo anexo Matriz_de_Errores_CCE_v2 Columna E - CÓDIGO ERROR Columna F - ERROR ver pestaña "Anexos"
B20: =IF(CP!B20<>0,CP!B20&"-"&_xlfn.SINGLE(CP!C20),"") -> CP02-CFDI-TipoDeComprobante CCE102 | C20: =IF(LEN($B20)<0,"",CP!D20) -> 1 | D20: =IF(LEN($A20)<0,"",CP!E20) -> Si el valor es "T", se debe registrar el atributo MotivoTraslado y, si el MotivoTraslado tiene la clave "05", se debe registrar el nodo Propietario. Los XML para probar el mensaje esperado de error son con el código de error: CCE102 El servicio será invocado: .Entes publicos .Servicios Gratuitos de Facturación | E20: =IF(LEN($A20)<0,"",CP!F20) -> El resultado esperado: El nodo Propietario se debe registrar cuando el atributo cfdi:Comprobante:TipoDeComprobante tiene el valor "T" y MotivoTraslado tiene la clave "05". En caso de error: La respuesta de los mensajes viene en el archivo de Response del XML con marcado en los campos de la estructura: <CodigoError> <MensajeIncidencia> Para esta prueba se espera la respuesta de los códigos de error: CCE102 | F20: =IF(LEN($A20)<0,"",CP!G20&CHAR(10)&CP!H20) -> Los mensajes de error se encuentran en el archivo anexo Matriz_de_Errores_CCE_v2 Columna E - CÓDIGO ERROR Columna F - ERROR ver pestaña "Anexos"
B21: =IF(CP!B21<>0,CP!B21&"-"&_xlfn.SINGLE(CP!C21),"") -> CP03-CFDI-Exportación CCE104 | C21: =IF(LEN($B21)<0,"",CP!D21) -> 1 | D21: =IF(LEN($A21)<0,"",CP!E21) -> El complemento de Comercio Exterior debe existir cuando el atributo “CFDI:Comprobante:Exportacion” contenga el valor “02”. de acuerdo al catCFDI:c_Exportacion, por lo que debe existir el complemento de Comercio Exterior. Cuando el valor del campo sea “04” puede o no existir. Los XML para probar el mensaje esperado de error son con el código de error: CCE104 El servicio será invocado: .Entes publicos .Servicios Gratuitos de Facturación | E21: =IF(LEN($A21)<0,"",CP!F21) -> El resultado esperado: La clave registrada en el atributo Exportacion contiene el valor "02" y no existe el complemento de Comercio Exterior. En caso de error: La respuesta de los mensajes viene en el archivo de Response del XML con marcado en los campos de la estructura: <CodigoError> <MensajeIncidencia> Para esta prueba se espera la respuesta de los códigos de error: CCE104 | F21: =IF(LEN($A21)<0,"",CP!G21&CHAR(10)&CP!H21) -> Los mensajes de error se encuentran en el archivo anexo Matriz_de_Errores_CCE_v2 Columna E - CÓDIGO ERROR Columna F - ERROR ver pestaña "Anexos"
B22: =IF(CP!B22<>0,CP!B22&"-"&_xlfn.SINGLE(CP!C22),"") -> CP04-CFDI-Receptor:Rfc CCE107 | C22: =IF(LEN($B22)<0,"",CP!D22) -> 1 | D22: =IF(LEN($A22)<0,"",CP!E22) -> Si el atributo TipoDeComprobante tiene el valor "I" este atributo puede tener un RFC registrado en la lista de RFC inscritos no cancelados del SAT (l_RFC) o el valor"XEXX010101000". Los XML para probar el mensaje esperado de error son con el código de error: CCE107 El servicio será invocado: .Entes publicos .Servicios Gratuitos de Facturación | E22: =IF(LEN($A22)<0,"",CP!F22) -> El resultado esperado: El atributo cfdi:Comprobante:Receptor:Rfc no tiene un RFC registrado en la lista de RFC inscritos no cancelados del SAT (l_RFC), ni el valor "XEXX010101000" o se encuentra vacío. En caso de error: La respuesta de los mensajes viene en el archivo de Response del XML con marcado en los campos de la estructura: <CodigoError> <MensajeIncidencia> Para esta prueba se espera la respuesta de los códigos de error: CCE107 | F22: =IF(LEN($A22)<0,"",CP!G22&CHAR(10)&CP!H22) -> Los mensajes de error se encuentran en el archivo anexo Matriz_de_Errores_CCE_v2 Columna E - CÓDIGO ERROR Columna F - ERROR ver pestaña "Anexos"
B23: =IF(CP!B23<>0,CP!B23&"-"&_xlfn.SINGLE(CP!C23),"") -> CP05-CFDI-Receptor:Rfc CCE108 | C23: =IF(LEN($B23)<0,"",CP!D23) -> 1 | D23: =IF(LEN($A23)<0,"",CP!E23) -> Si el atributo TipoDeComprobante tiene el valor "T", entonces este atributo debe ser igual al valor del atributo Emisor:Rfc; Los XML para probar el mensaje esperado de error son con el código de error: CCE108 El servicio será invocado: .Entes publicos .Servicios Gratuitos de Facturación | E23: =IF(LEN($A23)<0,"",CP!F23) -> El resultado esperado: El atributo cfdi:Comprobante:Receptor:Rfc tiene un valor diferente al registrado en el atributo cfdi:Comprobante:Emisor:Rfc o se encuentra vacío. En caso de error: La respuesta de los mensajes viene en el archivo de Response del XML con marcado en los campos de la estructura: <CodigoError> <MensajeIncidencia> Para esta prueba se espera la respuesta de los códigos de error: CCE108 | F23: =IF(LEN($A23)<0,"",CP!G23&CHAR(10)&CP!H23) -> Los mensajes de error se encuentran en el archivo anexo Matriz_de_Errores_CCE_v2 Columna E - CÓDIGO ERROR Columna F - ERROR ver pestaña "Anexos"
B24: =IF(CP!B24<>0,CP!B24&"-"&_xlfn.SINGLE(CP!C24),"") -> CP06-CFDI- AcuentaTerceros | C24: =IF(LEN($B24)<0,"",CP!D24) -> 1 | D24: =IF(LEN($A24)<0,"",CP!E24) -> El nodo "ACuentaTerceros" no debe existir. Los XML para probar el mensaje esperado de error son con el código de error: CCE111 El servicio será invocado: .Entes publicos .Servicios Gratuitos de Facturación | E24: =IF(LEN($A24)<0,"",CP!F24) -> El resultado esperado: Se registró información en el nodo "ACuentaTerceros" y no debe existir. En caso de error: La respuesta de los mensajes viene en el archivo de Response del XML con marcado en los campos de la estructura: <CodigoError> <MensajeIncidencia> Para esta prueba se espera la respuesta de los códigos de error: CCE111 | F24: =IF(LEN($A24)<0,"",CP!G24&CHAR(10)&CP!H24) -> Los mensajes de error se encuentran en el archivo anexo Matriz_de_Errores_CCE_v2 Columna E - CÓDIGO ERROR Columna F - ERROR ver pestaña "Anexos"
B25: =IF(CP!B25<>0,CP!B25&"-"&_xlfn.SINGLE(CP!C25),"") -> CP07-CFDI-CuentaPredial | C25: =IF(LEN($B25)<0,"",CP!D25) -> 1 | D25: =IF(LEN($A25)<0,"",CP!E25) -> El nodo "CuentaPredial" no debe existir. Los XML para probar el mensaje esperado de error son con el código de error: CCE112 El servicio será invocado: .Entes publicos .Servicios Gratuitos de Facturación | E25: =IF(LEN($A25)<0,"",CP!F25) -> El resultado esperado: Se registró información en el nodo "CuentaPredial" y no debe existir. En caso de error: La respuesta de los mensajes viene en el archivo de Response del XML con marcado en los campos de la estructura: <CodigoError> <MensajeIncidencia> Para esta prueba se espera la respuesta de los códigos de error: CCE112 | F25: =IF(LEN($A25)<0,"",CP!G25&CHAR(10)&CP!H25) -> Los mensajes de error se encuentran en el archivo anexo Matriz_de_Errores_CCE_v2 Columna E - CÓDIGO ERROR Columna F - ERROR ver pestaña "Anexos"
B26: =IF(CP!B26<>0,CP!B26&"-"&_xlfn.SINGLE(CP!C26),"") -> CP08-ComercioExterior-ComercioExterior CCE114 | C26: =IF(LEN($B26)<0,"",CP!D26) -> 1 | D26: =IF(LEN($A26)<0,"",CP!E26) -> El nodo cce20:ComercioExterior se debe registrar como un nodo hijo del nodo Complemento en el CFDI. Los XML para probar el mensaje esperado de error son con el código de error: CCE114 El servicio será invocado: .Entes publicos .Servicios Gratuitos de Facturación | E26: =IF(LEN($A26)<0,"",CP!F26) -> El resultado esperado: El nodo cce20:ComercioExterior debe registrarse como un nodo hijo del nodo Complemento en el CFDI. En caso de error: La respuesta de los mensajes viene en el archivo de Response del XML con marcado en los campos de la estructura: <CodigoError> <MensajeIncidencia> Para esta prueba se espera la respuesta de los códigos de error: CCE114 | F26: =IF(LEN($A26)<0,"",CP!G26&CHAR(10)&CP!H26) -> Los mensajes de error se encuentran en el archivo anexo Matriz_de_Errores_CCE_v2 Columna E - CÓDIGO ERROR Columna F - ERROR ver pestaña "Anexos"
B27: =IF(CP!B27<>0,CP!B27&"-"&_xlfn.SINGLE(CP!C27),"") -> CP09-ComercioExterior-ComercioExterior CCE115 | C27: =IF(LEN($B27)<0,"",CP!D27) -> 1 | D27: =IF(LEN($A27)<0,"",CP!E27) -> El nodo cce20:ComercioExterior solo puede coexistir con los complementos Timbre Fiscal Digital, otros derechos e impuestos, leyendas fiscales, CFDI registro fiscal y Carta Porte. Los XML para probar el mensaje esperado de error son con el código de error: CCE115 El servicio será invocado: .Entes publicos .Servicios Gratuitos de Facturación | E27: =IF(LEN($A27)<0,"",CP!F27) -> El resultado esperado: El nodo cce20:ComercioExterior solo puede coexistir con los complementos Timbre Fiscal Digital, otros derechos e impuestos, leyendas fiscales, CFDI registro fiscal y Carta Porte. En caso de error: La respuesta de los mensajes viene en el archivo de Response del XML con marcado en los campos de la estructura: <CodigoError> <MensajeIncidencia> Para esta prueba se espera la respuesta de los códigos de error: CCE115 | F27: =IF(LEN($A27)<0,"",CP!G27&CHAR(10)&CP!H27) -> Los mensajes de error se encuentran en el archivo anexo Matriz_de_Errores_CCE_v2 Columna E - CÓDIGO ERROR Columna F - ERROR ver pestaña "Anexos"
B28: =IF(CP!B28<>0,CP!B28&"-"&_xlfn.SINGLE(CP!C28),"") -> CP10-ComercioExterior-MotivoTraslado CCE117 | C28: =IF(LEN($B28)<0,"",CP!D28) -> 1 | D28: =IF(LEN($A28)<0,"",CP!E28) -> El atributo cce20:ComercioExterior:MotivoTraslado contiene el valor "05" y debe contener al menos un nodo "Propietario", en caso contrario no deben existir nodos "Propietario". Los XML para probar el mensaje esperado de error son con el código de error: CCE117 El servicio será invocado: .Entes publicos .Servicios Gratuitos de Facturación | E28: =IF(LEN($A28)<0,"",CP!F28) -> El resultado esperado: Se registró la clave "05" en el atributo cce20:ComercioExterior:MotivoTraslado y no existe al menos un nodo "Propietario". En caso de error: La respuesta de los mensajes viene en el archivo de Response del XML con marcado en los campos de la estructura: <CodigoError> <MensajeIncidencia> Para esta prueba se espera la respuesta de los códigos de error: CCE117 | F28: =IF(LEN($A28)<0,"",CP!G28&CHAR(10)&CP!H28) -> Los mensajes de error se encuentran en el archivo anexo Matriz_de_Errores_CCE_v2 Columna E - CÓDIGO ERROR Columna F - ERROR ver pestaña "Anexos"
B29: =IF(CP!B29<>0,CP!B29&"-"&_xlfn.SINGLE(CP!C29),"") -> CP11-ComercioExterior-NumCertificadoOrigen | C29: =IF(LEN($B29)<0,"",CP!D29) -> 1 | D29: =IF(LEN($A29)<0,"",CP!E29) -> Si el valor registrado en el campo CertificadoOrigen es 1 este campo deberá registrarse, en caso contrario no deberá existir. Los XML para probar el mensaje esperado de error son con el código de error: CCE118 El servicio será invocado: .Entes publicos .Servicios Gratuitos de Facturación | E29: =IF(LEN($A29)<0,"",CP!F29) -> El resultado esperado: El valor de cce20:ComercioExterior:CertificadoOrigen es "0" y se registró el atributo cce20:ComercioExterior:NumCertificadoOrigen En caso de error: La respuesta de los mensajes viene en el archivo de Response del XML con marcado en los campos de la estructura: <CodigoError> <MensajeIncidencia> Para esta prueba se espera la respuesta de los códigos de error: CCE118 | F29: =IF(LEN($A29)<0,"",CP!G29&CHAR(10)&CP!H29) -> Los mensajes de error se encuentran en el archivo anexo Matriz_de_Errores_CCE_v2 Columna E - CÓDIGO ERROR Columna F - ERROR ver pestaña "Anexos"
B30: =IF(CP!B30<>0,CP!B30&"-"&_xlfn.SINGLE(CP!C30),"") -> CP12-ComercioExterior-NumeroExportadorConfiable | C30: =IF(LEN($B30)<0,"",CP!D30) -> 1 | D30: =IF(LEN($A30)<0,"",CP!E30) -> El atributo cce20:ComercioExterior:NumeroExportadorConfiable no debe registrarse si la clave de país del receptor o del destinatario no corresponde a un país del catálogo catCFDI:c_Pais donde la columna Agrupación tenga el valor Unión Europea. Los XML para probar el mensaje esperado de error son con el código de error: CCE119 El servicio será invocado: .Entes publicos .Servicios Gratuitos de Facturación | E30: =IF(LEN($A30)<0,"",CP!F30) -> El resultado esperado: Se registró el atributo cce20:ComercioExterior:NumeroExportadorConfiable y la clave de país del receptor o del destinatario no corresponde a un país del catálogo catCFDI:c_Pais donde la columna Agrupación tenga el valor Unión Europea. En caso de error: La respuesta de los mensajes viene en el archivo de Response del XML con marcado en los campos de la estructura: <CodigoError> <MensajeIncidencia> Para esta prueba se espera la respuesta de los códigos de error: CCE119 | F30: =IF(LEN($A30)<0,"",CP!G30&CHAR(10)&CP!H30) -> Los mensajes de error se encuentran en el archivo anexo Matriz_de_Errores_CCE_v2 Columna E - CÓDIGO ERROR Columna F - ERROR ver pestaña "Anexos"
B31: =IF(CP!B31<>0,CP!B31&"-"&_xlfn.SINGLE(CP!C31),"") -> CP13-ComercioExterior-TipoCambioUSD | C31: =IF(LEN($B31)<0,"",CP!D31) -> 1 | D31: =IF(LEN($A31)<0,"",CP!E31) -> El atributo cce20:ComercioExterior:TipoCambioUSD debe corresponder con el número de pesos mexicanos que equivalen a un dólar de Estados Unidos, de acuerdo al artículo 20 del Código Fiscal de la Federación. Los XML para probar el mensaje esperado de error son con el código de error: CCE121 El servicio será invocado: .Entes publicos .Servicios Gratuitos de Facturación | E31: =IF(LEN($A31)<0,"",CP!F31) -> El valor del atributo cce20:ComercioExterior:TipoCambioUSD no corresponde con el número de pesos mexicanos equivalentes a un dólar de Estados Unidos. En caso de error: La respuesta de los mensajes viene en el archivo de Response del XML con marcado en los campos de la estructura: <CodigoError> <MensajeIncidencia> Para esta prueba se espera la respuesta de los códigos de error: CCE121 | F31: =IF(LEN($A31)<0,"",CP!G31&CHAR(10)&CP!H31) -> Los mensajes de error se encuentran en el archivo anexo Matriz_de_Errores_CCE_v2 Columna E - CÓDIGO ERROR Columna F - ERROR ver pestaña "Anexos"
... B191: =IF(CP!B191<>0,CP!B191&"-"&_xlfn.SINGLE(CP!C191),"") -> CP173-Error no clasificado-No clasificado | C191: =IF(LEN($B191)<0,"",CP!D191) -> 1 | D191: =IF(LEN($A191)<0,"",CP!E191) -> Error no clasificado. Los XML para probar el mensaje esperado de error son con el código de error: CFDI40999 El servicio será invocado: .Entes publicos .Servicios Gratuitos de Facturación | E191: =IF(LEN($A191)<0,"",CP!F191) -> Error no clasificado. En caso de error: La respuesta de los mensajes viene en el archivo de Response del XML con marcado en los campos de la estructura: <CodigoError> <MensajeIncidencia> Para esta prueba se espera la respuesta de los códigos de error: CFDI40999 | F191: =IF(LEN($A191)<0,"",CP!G191&CHAR(10)&CP!H191) -> Los mensajes de error se encuentran en el archivo anexo MatrizDeErrores_CFDI_v40_20260325 Columna E - CÓDIGO ERROR Columna F - ERROR ver pestaña "Anexos"
F192: =IF(LEN($A192)<0,"",CP!G192&CHAR(10)&CP!H192)
F193: =IF(LEN($A193)<0,"",CP!G193&CHAR(10)&CP!H193)
F194: =IF(LEN($A194)<0,"",CP!G194&CHAR(10)&CP!H194)
F195: =IF(LEN($A195)<0,"",CP!G195&CHAR(10)&CP!H195)
F196: =IF(LEN($A196)<0,"",CP!G196&CHAR(10)&CP!H196)
F197: =IF(LEN($A197)<0,"",CP!G197&CHAR(10)&CP!H197)
F198: =IF(LEN($A198)<0,"",CP!G198&CHAR(10)&CP!H198)
F199: =IF(LEN($A199)<0,"",CP!G199&CHAR(10)&CP!H199)
F200: =IF(LEN($A200)<0,"",CP!G200&CHAR(10)&CP!H200)
F201: =IF(LEN($A201)<0,"",CP!G201&CHAR(10)&CP!H201)
F202: =IF(LEN($A202)<0,"",CP!G202&CHAR(10)&CP!H202)
F203: =IF(LEN($A203)<0,"",CP!G203&CHAR(10)&CP!H203)
... F217: =IF(LEN($A217)<0,"",CP!G217&CHAR(10)&CP!H217)

Sheet Devops_Carga
A1: ID | B1: Work Item type | C1: Title | D1: Test Step | E1: Step Action | F1: Step expected
B2: Test Case | C2: CP01-CFDI-TipoDeComprobante CCE101 | D2: 1 | E2: Este atributo puede tener los valores "I", "E" o "T". Los XML para probar el mensaje esperado de error son con el código de error: CCE101 El servicio será invocado: .Entes publicos .Servicios Gratuitos de Facturación | F2: El resultado esperado: El atributo cfdi:Comprobante:TipoDeComprobante no cumple con alguno de los valores permitidos para este complemento. En caso de error: La respuesta de los mensajes viene en el archivo de Response del XML con marcado en los campos de la estructura: <CodigoError> <MensajeIncidencia> Para esta prueba se espera la respuesta de los códigos de error: CCE101 | G2: Los mensajes de error se encuentran en el archivo anexo Matriz_de_Errores_CCE_v2 Columna E - CÓDIGO ERROR Columna F - ERROR ver pestaña "Anexos"
C3: CP02-CFDI-TipoDeComprobante CCE102 | D3: 1 | E3: Si el valor es "T", se debe registrar el atributo MotivoTraslado y, si el MotivoTraslado tiene la clave "05", se debe registrar el nodo Propietario. Los XML para probar el mensaje esperado de error son con el código de error: CCE102 El servicio será invocado: .Entes publicos .Servicios Gratuitos de Facturación | F3: El resultado esperado: El nodo Propietario se debe registrar cuando el atributo cfdi:Comprobante:TipoDeComprobante tiene el valor "T" y MotivoTraslado tiene la clave "05". En caso de error: La respuesta de los mensajes viene en el archivo de Response del XML con marcado en los campos de la estructura: <CodigoError> <MensajeIncidencia> Para esta prueba se espera la respuesta de los códigos de error: CCE102 | G3: Los mensajes de error se encuentran en el archivo anexo Matriz_de_Errores_CCE_v2 Columna E - CÓDIGO ERROR Columna F - ERROR ver pestaña "Anexos"
C4: CP03-CFDI-Exportación CCE104 | D4: 1 | E4: El complemento de Comercio Exterior debe existir cuando el atributo “CFDI:Comprobante:Exportacion” contenga el valor “02”. de acuerdo al catCFDI:c_Exportacion, por lo que debe existir el complemento de Comercio Exterior. Cuando el valor del campo sea “04” puede o no existir. Los XML para probar el mensaje esperado de error son con el código de error: CCE104 El servicio será invocado: .Entes publicos .Servicios Gratuitos de Facturación | F4: El resultado esperado: La clave registrada en el atributo Exportacion contiene el valor "02" y no existe el complemento de Comercio Exterior. En caso de error: La respuesta de los mensajes viene en el archivo de Response del XML con marcado en los campos de la estructura: <CodigoError> <MensajeIncidencia> Para esta prueba se espera la respuesta de los códigos de error: CCE104 | G4: Los mensajes de error se encuentran en el archivo anexo Matriz_de_Errores_CCE_v2 Columna E - CÓDIGO ERROR Columna F - ERROR ver pestaña "Anexos"
C5: CP04-CFDI-Receptor:Rfc CCE107 | D5: 1 | E5: Si el atributo TipoDeComprobante tiene el valor "I" este atributo puede tener un RFC registrado en la lista de RFC inscritos no cancelados del SAT (l_RFC) o el valor"XEXX010101000". Los XML para probar el mensaje esperado de error son con el código de error: CCE107 El servicio será invocado: .Entes publicos .Servicios Gratuitos de Facturación | F5: El resultado esperado: El atributo cfdi:Comprobante:Receptor:Rfc no tiene un RFC registrado en la lista de RFC inscritos no cancelados del SAT (l_RFC), ni el valor "XEXX010101000" o se encuentra vacío. En caso de error: La respuesta de los mensajes viene en el archivo de Response del XML con marcado en los campos de la estructura: <CodigoError> <MensajeIncidencia> Para esta prueba se espera la respuesta de los códigos de error: CCE107 | G5: Los mensajes de error se encuentran en el archivo anexo Matriz_de_Errores_CCE_v2 Columna E - CÓDIGO ERROR Columna F - ERROR ver pestaña "Anexos"
C6: CP05-CFDI-Receptor:Rfc CCE108 | D6: 1 | E6: Si el atributo TipoDeComprobante tiene el valor "T", entonces este atributo debe ser igual al valor del atributo Emisor:Rfc; Los XML para probar el mensaje esperado de error son con el código de error: CCE108 El servicio será invocado: .Entes publicos .Servicios Gratuitos de Facturación | F6: El resultado esperado: El atributo cfdi:Comprobante:Receptor:Rfc tiene un valor diferente al registrado en el atributo cfdi:Comprobante:Emisor:Rfc o se encuentra vacío. En caso de error: La respuesta de los mensajes viene en el archivo de Response del XML con marcado en los campos de la estructura: <CodigoError> <MensajeIncidencia> Para esta prueba se espera la respuesta de los códigos de error: CCE108 | G6: Los mensajes de error se encuentran en el archivo anexo Matriz_de_Errores_CCE_v2 Columna E - CÓDIGO ERROR Columna F - ERROR ver pestaña "Anexos"
C7: CP06-CFDI- AcuentaTerceros | D7: 1 | E7: El nodo "ACuentaTerceros" no debe existir. Los XML para probar el mensaje esperado de error son con el código de error: CCE111 El servicio será invocado: .Entes publicos .Servicios Gratuitos de Facturación | F7: El resultado esperado: Se registró información en el nodo "ACuentaTerceros" y no debe existir. En caso de error: La respuesta de los mensajes viene en el archivo de Response del XML con marcado en los campos de la estructura: <CodigoError> <MensajeIncidencia> Para esta prueba se espera la respuesta de los códigos de error: CCE111 | G7: Los mensajes de error se encuentran en el archivo anexo Matriz_de_Errores_CCE_v2 Columna E - CÓDIGO ERROR Columna F - ERROR ver pestaña "Anexos"
C8: CP07-CFDI-CuentaPredial | D8: 1 | E8: El nodo "CuentaPredial" no debe existir. Los XML para probar el mensaje esperado de error son con el código de error: CCE112 El servicio será invocado: .Entes publicos .Servicios Gratuitos de Facturación | F8: El resultado esperado: Se registró información en el nodo "CuentaPredial" y no debe existir. En caso de error: La respuesta de los mensajes viene en el archivo de Response del XML con marcado en los campos de la estructura: <CodigoError> <MensajeIncidencia> Para esta prueba se espera la respuesta de los códigos de error: CCE112 | G8: Los mensajes de error se encuentran en el archivo anexo Matriz_de_Errores_CCE_v2 Columna E - CÓDIGO ERROR Columna F - ERROR ver pestaña "Anexos"
C9: CP08-ComercioExterior-ComercioExterior CCE114 | D9: 1 | E9: El nodo cce20:ComercioExterior se debe registrar como un nodo hijo del nodo Complemento en el CFDI. Los XML para probar el mensaje esperado de error son con el código de error: CCE114 El servicio será invocado: .Entes publicos .Servicios Gratuitos de Facturación | F9: El resultado esperado: El nodo cce20:ComercioExterior debe registrarse como un nodo hijo del nodo Complemento en el CFDI. En caso de error: La respuesta de los mensajes viene en el archivo de Response del XML con marcado en los campos de la estructura: <CodigoError> <MensajeIncidencia> Para esta prueba se espera la respuesta de los códigos de error: CCE114 | G9: Los mensajes de error se encuentran en el archivo anexo Matriz_de_Errores_CCE_v2 Columna E - CÓDIGO ERROR Columna F - ERROR ver pestaña "Anexos"
C10: CP09-ComercioExterior-ComercioExterior CCE115 | D10: 1 | E10: El nodo cce20:ComercioExterior solo puede coexistir con los complementos Timbre Fiscal Digital, otros derechos e impuestos, leyendas fiscales, CFDI registro fiscal y Carta Porte. Los XML para probar el mensaje esperado de error son con el código de error: CCE115 El servicio será invocado: .Entes publicos .Servicios Gratuitos de Facturación | F10: El resultado esperado: El nodo cce20:ComercioExterior solo puede coexistir con los complementos Timbre Fiscal Digital, otros derechos e impuestos, leyendas fiscales, CFDI registro fiscal y Carta Porte. En caso de error: La respuesta de los mensajes viene en el archivo de Response del XML con marcado en los campos de la estructura: <CodigoError> <MensajeIncidencia> Para esta prueba se espera la respuesta de los códigos de error: CCE115 | G10: Los mensajes de error se encuentran en el archivo anexo Matriz_de_Errores_CCE_v2 Columna E - CÓDIGO ERROR Columna F - ERROR ver pestaña "Anexos"
C11: CP10-ComercioExterior-MotivoTraslado CCE117 | D11: 1 | E11: El atributo cce20:ComercioExterior:MotivoTraslado contiene el valor "05" y debe contener al menos un nodo "Propietario", en caso contrario no deben existir nodos "Propietario". Los XML para probar el mensaje esperado de error son con el código de error: CCE117 El servicio será invocado: .Entes publicos .Servicios Gratuitos de Facturación | F11: El resultado esperado: Se registró la clave "05" en el atributo cce20:ComercioExterior:MotivoTraslado y no existe al menos un nodo "Propietario". En caso de error: La respuesta de los mensajes viene en el archivo de Response del XML con marcado en los campos de la estructura: <CodigoError> <MensajeIncidencia> Para esta prueba se espera la respuesta de los códigos de error: CCE117 | G11: Los mensajes de error se encuentran en el archivo anexo Matriz_de_Errores_CCE_v2 Columna E - CÓDIGO ERROR Columna F - ERROR ver pestaña "Anexos"
C12: CP11-ComercioExterior-NumCertificadoOrigen | D12: 1 | E12: Si el valor registrado en el campo CertificadoOrigen es 1 este campo deberá registrarse, en caso contrario no deberá existir. Los XML para probar el mensaje esperado de error son con el código de error: CCE118 El servicio será invocado: .Entes publicos .Servicios Gratuitos de Facturación | F12: El resultado esperado: El valor de cce20:ComercioExterior:CertificadoOrigen es "0" y se registró el atributo cce20:ComercioExterior:NumCertificadoOrigen En caso de error: La respuesta de los mensajes viene en el archivo de Response del XML con marcado en los campos de la estructura: <CodigoError> <MensajeIncidencia> Para esta prueba se espera la respuesta de los códigos de error: CCE118 | G12: Los mensajes de error se encuentran en el archivo anexo Matriz_de_Errores_CCE_v2 Columna E - CÓDIGO ERROR Columna F - ERROR ver pestaña "Anexos"
C13: CP12-ComercioExterior-NumeroExportadorConfiable | D13: 1 | E13: El atributo cce20:ComercioExterior:NumeroExportadorConfiable no debe registrarse si la clave de país del receptor o del destinatario no corresponde a un país del catálogo catCFDI:c_Pais donde la columna Agrupación tenga el valor Unión Europea. Los XML para probar el mensaje esperado de error son con el código de error: CCE119 El servicio será invocado: .Entes publicos .Servicios Gratuitos de Facturación | F13: El resultado esperado: Se registró el atributo cce20:ComercioExterior:NumeroExportadorConfiable y la clave de país del receptor o del destinatario no corresponde a un país del catálogo catCFDI:c_Pais donde la columna Agrupación tenga el valor Unión Europea. En caso de error: La respuesta de los mensajes viene en el archivo de Response del XML con marcado en los campos de la estructura: <CodigoError> <MensajeIncidencia> Para esta prueba se espera la respuesta de los códigos de error: CCE119 | G13: Los mensajes de error se encuentran en el archivo anexo Matriz_de_Errores_CCE_v2 Columna E - CÓDIGO ERROR Columna F - ERROR ver pestaña "Anexos"
C14: CP13-ComercioExterior-TipoCambioUSD | D14: 1 | E14: El atributo cce20:ComercioExterior:TipoCambioUSD debe corresponder con el número de pesos mexicanos que equivalen a un dólar de Estados Unidos, de acuerdo al artículo 20 del Código Fiscal de la Federación. Los XML para probar el mensaje esperado de error son con el código de error: CCE121 El servicio será invocado: .Entes publicos .Servicios Gratuitos de Facturación | F14: El valor del atributo cce20:ComercioExterior:TipoCambioUSD no corresponde con el número de pesos mexicanos equivalentes a un dólar de Estados Unidos. En caso de error: La respuesta de los mensajes viene en el archivo de Response del XML con marcado en los campos de la estructura: <CodigoError> <MensajeIncidencia> Para esta prueba se espera la respuesta de los códigos de error: CCE121 | G14: Los mensajes de error se encuentran en el archivo anexo Matriz_de_Errores_CCE_v2 Columna E - CÓDIGO ERROR Columna F - ERROR ver pestaña "Anexos"
... C174: CP173-Error no clasificado-No clasificado | D174: 1 | E174: Error no clasificado. Los XML para probar el mensaje esperado de error son con el código de error: CFDI40999 El servicio será invocado: .Entes publicos .Servicios Gratuitos de Facturación | F174: Error no clasificado. En caso de error: La respuesta de los mensajes viene en el archivo de Response del XML con marcado en los campos de la estructura: <CodigoError> <MensajeIncidencia> Para esta prueba se espera la respuesta de los códigos de error: CFDI40999 | G174: Los mensajes de error se encuentran en el archivo anexo MatrizDeErrores_CFDI_v40_20260325 Columna E - CÓDIGO ERROR Columna F - ERROR ver pestaña "Anexos"

Sheet Anexos
D10: ANEXOS
A12: Código del Aplicativo: | B12: 611.2
A13: ID de Requerimiento: | B13: POL_8211
A14: Nombre de Requerimiento: | B14: Validaciones Adicionales con el Complemento Complemento Comercio Exterior y Complemento para Recepción de Pagos 2.0
A18: Nombre Archivo | B18: Anexos
A19: Matriz_de_Errores_CCE_v2.xls
A20: Matriz_De_Errores_CRP_V20_Rev_B.xls
A21: MatrizDeErrores_CFDI_v40_20260325

Sheet Firmas Conformidad
B2: El uso de la siguiente Sección de Firmas de Conformidad es opcional, dependiendo de la necesidad del consumidor de la información.
B3: Instrucciones:
B4: Registrar en la tabla la información de los participantes en la elaboración, revisión, aprobación, etc. del artefacto.
B7: FIRMAS DE CONFORMIDAD
B8: Autorizó | C8: Autorizó / Revisó
B9: Nombre: Pedro López Bernal | C9: Nombre: Maria Luisa Flores Barron
B10: Puesto: Administrador de Gestión de Servicios y Trámites con Medios Electrónicos 3 | C10: Puesto: Subadministración de Gestión de Servicios y Trámites con Medios Electrónicos
B12: Fecha: | C12: Fecha:
B15: Autorizó / Revisó | C15: Autorizó / Revisó
B16: Nombre: Diana Maribel Velázquez Barroso | C16: Nombre: Roberto Benjamín Monroy Vargas
B17: Puesto: Administradora de Soluciones de Negocio 3. | C17: Puesto: Subadministrador de Soluciones de Negocio.
B18: Fecha: | C18: Fecha:
B21: Elaboró / Revisó | C21: Elaboró / Revisó
B22: Nombre: Alma Torres Gonzalez | C22: Nombre: Victor Manuel Esparza Muñoz
B24: Puesto: Jefe de departamento de Soluciones de Negocio. | C24: Puesto: Jefe de departamento de Gestión de Servicios y Trámites con Medios Electrónicos
B26: Fecha:

Sheet Encabezado
C1: Tomar como referencia el siguiente Encabezado para edición:
H4: Administración General de Comunicaciones y Tecnologías de la Información
H6: Marco Documental 7.0
C7: Fecha de aprobación del Template: 01/11/2021 | E7: Requerimientos de Pruebas Clave del Documento XX_RDP_REQPRUEBAS.xlsx [Nomenclatura del artefacto, punto, extensión del archivo actual] Servicio Administración del Ciclo de Vida de Aplicaciones de TIC Central Dueña: Administración Central de Soluciones de Negocio (ACSN) Central que Elabora: ACSN Central Consumidora: ACDMA | J7: Versión del template: 7.00
H13: Administración General de Comunicaciones y Tecnologías de la Información
H15: Marco Documental 7.0
C16: Fecha de aprobación del Template: 01/11/2021 | E16: Requerimientos de Pruebas RDP ValidacionesAsincronas-ComExt-Pagos-CFDI.xlsx | J16: Versión del template: 7.00
