Workbook

Sheet Instrucciones
B15: Objetivo: Identificar los insumos necesarios para pruebas de aceptación de usuario, a través de los casos de prueba, ambientes requeridos, especificación de los datos, cobertura de escenarios y atributos relacionados, a fin de contar con la integración de datos suficientes para la ejecución de las pruebas de la solución tecnológica con el usuario.
B17: Guía de Uso: 1.- Las pestañas "Casos de Prueba" y "Ambientes Requeridos" serán llenadas por la Administración Central de Soluciones de Negocio (ACSN), en la Fase Análisis, Etapa Especificación Funcional. 2.- Las pestañas "Interfaz de Usuario" y "Cobertura" serán llenadas en la Fase Desarrollo por las áreas ténicas que deban participar. En la primera también participará la ACSN en la Fase Pruebas, Etapa Pruebas Funcionales (AVL), por tema de Lineamientos Gráficos del SIAT, y para reflejar resultado de dichas pruebas. 3.- El documento está firmado por los responsables del llenado, incluyendo por el negocio cuando participa en la autorización. 4.- Si la pestaña "Casos de Prueba" incluye varias páginas, debe imprimirse sólo la página que contienen las firmas. Una vez firmado, debe digitalizarse y almacenarse en el repositorio como sustento junto con el archivo de Excel que corresponda a todo el documento. 5.- Si fuera necesario reservar información generada en esta plantilla, se hará bajo lo estipulado en la Ley General de Transparencia y Acceso a la Información Pública vigente (LGTAIP), pudiendo consultar a la ACPPI para su aplicación. (Ver abajo "Nota acerca de Irformación Reservada"). 6.- La aplicación de la sección de Firmas es opcional,dependiendo de las necesidades del consumidor, pero al contener temas de usuario de Negocio es importante la firma de éste.
B18: Nota acerca de Información Reservada Es reponsabilidad de cada requisitador la identificación de la información que se genere en este formato y así determinar si se cuenta con causas que originen la reserva de la misma, apegándose estrictamente a lo señalado en los ordenamientos jurídicos vigentes en materia de Transparencia. En caso de detectar información sensible (Reservada), se tendrá que indicar en la sección u hoja que lo amerite de este documento, en la parte inferior del texto, con la siguiente señalización: [Área dueña de la Información XX, clasificada como Reservada con Fundamento Legal XX, Motivación XX, Fecha de clasificación XX y Periodo de la reserva XX]. Ejemplo: "La información contenida en este documento pertenece a la Administración Central de Soluciones de Negocio, teniendo carácter de Reservada a partir del 01 de abril de 2018, con un periodo de reserva de 5 años, por tratarse de información que de revelarse puede causar un serio perjuicio a la recaudación de las contribuciones. Lo anterior tiene su fundamento en el artículo 113, fracción IV, de la Ley General de Transparencia y Acceso a la Información Pública."
B20: Hoja | D20: Descripción
B21: Casos de Prueba | D21: Esta hoja se utiliza para la documentación detallada de los casos de pruebas que serán utilizados en la ejecución de pruebas.
D22: Registra varios casos de prueba, con la finalidad de agrupar en un solo documento una cantidad suficiente de casos que pueda ser aprovechada para la importación de casos de prueba en alguna herramienta automatizada, o bien, para obtener de ella la información de casos de prueba. También se utiliza para especificar los elementos donde se emplearán los datos (Datos de Prueba)
D23: Criterios de Aceptación
D24: • El documento es utilizado de acuerdo al formato establecido. El documento cumple con el Marco Documental vigente. • El documento no contiene faltas de ortografía. • Cuando no se llene un renglón-columna, se deberá especificar el motivo por el cual no se registra la información, conteniendo al menos un "N/A". Ningún campo debe estar vacío. ●No se combinan celdas (exceptuando la sección de firmas) ●No incluye fórmulas en ningún renglón-columna • El documento describe detalladamente paso a paso las actividades a seguir para la validación de requerimientos del sistema. • El documento describe en cada paso una acción y una respuesta esperada que puede ser evaluada. El documento está firmado por los responsables del llenado, incluyendo por el negocio cuando participa en la autorización.
B26: Hoja | D26: Descripción
B27: Ambientes Requeridos | D27: Registra elementos de información sobre repositorios y ambientes necesarios para las pruebas y sus características, relacionadas con criterios que debe cubrir la información que se requiere para las pruebas; cantidad de datos requeridos para la ejecución de la prueba; datos o campos solicitados; condiciones que se deben cubrir para la extracción de datos y comentarios adicionales.
D28: Criterios de Aceptación
D29: * El documento es utilizado de acuerdo al formato establecido. * El documento cumple con el Marco Documental vigente. * El documento no contiene faltas de ortografía. * Cuando no se llene un renglón-columna, se deberá especificar el motivo por el cual no se registra la información, conteniendo al menos un "N/A". Ningún campo debe estar vacío. * El documento está firmado por los responsables del llenado, incluyendo por el negocio cuando participa en la autorización.
B31: Hoja | D31: Descripción
B32: Interfaz de Usuario | D32: Esta hoja aplica por la naturaleza de la solución tecnológica integrada que haya sido requerida. Se utiliza para validar que se cumplan los criterios definidos para la Interfaz de Usuario, incluyendo la aplicación y verificación de los Lineamientos Gráficos del SIAT, cuando sea el caso.
D33: Se detallan los puntos a validar de interfaz de usuario (interfaz gráfica) de las aplicaciones, como encabezados, pie de página, colores, alineación, etiquetas, listas desplegables, áreas de búsqueda, etc, etc.
D34: Criterios de Aceptación
D35: • El documento es utilizado de acuerdo al formato establecido. • El documento no contiene faltas de ortografía. • Cuando no se llene un renglón-columna, se deberá especificar el motivo por el cual no se registra la información. • Cada una de las características consideradas en esta pestaña estarán asociadas al contenido del artefacto "Especificación de Interacción de Usuario", en caso de ajustes o situaciones que expongan desviación al documento en comento, deberá ajustarse. • Cada defecto detectado deberá registrarse en la herramienta correspondiente para su atención y cierre.
B37: Hoja | D37: Descripción
B38: Cobertura | D38: Esta hoja se utiliza para identificar y detallar la cobertura de la prueba basada en complejidad ciclomática, para asegurar que se diseñen tantos casos de prueba como sean necesarios para que cada condición se ejecute al menos una vez con un valor verdadero, y al menos una vez uno falso.
D40: Criterios de Aceptación
D41: • El documento es utilizado de acuerdo al formato establecido. • El documento no contiene faltas de ortografía. • Cuando no se llene un renglón-columna, se deberá especificar el motivo por el cual no se registra la información. • El documento describe detalladamente los escenarios de prueba necesarios para que cada condición se ejecute al menos una vez con un valor verdadero y al menos una vez uno falso.
B43: Hoja | D43: Descripción
B44: Encabezado_Imagen | D44: En artefactos tipo Excel, la inserción del Encabezado como imagen en el mismo documento, puede hacerse como una alternativa cuando por la naturaleza y cantidad de información registrada en él, se hace necesario ampliar significativamente el tamaño de las celdas, ocasionando con ello distorsión o inadecuada distribución de la estructura del Encabezado del artefacto. Si ese fuera el caso, en esta hoja puede configurarse el Encabezado del artefacto y después insertarlo como imagen en cualquier otra sección del mismo, siguiendo las instrucciones allí descritas.
B46: Hoja | D46: Descripción
B47: Firmas Conformidad_Imagen | D47: En artefactos tipo Excel, la inserción de la Sección FIRMAS DE CONFORMIDAD como imagen en el mismo documento, puede hacerse como una alternativa cuando por la naturaleza y cantidad de información registrada en él, se hace necesario ampliar significativamente el tamaño de las celdas, ocasionando con ello distorsión o inadecuada distribución de la estructura de la sección de firmas localizada en la parte inferior del artefacto. Si ese fuera el caso, en esta hoja puede capturarse la información de las personas que participan en la elaboración y aprobación del artefacto, y después insertarla como imagen en cualquier otra sección del documento, siguiendo los pasos que allí se describen.

Sheet Versionamiento
B12: Tabla de Versiones y Modificaciones
B13: En la tabla siguiente se deben listar las versiones y descripciones hechas a este documento, desde el momento de su creación y cada vez que se llene y/o actualice alguna de sus pestañas. La descripción debe incluir una síntesis del cambio hecho.
B14: Para la Versión, especificar un número entero consecutivo, iniciando con 1 para la creación del documento e incrementar en decimales conforme se actualice (1.1, 1.2, 1.3, Etc.). Al terminarlo, especificar la versión final para firma, en caso necesario.
B15: Para futuros proyectos donde este documento se reutilice, el versionamiento reiniciará en versión 2, incrementando las actualizaciones igualmente con decimales (2.1, 2.2, 2.3, etc.). Posteriores reutilizaciones iniciarían entonces con versión 3, 4, etc.
C19: Versión | D19: Descripción del Cambio | E19: Responsable de la Versión | F19: Fecha
C20: 0.1 | D20: Creación del documento. | E20: Alma Quetzabeth Torres González | F20: 45604
C21: 0.2 | D21: Ajustes Se agregar "Recuperar descargas Detalle de consulta de incidencias" | E21: Alma Quetzabeth Torres González | F21: 45607
C22: 1 | D22: Versión aprobada para firma | E22: Alma Quetzabeth Torres González Mario Alberto Huerta Velázquez Roberto Benjamín Monroy Vargas

Sheet ListadoCP
B10: Portal Consulta de Incidentes
B11: Casos de Prueba
B13: 1.- Seguridad
B14: CP01/Autenticación
B15: CP02/Autenticación_Cer_Key_Incorrecto
B16: CP03/Autenticación_Contraseña_Incorrecto
B17: CP04/Inactividad
B18: CP05/Salir
B19: =COUNTA(B14:B18) -> 5
B20: 2.- CFDI - Consulta incidentes CFDI - Incidentes Servicio de Recepción
B21: CP06/FolioFiscalConsulta
B22: CP07/MsgErrorConsultaCFDIVacio
B23: CP08/MsgErrorConsultaCFDIFormatoIncorrecto
B24: CP09/MsgErrorConsultaCFDIRetenciones
B25: CP10/FolioFiscalExportarPDF
B26: CP11/FolioFiscalExportarJSON
B27: CP12/FechaConsulta
B28: CP13/FechaMsgErrorConsultaRangoFecha
B29: CP14/FechaExportarPDF
B30: CP15/FechaExportarJSON
B31: =COUNTA(B21:B30) -> 10
B32: 3.- CFDI RETENCIONES - Consulta incidentes CFDI - Incidentes Servicio de Recepción
B33: CP16/Retenciones/FolioFiscalConsulta
B34: CP17/Retenciones/MsgErrorConsultaCFDIRetVacio
B35: CP18/Retenciones/MsgErrorConsultaCFDIRetFormatoIncorrecto
B36: CP19/MsgErrorConsultaCFDIv4.0
B37: CP20/Retenciones/FolioFiscalExportarPDF
B38: CP21/Retenciones/FolioFiscalExportarJSON
B39: CP22/Retenciones/FechaConsulta
B40: CP23/Retenciones/FechaMsgErrorConsultaRangoFecha
B41: CP24/Retenciones/FechaExportarPDF
B42: CP25/Retenciones/FechaExportarJSON
B43: =COUNTA(B33:B42) -> 10
B44: 4.- Recuperar descargas Detalle de consulta de incidencias’
B45: CP26/Recuperar descargas Detalle de consulta de incidencias/Sin Peticiones
B46: CP27/Recuperar descargas Detalle de consulta de incidencias/Descargar
B47: =COUNTA(B45:B46) -> 2
B48: 5.- Recuperar descargas Detalle de consulta de incidencias’
B49: CP28/Retenciones/FechaExportarPDFmas100Registros
B50: CP29/Retenciones/FechaExportarJSONmas100Registros
...

Sheet Casos de Prueba
D10: Casos de Prueba
A12: Código del Aplicativo:
A13: ID de Requerimiento: | C13: 8211
A14: Nombre de Requerimiento: | C14: Consulta de incidentes registrado en recepción
A15: [Fase: Análisis] [Etapa: Especificación Funcional] (ACSN)
A17: ID del Caso | B17: CP | C17: Nombre del Caso | D17: Paso | E17: Descripción de Paso | F17: Resultado Esperado | G17: Comentarios | H17: Perfil de usuario para su ejecución | I17: Datos de Prueba | J17: Resultado
B18: CP01 | C18: /Autenticación
A19: POL_8211\Recepción_Consulta_Incidentes_CFDI | C19: /Autenticación | D19: 1 | E19: Usuario abre explorador | H19: Contribuyente | I19: e.firma vigentes
A20: POL_8211\Recepción_Consulta_Incidentes_CFDI | C20: /Autenticación | D20: 2 | E20: Usuario ingresa a la URL correspondiente al Portal | F20: Se muestran los datos para ingresar: Certificado (.cer) Clave privada (.Key) Contraseña de clave privada: Se muestra el campo RFC | G20: Se requiere que el usuario al ingresar al aplicativo cuente con una opción que le permita autenticarse mediante su e.firma para lo cual: • Se deberá visualizar el componente para el firmado electrónico, el cual debe apegarse a los lineamientos institucionales vigentes por el área de Seguridad del SAT. • Se solicitarán los archivos del certificado, clave privada y contraseña vigentes. • Se mostrarán los mensajes de validación de los campos proporcionados por el empleado conforme a los lineamientos institucionales vigentes por el área de Seguridad del SAT. | I20: El Usuario de negocio debe tener asignado el rol
A21: POL_8211\Recepción_Consulta_Incidentes_CFDI | C21: /Autenticación | D21: 3 | E21: Usuario da clic en buscar y selecciona el archivo correspondiente a su certificado | F21: Se muestra el dato en el campo certificado y en el campo RFC el dato del RFC del empleado
A22: POL_8211\Recepción_Consulta_Incidentes_CFDI | C22: /Autenticación | D22: 4 | E22: Usuario da clic en buscar y selecciona el archivo correspondiente a su clave privada | F22: Se muestra el dato en el campo clave privada
A23: POL_8211\Recepción_Consulta_Incidentes_CFDI | C23: /Autenticación | D23: 5 | E23: Usuario ingresa su contraseña | F23: Se muestra oculto el dato en el campo contraseña
A24: POL_8211\Recepción_Consulta_Incidentes_CFDI | C24: /Autenticación | D24: 6 | E24: Da clic en enviar | F24: Si la autenticación es correcta, el aplicativo abre la página principal del Portal de Incidencias con las opciones: - Consulta incidentes CFDI - Consulta incidentes CFDI Retenciones - Recuperar descargas Detalle de cosulta de incidencias | G24: En caso de que el empleado no cuente con los permisos asignados conforme a los roles establecidos, el aplicativo mostrará el mensaje: “El Usuario no cuenta con los privilegios de acceso” y no se va a permitir su acceso.
B25: CP02 | C25: /Autenticación_Cer_Key_Incorrecto
A26: POL_8211\Recepción_Consulta_Incidentes_CFDI | C26: /Autenticación_Cer_Key_Incorrecto | D26: 1 | E26: Usuario abre explorador | H26: Contribuyente | I26: e.firma vigentes
A27: POL_8211\Recepción_Consulta_Incidentes_CFDI | C27: /Autenticación_Cer_Key_Incorrecto | D27: 2 | E27: Usuario ingresa a la URL correspondiente al Portal | F27: Se muestran los datos para ingresar: Certificado (.cer) Clave privada (.Key) Contraseña de clave privada: Se muestra el campo RFC | I27: El Usuario de negocio debe tener asignado el rol Para efectos de este caso de prueba se requiere un archivo .cer o un archivo .Key sean incorrectos.
A28: POL_8211\Recepción_Consulta_Incidentes_CFDI | C28: /Autenticación_Cer_Key_Incorrecto | D28: 3 | E28: Usuario da clic en buscar y selecciona el archivo correspondiente a su certificado | F28: Se muestra el dato en el campo certificado y en el campo RFC el dato del RFC del empleado | G28: El Usuario previamente se autenticó y accedió al portal
A29: POL_8211\Recepción_Consulta_Incidentes_CFDI | C29: /Autenticación_Cer_Key_Incorrecto | D29: 4 | E29: Usuario da clic en buscar y selecciona el archivo correspondiente a su clave privada | F29: Se muestra el dato en el campo clave privada
A30: POL_8211\Recepción_Consulta_Incidentes_CFDI | C30: /Autenticación_Cer_Key_Incorrecto | D30: 5 | E30: Usuario ingresa su contraseña | F30: Se muestra oculto el dato en el campo contraseña
A31: POL_8211\Recepción_Consulta_Incidentes_CFDI | C31: /Autenticación_Cer_Key_Incorrecto | D31: 6 | E31: Da clic en enviar | F31: El sistema muestra mensaje: El certificado no corresponde con la llave privada. Y no permite el acceso al Portal de Incidentes
B32: CP03 | C32: /Autenticación_Contraseña_Incorrecto
A33: POL_8211\Recepción_Consulta_Incidentes_CFDI | C33: /Autenticación_Contraseña_Incorrecto | D33: 1 | E33: Usuario abre explorador | H33: Contribuyente | I33: e.firma vigentes
A34: POL_8211\Recepción_Consulta_Incidentes_CFDI | C34: /Autenticación_Contraseña_Incorrecto | D34: 2 | E34: Usuario ingresa a la URL correspondiente al Portal | F34: Se muestran los datos para ingresar: Certificado (.cer) Clave privada (.Key) Contraseña de clave privada: Se muestra el campo RFC | I34: El Usuario de negocio debe tener asignado el rol Para efectos de este caso de prueba se requiere ingresar una contraseña incorrecta.
A35: POL_8211\Recepción_Consulta_Incidentes_CFDI | C35: /Autenticación_Contraseña_Incorrecto | D35: 3 | E35: Usuario da clic en buscar y selecciona el archivo correspondiente a su certificado | F35: Se muestra el dato en el campo certificado y en el campo RFC el dato del RFC del empleado
A36: POL_8211\Recepción_Consulta_Incidentes_CFDI | C36: /Autenticación_Contraseña_Incorrecto | D36: 4 | E36: Usuario da clic en buscar y selecciona el archivo correspondiente a su clave privada | F36: Se muestra el dato en el campo clave privada
A37: POL_8211\Recepción_Consulta_Incidentes_CFDI | C37: /Autenticación_Contraseña_Incorrecto | D37: 5 | E37: Usuario ingresa su contraseña incorrecta | F37: Se muestra oculto el dato en el campo contraseña
A38: POL_8211\Recepción_Consulta_Incidentes_CFDI | C38: /Autenticación_Contraseña_Incorrecto | D38: 6 | E38: Da clic en enviar | F38: El sistema muestra mensaje: Certificado, clave privada o contraseña de clave privada inválidos, inténtelo nuevamente.
B39: CP04 | C39: /Inactividad
A40: POL_8211\Recepción_Consulta_Incidentes_CFDI | C40: /Inactividad | D40: 1 | E40: Usuario ingresa al Portal de Incidentes | F40: El sistema muestra las siguientes opciones: - Consulta incidentes CFDI - Consulta incidentes CFDI Retenciones -Recuperar descargas Detalle de consulta de incidencias’ | G40: El Usuario previamente se autenticó y accedió al portal de Incidentes | H40: Contribuyente RFC Autenticado | I40: e.firma vigentes El Usuario de negocio debe tener asignado el rol Comprobante Fiscal CFDI versión 4.0
A41: POL_8211\Recepción_Consulta_Incidentes_CFDI | C41: /Inactividad | D41: 2 | E41: Da clic en "Consulta incidentes CFDI" | F41: El sistema muestra el RFC del empleado autenticado con la opción Salir. El sistema muestra las opciones: .Tipo de consulta Opción: Folio Fiscal* .Folio Fiscal Digital Opción: Por Fechas .Fecha Inicial de Recepción* .Fecha Final de Recepción* .Versión del comprobante (El valor es por default) .PAC Botón "Consultar Incidentes"
A42: POL_8211\Recepción_Consulta_Incidentes_CFDI | C42: /Inactividad | D42: 3 | E42: Dejar la sesión abierta | F42: La sesión debe cerrarse de forma automática cuando esta se encuentre inactiva por el usuario y permanezca abierta en un plazo mayor a 10 minutos Se muestra el siguiente mensaje: "Ha salido de la sesión. Se recomienda que cierre el navegador para completar la terminación de esta sesión"
B43: CP05 | C43: /Salir
A44: POL_8211\Recepción_Consulta_Incidentes_CFDI | C44: /Salir | D44: 1 | E44: Usuario ingresa al Portal de Incidentes | F44: El sistema muestra las siguientes opciones: - Consulta Incidentes CFDI - Consulta Incidentes CFDI de Retenciones -Recuperar descargas Detalle de consulta de incidencias’ | G44: El Usuario previamente se autenticó y accedió al portal de Cancelaciones | H44: RFC Autenticado | I44: Comprobante Fiscal CFDI versión 4.0
A45: POL_8211\Recepción_Consulta_Incidentes_CFDI | C45: /Salir | D45: 2 | E45: Da clic en "Consulta Incidentes CFDI" | F45: El sistema muestra el RFC del empleado autenticado con la opción Salir. El sistema muestra las opciones: .Tipo de consulta Opción: Folio Fiscal*Tooltip .Folio Fiscal Digital Opción: Por Fechas .Fecha Inicial de Recepción* .Fecha Final de Recepción* .Versión del comprobante (El valor es por default) .PAC Botón "Consultar Incidentes"
A46: POL_8211\Recepción_Consulta_Incidentes_CFDI | C46: /Salir | D46: 3 | E46: Da clic en Cerrar Sesion | F46: Cierra la sesión del RFC
B47: CP06 | C47: /FolioFiscalConsulta
A48: POL_8211\Recepción_Consulta_Incidentes_CFDI | C48: /FolioFiscalConsulta | D48: 1 | E48: Usuario ingresa al Portal de Incidentes | F48: El sistema muestra las siguientes opciones: - Consulta incidentes CFDI - Consulta incidentes CFDI Retenciones -Recuperar descargas Detalle de consulta de incidencias’ | G48: El Usuario previamente se autenticó y accedió al portal de Incidentes | H48: Contribuyente RFC Autenticado | I48: e.firma vigentes El Usuario de negocio debe tener asignado el rol Para este caso de prueba se requiere un Comprobante Fiscal CFDI versión 4.0
A49: POL_8211\Recepción_Consulta_Incidentes_CFDI | C49: /FolioFiscalConsulta | D49: 2 | E49: Da clic en "Consulta incidentes CFDI" | F49: El sistema muestra el RFC del empleado autenticado con la opción Salir. El sistema muestra las opciones: Tipo de consulta Lista desplegable (Opciones inhabilitadas) Folio Fiscal Por Fechas Fecha Inicial de Recepción* Fecha Final de Recepción* Versión del comprobante (Valor es por default 4.0) PAC Botón "Consultar Incidentes"
A50: POL_8211\Recepción_Consulta_Incidentes_CFDI | C50: /FolioFiscalConsulta | D50: 3 | E50: Selecciona en el campo "Tipo de Consulta": Incidentes Servicio de Recepción | F50: El sistema muestra las opciones: Los campos marcados con (*) son obligatorios Tipo de consulta: Incidentes Servicio de Recepción Opción: Folio Fiscal Textbox: Folio Fiscal Digital* Opción: Por Fechas Tooltip Checkbox (Comprobantes Rechazados). Fecha Inicial de Recepción* Fecha Final de Recepción* PAC Botón "Consultar Incidentes" | G50: Al seleccionar la opción por Folio Fiscal y al colocar el cursor en el tooltip “?” el sistema deberá mostrar el siguiente mensaje y el sistema aplicará lo que menciona el mismo: "En esta opción sólo se podrán visualizar las incidencias de los comprobantes que fueron recibidos" Version por default 4.0
A51: POL_8211\Recepción_Consulta_Incidentes_CFDI | C51: /FolioFiscalConsulta | D51: 4 | E51: Selecciona el campo Folio Fiscal e ingresa el UUID del comprobante del cual se desea conocer los incidentes registrados | F51: El sistema muestra los datos que se van ingresando
...

Sheet Devops
C19: Test Case | D19: =IF('Casos de Prueba'!B18<>0,'Casos de Prueba'!B18&"-"&'Casos de Prueba'!C18,"") -> CP01-/Autenticación
D20: =IF('Casos de Prueba'!B19<>0,'Casos de Prueba'!B19&"-"&'Casos de Prueba'!C19,"") | E20: =IF(LEN($C20)>0,"",'Casos de Prueba'!D19) -> 1 | F20: =IF(LEN($C20)>0,"",'Casos de Prueba'!E19) -> Usuario abre explorador | G20: =IF(LEN($C20)>0,"",'Casos de Prueba'!F19&CHAR(10)&'Casos de Prueba'!G19)
D21: =IF('Casos de Prueba'!B20<>0,'Casos de Prueba'!B20&"-"&'Casos de Prueba'!C20,"") | E21: =IF(LEN($C21)>0,"",'Casos de Prueba'!D20) -> 2 | F21: =IF(LEN($C21)>0,"",'Casos de Prueba'!E20) -> Usuario ingresa a la URL correspondiente al Portal | G21: =IF(LEN($C21)>0,"",'Casos de Prueba'!F20&CHAR(10)&'Casos de Prueba'!G20) -> Se muestran los datos para ingresar: Certificado (.cer) Clave privada (.Key) Contraseña de clave privada: Se muestra el campo RFC Se requiere que el usuario al ingresar al aplicativo cuente con una opción que le permita autenticarse mediante su e.firma para lo cual: • Se deberá visualizar el componente para el firmado electrónico, el cual debe apegarse a los lineamientos institucionales vigentes por el área de Seguridad del SAT. • Se solicitarán los archivos del certificado, clave privada y contraseña vigentes. • Se mostrarán los mensajes de validación de los campos proporcionados por el empleado conforme a los lineamientos institucionales vigentes por el área de Seguridad del SAT.
D22: =IF('Casos de Prueba'!B21<>0,'Casos de Prueba'!B21&"-"&'Casos de Prueba'!C21,"") | E22: =IF(LEN($C22)>0,"",'Casos de Prueba'!D21) -> 3 | F22: =IF(LEN($C22)>0,"",'Casos de Prueba'!E21) -> Usuario da clic en buscar y selecciona el archivo correspondiente a su certificado | G22: =IF(LEN($C22)>0,"",'Casos de Prueba'!F21&CHAR(10)&'Casos de Prueba'!G21) -> Se muestra el dato en el campo certificado y en el campo RFC el dato del RFC del empleado
D23: =IF('Casos de Prueba'!B22<>0,'Casos de Prueba'!B22&"-"&'Casos de Prueba'!C22,"") | E23: =IF(LEN($C23)>0,"",'Casos de Prueba'!D22) -> 4 | F23: =IF(LEN($C23)>0,"",'Casos de Prueba'!E22) -> Usuario da clic en buscar y selecciona el archivo correspondiente a su clave privada | G23: =IF(LEN($C23)>0,"",'Casos de Prueba'!F22&CHAR(10)&'Casos de Prueba'!G22) -> Se muestra el dato en el campo clave privada
D24: =IF('Casos de Prueba'!B23<>0,'Casos de Prueba'!B23&"-"&'Casos de Prueba'!C23,"") | E24: =IF(LEN($C24)>0,"",'Casos de Prueba'!D23) -> 5 | F24: =IF(LEN($C24)>0,"",'Casos de Prueba'!E23) -> Usuario ingresa su contraseña | G24: =IF(LEN($C24)>0,"",'Casos de Prueba'!F23&CHAR(10)&'Casos de Prueba'!G23) -> Se muestra oculto el dato en el campo contraseña
D25: =IF('Casos de Prueba'!B24<>0,'Casos de Prueba'!B24&"-"&'Casos de Prueba'!C24,"") | E25: =IF(LEN($C25)>0,"",'Casos de Prueba'!D24) -> 6 | F25: =IF(LEN($C25)>0,"",'Casos de Prueba'!E24) -> Da clic en enviar | G25: =IF(LEN($C25)>0,"",'Casos de Prueba'!F24&CHAR(10)&'Casos de Prueba'!G24) -> Si la autenticación es correcta, el aplicativo abre la página principal del Portal de Incidencias con las opciones: - Consulta incidentes CFDI - Consulta incidentes CFDI Retenciones - Recuperar descargas Detalle de cosulta de incidencias En caso de que el empleado no cuente con los permisos asignados conforme a los roles establecidos, el aplicativo mostrará el mensaje: “El Usuario no cuenta con los privilegios de acceso” y no se va a permitir su acceso.
D26: =IF('Casos de Prueba'!B25<>0,'Casos de Prueba'!B25&"-"&'Casos de Prueba'!C25,"") -> CP02-/Autenticación_Cer_Key_Incorrecto | G26: =IF(LEN($C26)>0,"",'Casos de Prueba'!F25&CHAR(10)&'Casos de Prueba'!G25)
D27: =IF('Casos de Prueba'!B26<>0,'Casos de Prueba'!B26&"-"&'Casos de Prueba'!C26,"") | E27: =IF(LEN($C27)>0,"",'Casos de Prueba'!D26) -> 1 | F27: =IF(LEN($C27)>0,"",'Casos de Prueba'!E26) -> Usuario abre explorador | G27: =IF(LEN($C27)>0,"",'Casos de Prueba'!F26&CHAR(10)&'Casos de Prueba'!G26)
D28: =IF('Casos de Prueba'!B27<>0,'Casos de Prueba'!B27&"-"&'Casos de Prueba'!C27,"") | E28: =IF(LEN($C28)>0,"",'Casos de Prueba'!D27) -> 2 | F28: =IF(LEN($C28)>0,"",'Casos de Prueba'!E27) -> Usuario ingresa a la URL correspondiente al Portal | G28: =IF(LEN($C28)>0,"",'Casos de Prueba'!F27&CHAR(10)&'Casos de Prueba'!G27) -> Se muestran los datos para ingresar: Certificado (.cer) Clave privada (.Key) Contraseña de clave privada: Se muestra el campo RFC
D29: =IF('Casos de Prueba'!B28<>0,'Casos de Prueba'!B28&"-"&'Casos de Prueba'!C28,"") | E29: =IF(LEN($C29)>0,"",'Casos de Prueba'!D28) -> 3 | F29: =IF(LEN($C29)>0,"",'Casos de Prueba'!E28) -> Usuario da clic en buscar y selecciona el archivo correspondiente a su certificado | G29: =IF(LEN($C29)>0,"",'Casos de Prueba'!F28&CHAR(10)&'Casos de Prueba'!G28) -> Se muestra el dato en el campo certificado y en el campo RFC el dato del RFC del empleado El Usuario previamente se autenticó y accedió al portal
D30: =IF('Casos de Prueba'!B29<>0,'Casos de Prueba'!B29&"-"&'Casos de Prueba'!C29,"") | E30: =IF(LEN($C30)>0,"",'Casos de Prueba'!D29) -> 4 | F30: =IF(LEN($C30)>0,"",'Casos de Prueba'!E29) -> Usuario da clic en buscar y selecciona el archivo correspondiente a su clave privada | G30: =IF(LEN($C30)>0,"",'Casos de Prueba'!F29&CHAR(10)&'Casos de Prueba'!G29) -> Se muestra el dato en el campo clave privada
D31: =IF('Casos de Prueba'!B30<>0,'Casos de Prueba'!B30&"-"&'Casos de Prueba'!C30,"") | E31: =IF(LEN($C31)>0,"",'Casos de Prueba'!D30) -> 5 | F31: =IF(LEN($C31)>0,"",'Casos de Prueba'!E30) -> Usuario ingresa su contraseña | G31: =IF(LEN($C31)>0,"",'Casos de Prueba'!F30&CHAR(10)&'Casos de Prueba'!G30) -> Se muestra oculto el dato en el campo contraseña
D32: =IF('Casos de Prueba'!B31<>0,'Casos de Prueba'!B31&"-"&'Casos de Prueba'!C31,"") | E32: =IF(LEN($C32)>0,"",'Casos de Prueba'!D31) -> 6 | F32: =IF(LEN($C32)>0,"",'Casos de Prueba'!E31) -> Da clic en enviar | G32: =IF(LEN($C32)>0,"",'Casos de Prueba'!F31&CHAR(10)&'Casos de Prueba'!G31) -> El sistema muestra mensaje: El certificado no corresponde con la llave privada. Y no permite el acceso al Portal de Incidentes
D33: =IF('Casos de Prueba'!B32<>0,'Casos de Prueba'!B32&"-"&'Casos de Prueba'!C32,"") -> CP03-/Autenticación_Contraseña_Incorrecto | G33: =IF(LEN($C33)>0,"",'Casos de Prueba'!F32&CHAR(10)&'Casos de Prueba'!G32)
D34: =IF('Casos de Prueba'!B33<>0,'Casos de Prueba'!B33&"-"&'Casos de Prueba'!C33,"") | E34: =IF(LEN($C34)>0,"",'Casos de Prueba'!D33) -> 1 | F34: =IF(LEN($C34)>0,"",'Casos de Prueba'!E33) -> Usuario abre explorador | G34: =IF(LEN($C34)>0,"",'Casos de Prueba'!F33&CHAR(10)&'Casos de Prueba'!G33)
D35: =IF('Casos de Prueba'!B34<>0,'Casos de Prueba'!B34&"-"&'Casos de Prueba'!C34,"") | E35: =IF(LEN($C35)>0,"",'Casos de Prueba'!D34) -> 2 | F35: =IF(LEN($C35)>0,"",'Casos de Prueba'!E34) -> Usuario ingresa a la URL correspondiente al Portal | G35: =IF(LEN($C35)>0,"",'Casos de Prueba'!F34&CHAR(10)&'Casos de Prueba'!G34) -> Se muestran los datos para ingresar: Certificado (.cer) Clave privada (.Key) Contraseña de clave privada: Se muestra el campo RFC
D36: =IF('Casos de Prueba'!B35<>0,'Casos de Prueba'!B35&"-"&'Casos de Prueba'!C35,"") | E36: =IF(LEN($C36)>0,"",'Casos de Prueba'!D35) -> 3 | F36: =IF(LEN($C36)>0,"",'Casos de Prueba'!E35) -> Usuario da clic en buscar y selecciona el archivo correspondiente a su certificado | G36: =IF(LEN($C36)>0,"",'Casos de Prueba'!F35&CHAR(10)&'Casos de Prueba'!G35) -> Se muestra el dato en el campo certificado y en el campo RFC el dato del RFC del empleado
D37: =IF('Casos de Prueba'!B36<>0,'Casos de Prueba'!B36&"-"&'Casos de Prueba'!C36,"") | E37: =IF(LEN($C37)>0,"",'Casos de Prueba'!D36) -> 4 | F37: =IF(LEN($C37)>0,"",'Casos de Prueba'!E36) -> Usuario da clic en buscar y selecciona el archivo correspondiente a su clave privada | G37: =IF(LEN($C37)>0,"",'Casos de Prueba'!F36&CHAR(10)&'Casos de Prueba'!G36) -> Se muestra el dato en el campo clave privada
D38: =IF('Casos de Prueba'!B37<>0,'Casos de Prueba'!B37&"-"&'Casos de Prueba'!C37,"") | E38: =IF(LEN($C38)>0,"",'Casos de Prueba'!D37) -> 5 | F38: =IF(LEN($C38)>0,"",'Casos de Prueba'!E37) -> Usuario ingresa su contraseña incorrecta | G38: =IF(LEN($C38)>0,"",'Casos de Prueba'!F37&CHAR(10)&'Casos de Prueba'!G37) -> Se muestra oculto el dato en el campo contraseña
D39: =IF('Casos de Prueba'!B38<>0,'Casos de Prueba'!B38&"-"&'Casos de Prueba'!C38,"") | E39: =IF(LEN($C39)>0,"",'Casos de Prueba'!D38) -> 6 | F39: =IF(LEN($C39)>0,"",'Casos de Prueba'!E38) -> Da clic en enviar | G39: =IF(LEN($C39)>0,"",'Casos de Prueba'!F38&CHAR(10)&'Casos de Prueba'!G38) -> El sistema muestra mensaje: Certificado, clave privada o contraseña de clave privada inválidos, inténtelo nuevamente.
D40: =IF('Casos de Prueba'!B39<>0,'Casos de Prueba'!B39&"-"&'Casos de Prueba'!C39,"") -> CP04-/Inactividad | G40: =IF(LEN($C40)>0,"",'Casos de Prueba'!F39&CHAR(10)&'Casos de Prueba'!G39)
D41: =IF('Casos de Prueba'!B40<>0,'Casos de Prueba'!B40&"-"&'Casos de Prueba'!C40,"") | E41: =IF(LEN($C41)>0,"",'Casos de Prueba'!D40) -> 1 | F41: =IF(LEN($C41)>0,"",'Casos de Prueba'!E40) -> Usuario ingresa al Portal de Incidentes | G41: =IF(LEN($C41)>0,"",'Casos de Prueba'!F40&CHAR(10)&'Casos de Prueba'!G40) -> El sistema muestra las siguientes opciones: - Consulta incidentes CFDI - Consulta incidentes CFDI Retenciones -Recuperar descargas Detalle de consulta de incidencias’ El Usuario previamente se autenticó y accedió al portal de Incidentes
D42: =IF('Casos de Prueba'!B41<>0,'Casos de Prueba'!B41&"-"&'Casos de Prueba'!C41,"") | E42: =IF(LEN($C42)>0,"",'Casos de Prueba'!D41) -> 2 | F42: =IF(LEN($C42)>0,"",'Casos de Prueba'!E41) -> Da clic en "Consulta incidentes CFDI" | G42: =IF(LEN($C42)>0,"",'Casos de Prueba'!F41&CHAR(10)&'Casos de Prueba'!G41) -> El sistema muestra el RFC del empleado autenticado con la opción Salir. El sistema muestra las opciones: .Tipo de consulta Opción: Folio Fiscal* .Folio Fiscal Digital Opción: Por Fechas .Fecha Inicial de Recepción* .Fecha Final de Recepción* .Versión del comprobante (El valor es por default) .PAC Botón "Consultar Incidentes"
D43: =IF('Casos de Prueba'!B42<>0,'Casos de Prueba'!B42&"-"&'Casos de Prueba'!C42,"") | E43: =IF(LEN($C43)>0,"",'Casos de Prueba'!D42) -> 3 | F43: =IF(LEN($C43)>0,"",'Casos de Prueba'!E42) -> Dejar la sesión abierta | G43: =IF(LEN($C43)>0,"",'Casos de Prueba'!F42&CHAR(10)&'Casos de Prueba'!G42) -> La sesión debe cerrarse de forma automática cuando esta se encuentre inactiva por el usuario y permanezca abierta en un plazo mayor a 10 minutos Se muestra el siguiente mensaje: "Ha salido de la sesión. Se recomienda que cierre el navegador para completar la terminación de esta sesión"
D44: =IF('Casos de Prueba'!B43<>0,'Casos de Prueba'!B43&"-"&'Casos de Prueba'!C43,"") -> CP05-/Salir | G44: =IF(LEN($C44)>0,"",'Casos de Prueba'!F43&CHAR(10)&'Casos de Prueba'!G43)
D45: =IF('Casos de Prueba'!B44<>0,'Casos de Prueba'!B44&"-"&'Casos de Prueba'!C44,"") | E45: =IF(LEN($C45)>0,"",'Casos de Prueba'!D44) -> 1 | F45: =IF(LEN($C45)>0,"",'Casos de Prueba'!E44) -> Usuario ingresa al Portal de Incidentes | G45: =IF(LEN($C45)>0,"",'Casos de Prueba'!F44&CHAR(10)&'Casos de Prueba'!G44) -> El sistema muestra las siguientes opciones: - Consulta Incidentes CFDI - Consulta Incidentes CFDI de Retenciones -Recuperar descargas Detalle de consulta de incidencias’ El Usuario previamente se autenticó y accedió al portal de Cancelaciones
D46: =IF('Casos de Prueba'!B45<>0,'Casos de Prueba'!B45&"-"&'Casos de Prueba'!C45,"") | E46: =IF(LEN($C46)>0,"",'Casos de Prueba'!D45) -> 2 | F46: =IF(LEN($C46)>0,"",'Casos de Prueba'!E45) -> Da clic en "Consulta Incidentes CFDI" | G46: =IF(LEN($C46)>0,"",'Casos de Prueba'!F45&CHAR(10)&'Casos de Prueba'!G45) -> El sistema muestra el RFC del empleado autenticado con la opción Salir. El sistema muestra las opciones: .Tipo de consulta Opción: Folio Fiscal*Tooltip .Folio Fiscal Digital Opción: Por Fechas .Fecha Inicial de Recepción* .Fecha Final de Recepción* .Versión del comprobante (El valor es por default) .PAC Botón "Consultar Incidentes"
D47: =IF('Casos de Prueba'!B46<>0,'Casos de Prueba'!B46&"-"&'Casos de Prueba'!C46,"") | E47: =IF(LEN($C47)>0,"",'Casos de Prueba'!D46) -> 3 | F47: =IF(LEN($C47)>0,"",'Casos de Prueba'!E46) -> Da clic en Cerrar Sesion | G47: =IF(LEN($C47)>0,"",'Casos de Prueba'!F46&CHAR(10)&'Casos de Prueba'!G46) -> Cierra la sesión del RFC
D48: =IF('Casos de Prueba'!B47<>0,'Casos de Prueba'!B47&"-"&'Casos de Prueba'!C47,"") -> CP06-/FolioFiscalConsulta | G48: =IF(LEN($C48)>0,"",'Casos de Prueba'!F47&CHAR(10)&'Casos de Prueba'!G47)
D49: =IF('Casos de Prueba'!B48<>0,'Casos de Prueba'!B48&"-"&'Casos de Prueba'!C48,"") | E49: =IF(LEN($C49)>0,"",'Casos de Prueba'!D48) -> 1 | F49: =IF(LEN($C49)>0,"",'Casos de Prueba'!E48) -> Usuario ingresa al Portal de Incidentes | G49: =IF(LEN($C49)>0,"",'Casos de Prueba'!F48&CHAR(10)&'Casos de Prueba'!G48) -> El sistema muestra las siguientes opciones: - Consulta incidentes CFDI - Consulta incidentes CFDI Retenciones -Recuperar descargas Detalle de consulta de incidencias’ El Usuario previamente se autenticó y accedió al portal de Incidentes
D50: =IF('Casos de Prueba'!B49<>0,'Casos de Prueba'!B49&"-"&'Casos de Prueba'!C49,"") | E50: =IF(LEN($C50)>0,"",'Casos de Prueba'!D49) -> 2 | F50: =IF(LEN($C50)>0,"",'Casos de Prueba'!E49) -> Da clic en "Consulta incidentes CFDI" | G50: =IF(LEN($C50)>0,"",'Casos de Prueba'!F49&CHAR(10)&'Casos de Prueba'!G49) -> El sistema muestra el RFC del empleado autenticado con la opción Salir. El sistema muestra las opciones: Tipo de consulta Lista desplegable (Opciones inhabilitadas) Folio Fiscal Por Fechas Fecha Inicial de Recepción* Fecha Final de Recepción* Versión del comprobante (Valor es por default 4.0) PAC Botón "Consultar Incidentes"
D51: =IF('Casos de Prueba'!B50<>0,'Casos de Prueba'!B50&"-"&'Casos de Prueba'!C50,"") | E51: =IF(LEN($C51)>0,"",'Casos de Prueba'!D50) -> 3 | F51: =IF(LEN($C51)>0,"",'Casos de Prueba'!E50) -> Selecciona en el campo "Tipo de Consulta": Incidentes Servicio de Recepción | G51: =IF(LEN($C51)>0,"",'Casos de Prueba'!F50&CHAR(10)&'Casos de Prueba'!G50) -> El sistema muestra las opciones: Los campos marcados con (*) son obligatorios Tipo de consulta: Incidentes Servicio de Recepción Opción: Folio Fiscal Textbox: Folio Fiscal Digital* Opción: Por Fechas Tooltip Checkbox (Comprobantes Rechazados). Fecha Inicial de Recepción* Fecha Final de Recepción* PAC Botón "Consultar Incidentes" Al seleccionar la opción por Folio Fiscal y al colocar el cursor en el tooltip “?” el sistema deberá mostrar el siguiente mensaje y el sistema aplicará lo que menciona el mismo: "En esta opción sólo se podrán visualizar las incidencias de los comprobantes que fueron recibidos" Version por default 4.0
D52: =IF('Casos de Prueba'!B51<>0,'Casos de Prueba'!B51&"-"&'Casos de Prueba'!C51,"") | E52: =IF(LEN($C52)>0,"",'Casos de Prueba'!D51) -> 4 | F52: =IF(LEN($C52)>0,"",'Casos de Prueba'!E51) -> Selecciona el campo Folio Fiscal e ingresa el UUID del comprobante del cual se desea conocer los incidentes registrados | G52: =IF(LEN($C52)>0,"",'Casos de Prueba'!F51&CHAR(10)&'Casos de Prueba'!G51) -> El sistema muestra los datos que se van ingresando
D53: =IF('Casos de Prueba'!B52<>0,'Casos de Prueba'!B52&"-"&'Casos de Prueba'!C52,"") | E53: =IF(LEN($C53)>0,"",'Casos de Prueba'!D52) -> 5 | F53: =IF(LEN($C53)>0,"",'Casos de Prueba'!E52) -> Se da clic en el botón "Consultar Incidentes" | G53: =IF(LEN($C53)>0,"",'Casos de Prueba'!F52&CHAR(10)&'Casos de Prueba'!G52) -> El servicio inhabilita la sección de Fecha Inicial y Final de Recepción. El sistema deberá mostrar en una tabla los resultados obtenidos de la consulta: • RFC del PAC • Nombre o Razón Social • Evento • Mensaje • Total • Detalle (Boton)
D54: =IF('Casos de Prueba'!B53<>0,'Casos de Prueba'!B53&"-"&'Casos de Prueba'!C53,"") | E54: =IF(LEN($C54)>0,"",'Casos de Prueba'!D53) -> 6 | F54: =IF(LEN($C54)>0,"",'Casos de Prueba'!E53) -> Da clic en Cerrar Sesion | G54: =IF(LEN($C54)>0,"",'Casos de Prueba'!F53&CHAR(10)&'Casos de Prueba'!G53) -> Cierra la sesión del RFC Fin del caso
D55: =IF('Casos de Prueba'!B54<>0,'Casos de Prueba'!B54&"-"&'Casos de Prueba'!C54,"") -> CP07-/MsgErrorConsultaCFDIVacio | G55: =IF(LEN($C55)>0,"",'Casos de Prueba'!F54&CHAR(10)&'Casos de Prueba'!G54)
D56: =IF('Casos de Prueba'!B55<>0,'Casos de Prueba'!B55&"-"&'Casos de Prueba'!C55,"") | E56: =IF(LEN($C56)>0,"",'Casos de Prueba'!D55) -> 1 | F56: =IF(LEN($C56)>0,"",'Casos de Prueba'!E55) -> Usuario ingresa al Portal de Incidentes | G56: =IF(LEN($C56)>0,"",'Casos de Prueba'!F55&CHAR(10)&'Casos de Prueba'!G55) -> El sistema muestra las siguientes opciones: - Consulta incidentes CFDI - Consulta incidentes CFDI Retenciones -Recuperar descargas Detalle de consulta de incidencias’ El Usuario previamente se autenticó y accedió al portal de Incidentes
D57: =IF('Casos de Prueba'!B56<>0,'Casos de Prueba'!B56&"-"&'Casos de Prueba'!C56,"") | E57: =IF(LEN($C57)>0,"",'Casos de Prueba'!D56) -> 2 | F57: =IF(LEN($C57)>0,"",'Casos de Prueba'!E56) -> Da clic en "Consulta incidentes CFDI" | G57: =IF(LEN($C57)>0,"",'Casos de Prueba'!F56&CHAR(10)&'Casos de Prueba'!G56) -> El sistema muestra el RFC del empleado autenticado con la opción Salir. El sistema muestra las opciones: Tipo de consulta Lista desplegable (Opciones inhabilitadas) Folio Fiscal Por Fechas Fecha Inicial de Recepción* Fecha Final de Recepción* Versión del comprobante (Valor es por default 4.0) PAC Botón "Consultar Incidentes"
D58: =IF('Casos de Prueba'!B57<>0,'Casos de Prueba'!B57&"-"&'Casos de Prueba'!C57,"") | E58: =IF(LEN($C58)>0,"",'Casos de Prueba'!D57) -> 3 | F58: =IF(LEN($C58)>0,"",'Casos de Prueba'!E57) -> Selecciona en el campo "Tipo de Consulta": Incidentes Servicio de Recepción | G58: =IF(LEN($C58)>0,"",'Casos de Prueba'!F57&CHAR(10)&'Casos de Prueba'!G57) -> El sistema muestra las opciones: Los campos marcados con (*) son obligatorios Tipo de consulta: Incidentes Servicio de Recepción Opción: Folio Fiscal Textbox: Folio Fiscal Digital* Opción: Por Fechas Tooltip Checkbox (Comprobantes Rechazados). Fecha Inicial de Recepción* Fecha Final de Recepción* PAC Botón "Consultar Incidentes" Al seleccionar la opción por Folio Fiscal y al colocar el cursor en el tooltip “?” el sistema deberá mostrar el siguiente mensaje y el sistema aplicará lo que menciona el mismo: "En esta opción sólo se podrán visualizar las incidencias de los comprobantes que fueron recibidos" Version por default 4.0
...

Sheet Devops_Carga
B1: Work Item type | C1: Title | D1: Step Action | E1: Step expected
B2: Test Case | C2: CP01-/Autenticación
D3: 1 | E3: Usuario abre explorador
D4: 2 | E4: Usuario ingresa a la URL correspondiente al Portal | F4: Se muestran los datos para ingresar: Certificado (.cer) Clave privada (.Key) Contraseña de clave privada: Se muestra el campo RFC Se requiere que el usuario al ingresar al aplicativo cuente con una opción que le permita autenticarse mediante su e.firma para lo cual: • Se deberá visualizar el componente para el firmado electrónico, el cual debe apegarse a los lineamientos institucionales vigentes por el área de Seguridad del SAT. • Se solicitarán los archivos del certificado, clave privada y contraseña vigentes. • Se mostrarán los mensajes de validación de los campos proporcionados por el empleado conforme a los lineamientos institucionales vigentes por el área de Seguridad del SAT.
D5: 3 | E5: Usuario da clic en buscar y selecciona el archivo correspondiente a su certificado | F5: Se muestra el dato en el campo certificado y en el campo RFC el dato del RFC del empleado
D6: 4 | E6: Usuario da clic en buscar y selecciona el archivo correspondiente a su clave privada | F6: Se muestra el dato en el campo clave privada
D7: 5 | E7: Usuario ingresa su contraseña | F7: Se muestra oculto el dato en el campo contraseña
D8: 6 | E8: Da clic en enviar | F8: Si la autenticación es correcta, el aplicativo abre la página principal del Portal de Incidencias con las opciones: - Consulta incidentes CFDI - Consulta incidentes CFDI Retenciones - Recuperar descargas Detalle de cosulta de incidencias En caso de que el empleado no cuente con los permisos asignados conforme a los roles establecidos, el aplicativo mostrará el mensaje: “El Usuario no cuenta con los privilegios de acceso” y no se va a permitir su acceso.
C9: CP02-/Autenticación_Cer_Key_Incorrecto
D10: 1 | E10: Usuario abre explorador
D11: 2 | E11: Usuario ingresa a la URL correspondiente al Portal | F11: Se muestran los datos para ingresar: Certificado (.cer) Clave privada (.Key) Contraseña de clave privada: Se muestra el campo RFC
D12: 3 | E12: Usuario da clic en buscar y selecciona el archivo correspondiente a su certificado | F12: Se muestra el dato en el campo certificado y en el campo RFC el dato del RFC del empleado El Usuario previamente se autenticó y accedió al portal
D13: 4 | E13: Usuario da clic en buscar y selecciona el archivo correspondiente a su clave privada | F13: Se muestra el dato en el campo clave privada
D14: 5 | E14: Usuario ingresa su contraseña | F14: Se muestra oculto el dato en el campo contraseña
D15: 6 | E15: Da clic en enviar | F15: El sistema muestra mensaje: El certificado no corresponde con la llave privada. Y no permite el acceso al Portal de Incidentes
C16: CP03-/Autenticación_Contraseña_Incorrecto
D17: 1 | E17: Usuario abre explorador
D18: 2 | E18: Usuario ingresa a la URL correspondiente al Portal | F18: Se muestran los datos para ingresar: Certificado (.cer) Clave privada (.Key) Contraseña de clave privada: Se muestra el campo RFC
D19: 3 | E19: Usuario da clic en buscar y selecciona el archivo correspondiente a su certificado | F19: Se muestra el dato en el campo certificado y en el campo RFC el dato del RFC del empleado
D20: 4 | E20: Usuario da clic en buscar y selecciona el archivo correspondiente a su clave privada | F20: Se muestra el dato en el campo clave privada
D21: 5 | E21: Usuario ingresa su contraseña incorrecta | F21: Se muestra oculto el dato en el campo contraseña
D22: 6 | E22: Da clic en enviar | F22: El sistema muestra mensaje: Certificado, clave privada o contraseña de clave privada inválidos, inténtelo nuevamente.
C23: CP04-/Inactividad
D24: 1 | E24: Usuario ingresa al Portal de Incidentes | F24: El sistema muestra las siguientes opciones: - Consulta incidentes CFDI - Consulta incidentes CFDI Retenciones -Recuperar descargas Detalle de consulta de incidencias’ El Usuario previamente se autenticó y accedió al portal de Incidentes
D25: 2 | E25: Da clic en "Consulta incidentes CFDI" | F25: El sistema muestra el RFC del empleado autenticado con la opción Salir. El sistema muestra las opciones: .Tipo de consulta Opción: Folio Fiscal* .Folio Fiscal Digital Opción: Por Fechas .Fecha Inicial de Recepción* .Fecha Final de Recepción* .Versión del comprobante (El valor es por default) .PAC Botón "Consultar Incidentes"
D26: 3 | E26: Dejar la sesión abierta | F26: La sesión debe cerrarse de forma automática cuando esta se encuentre inactiva por el usuario y permanezca abierta en un plazo mayor a 10 minutos Se muestra el siguiente mensaje: "Ha salido de la sesión. Se recomienda que cierre el navegador para completar la terminación de esta sesión"
C27: CP05-/Salir
D28: 1 | E28: Usuario ingresa al Portal de Incidentes | F28: El sistema muestra las siguientes opciones: - Consulta Incidentes CFDI - Consulta Incidentes CFDI de Retenciones -Recuperar descargas Detalle de consulta de incidencias’ El Usuario previamente se autenticó y accedió al portal de Cancelaciones
D29: 2 | E29: Da clic en "Consulta Incidentes CFDI" | F29: El sistema muestra el RFC del empleado autenticado con la opción Salir. El sistema muestra las opciones: .Tipo de consulta Opción: Folio Fiscal*Tooltip .Folio Fiscal Digital Opción: Por Fechas .Fecha Inicial de Recepción* .Fecha Final de Recepción* .Versión del comprobante (El valor es por default) .PAC Botón "Consultar Incidentes"
D30: 3 | E30: Da clic en Cerrar Sesion | F30: Cierra la sesión del RFC
C31: CP06-/FolioFiscalConsulta
D32: 1 | E32: Usuario ingresa al Portal de Incidentes | F32: El sistema muestra las siguientes opciones: - Consulta incidentes CFDI - Consulta incidentes CFDI Retenciones -Recuperar descargas Detalle de consulta de incidencias’ El Usuario previamente se autenticó y accedió al portal de Incidentes
D33: 2 | E33: Da clic en "Consulta incidentes CFDI" | F33: El sistema muestra el RFC del empleado autenticado con la opción Salir. El sistema muestra las opciones: Tipo de consulta Lista desplegable (Opciones inhabilitadas) Folio Fiscal Por Fechas Fecha Inicial de Recepción* Fecha Final de Recepción* Versión del comprobante (Valor es por default 4.0) PAC Botón "Consultar Incidentes"
D34: 3 | E34: Selecciona en el campo "Tipo de Consulta": Incidentes Servicio de Recepción | F34: El sistema muestra las opciones: Los campos marcados con (*) son obligatorios Tipo de consulta: Incidentes Servicio de Recepción Opción: Folio Fiscal Textbox: Folio Fiscal Digital* Opción: Por Fechas Tooltip Checkbox (Comprobantes Rechazados). Fecha Inicial de Recepción* Fecha Final de Recepción* PAC Botón "Consultar Incidentes" Al seleccionar la opción por Folio Fiscal y al colocar el cursor en el tooltip “?” el sistema deberá mostrar el siguiente mensaje y el sistema aplicará lo que menciona el mismo: "En esta opción sólo se podrán visualizar las incidencias de los comprobantes que fueron recibidos" Version por default 4.0
D35: 4 | E35: Selecciona el campo Folio Fiscal e ingresa el UUID del comprobante del cual se desea conocer los incidentes registrados | F35: El sistema muestra los datos que se van ingresando
D36: 5 | E36: Se da clic en el botón "Consultar Incidentes" | F36: El servicio inhabilita la sección de Fecha Inicial y Final de Recepción. El sistema deberá mostrar en una tabla los resultados obtenidos de la consulta: • RFC del PAC • Nombre o Razón Social • Evento • Mensaje • Total • Detalle (Boton)
D37: 6 | E37: Da clic en Cerrar Sesion | F37: Cierra la sesión del RFC Fin del caso
C38: CP07-/MsgErrorConsultaCFDIVacio
D39: 1 | E39: Usuario ingresa al Portal de Incidentes | F39: El sistema muestra las siguientes opciones: - Consulta incidentes CFDI - Consulta incidentes CFDI Retenciones -Recuperar descargas Detalle de consulta de incidencias’ El Usuario previamente se autenticó y accedió al portal de Incidentes
D40: 2 | E40: Da clic en "Consulta incidentes CFDI" | F40: El sistema muestra el RFC del empleado autenticado con la opción Salir. El sistema muestra las opciones: Tipo de consulta Lista desplegable (Opciones inhabilitadas) Folio Fiscal Por Fechas Fecha Inicial de Recepción* Fecha Final de Recepción* Versión del comprobante (Valor es por default 4.0) PAC Botón "Consultar Incidentes"
...

Sheet Firmas Conformidad
B2: El uso de la siguiente Sección de Firmas de Conformidad es opcional, dependiendo de la necesidad del consumidor de la información.
B3: Instrucciones:
B4: Registrar en la tabla la información de los participantes en la elaboración, revisión, aprobación, etc. del artefacto.
B7: FIRMAS DE CONFORMIDAD
B8: Autorizó | C8: Autorizó
B10: Nombre: Pedro López Bernal. | C10: Nombre: Diana Maribel Velazquez Barroso
B11: Puesto: Administrador de Gestión de Servicios y Trámites con Medios Electrónicos 3 | C11: Puesto: Administradora de Soluciones de Negocio 3
B12: Fecha: | C12: Fecha:
B13: ‍
B14: Revisó | C14: Revisó
B15: Nombre: Mario Alberto Huerta Velazquez | C15: Nombre: Roberto Benjamín Monroy Vargas
B16: Puesto: Subadministrador de Gestión de Servicios y Trámites con Medios Electrónicos | C16: Puesto: Subadministrador de Soluciones de Negocio
B17: Fecha: | C17: Fecha:
B19: Elaboró | C19: Elaboró
B20: Nombre: Nadia Anahí Ortega Nava | C20: Nombre: Alma Quetzabeth Torres González
B21: Puesto: Jefe de Departamento de Gestión de Servicios y Trámites con Medios Electrónicos | C21: Puesto: Jefe de Departamento de Soluciones de Negocio
B22: Fecha: | C22: Fecha:

Sheet Encabezado
C1: Tomar como referencia el siguiente Encabezado para edición:
H4: Administración General de Comunicaciones y Tecnologías de la Información
H6: Marco Documental 7.0
C7: Fecha de aprobación del Template: 01/11/2021 | E7: Requerimientos de Pruebas Clave del Documento XX_RDP_REQPRUEBAS.xlsx [Nomenclatura del artefacto, punto, extensión del archivo actual] Servicio Administración del Ciclo de Vida de Aplicaciones de TIC Central Dueña: Administración Central de Soluciones de Negocio (ACSN) Central que Elabora: ACSN Central Consumidora: ACDMA | J7: Versión del template: 7.00
H13: Administración General de Comunicaciones y Tecnologías de la Información
H15: Marco Documental 7.0
C16: Fecha de aprobación del Template: 01/11/2021 | E16: Requerimientos de Pruebas RDP-Consulta_Incidentes_Negocio.xlsx | J16: Versión del template: 7.00
