Workbook

Sheet Instrucciones
B15: Objetivo: Identificar los insumos necesarios para pruebas de aceptación de usuario, a través de los casos de prueba, ambientes requeridos, especificación de los datos, cobertura de escenarios y atributos relacionados, a fin de contar con la integración de datos suficientes para la ejecución de las pruebas de la solución tecnológica con el usuario.
B17: Guía de Uso: 1.- Las pestañas "Casos de Prueba" y "Ambientes Requeridos" serán llenadas por la Administración Central de Soluciones de Negocio (ACSN), en la Fase Análisis, Etapa Especificación Funcional. 2.- Las pestañas "Interfaz de Usuario" y "Cobertura" serán llenadas en la Fase Desarrollo por las áreas ténicas que deban participar. En la primera también participará la ACSN en la Fase Pruebas, Etapa Pruebas Funcionales (AVL), por tema de Lineamientos Gráficos del SIAT, y para reflejar resultado de dichas pruebas. 3.- El documento está firmado por los responsables del llenado, incluyendo por el negocio cuando participa en la autorización. 4.- Si la pestaña "Casos de Prueba" incluye varias páginas, debe imprimirse sólo la página que contienen las firmas. Una vez firmado, debe digitalizarse y almacenarse en el repositorio como sustento junto con el archivo de Excel que corresponda a todo el documento. 5.- Si fuera necesario reservar información generada en esta plantilla, se hará bajo lo estipulado en la Ley General de Transparencia y Acceso a la Información Pública vigente (LGTAIP), pudiendo consultar a la ACPPI para su aplicación. (Ver abajo "Nota acerca de Irformación Reservada"). 6.- La aplicación de la sección de Firmas es opcional,dependiendo de las necesidades del consumidor, pero al contener temas de usuario de Negocio es importante la firma de éste.
B18: Nota acerca de Información Reservada Es reponsabilidad de cada requisitador la identificación de la información que se genere en este formato y así determinar si se cuenta con causas que originen la reserva de la misma, apegándose estrictamente a lo señalado en los ordenamientos jurídicos vigentes en materia de Transparencia. En caso de detectar información sensible (Reservada), se tendrá que indicar en la sección u hoja que lo amerite de este documento, en la parte inferior del texto, con la siguiente señalización: [Área dueña de la Información XX, clasificada como Reservada con Fundamento Legal XX, Motivación XX, Fecha de clasificación XX y Periodo de la reserva XX]. Ejemplo: "La información contenida en este documento pertenece a la Administración Central de Soluciones de Negocio, teniendo carácter de Reservada a partir del 01 de abril de 2018, con un periodo de reserva de 5 años, por tratarse de información que de revelarse puede causar un serio perjuicio a la recaudación de las contribuciones. Lo anterior tiene su fundamento en el artículo 113, fracción IV, de la Ley General de Transparencia y Acceso a la Información Pública."
B20: Hoja | D20: Descripción
B21: Casos de Prueba | D21: Esta hoja se utiliza para la documentación detallada de los casos de pruebas que serán utilizados en la ejecución de pruebas.
D22: Registra varios casos de prueba, con la finalidad de agrupar en un solo documento una cantidad suficiente de casos que pueda ser aprovechada para la importación de casos de prueba en alguna herramienta automatizada, o bien, para obtener de ella la información de casos de prueba. También se utiliza para especificar los elementos donde se emplearán los datos (Datos de Prueba)
D23: Criterios de Aceptación
D24: • El documento es utilizado de acuerdo al formato establecido. El documento cumple con el Marco Documental vigente. • El documento no contiene faltas de ortografía. • Cuando no se llene un renglón-columna, se deberá especificar el motivo por el cual no se registra la información, conteniendo al menos un "N/A". Ningún campo debe estar vacío. ●No se combinan celdas (exceptuando la sección de firmas) ●No incluye fórmulas en ningún renglón-columna • El documento describe detalladamente paso a paso las actividades a seguir para la validación de requerimientos del sistema. • El documento describe en cada paso una acción y una respuesta esperada que puede ser evaluada. El documento está firmado por los responsables del llenado, incluyendo por el negocio cuando participa en la autorización.
B26: Hoja | D26: Descripción
B27: Ambientes Requeridos | D27: Registra elementos de información sobre repositorios y ambientes necesarios para las pruebas y sus características, relacionadas con criterios que debe cubrir la información que se requiere para las pruebas; cantidad de datos requeridos para la ejecución de la prueba; datos o campos solicitados; condiciones que se deben cubrir para la extracción de datos y comentarios adicionales.
D28: Criterios de Aceptación
D29: * El documento es utilizado de acuerdo al formato establecido. * El documento cumple con el Marco Documental vigente. * El documento no contiene faltas de ortografía. * Cuando no se llene un renglón-columna, se deberá especificar el motivo por el cual no se registra la información, conteniendo al menos un "N/A". Ningún campo debe estar vacío. * El documento está firmado por los responsables del llenado, incluyendo por el negocio cuando participa en la autorización.
B31: Hoja | D31: Descripción
B32: Interfaz de Usuario | D32: Esta hoja aplica por la naturaleza de la solución tecnológica integrada que haya sido requerida. Se utiliza para validar que se cumplan los criterios definidos para la Interfaz de Usuario, incluyendo la aplicación y verificación de los Lineamientos Gráficos del SIAT, cuando sea el caso.
D33: Se detallan los puntos a validar de interfaz de usuario (interfaz gráfica) de las aplicaciones, como encabezados, pie de página, colores, alineación, etiquetas, listas desplegables, áreas de búsqueda, etc, etc.
D34: Criterios de Aceptación
D35: • El documento es utilizado de acuerdo al formato establecido. • El documento no contiene faltas de ortografía. • Cuando no se llene un renglón-columna, se deberá especificar el motivo por el cual no se registra la información. • Cada una de las características consideradas en esta pestaña estarán asociadas al contenido del artefacto "Especificación de Interacción de Usuario", en caso de ajustes o situaciones que expongan desviación al documento en comento, deberá ajustarse. • Cada defecto detectado deberá registrarse en la herramienta correspondiente para su atención y cierre.
B37: Hoja | D37: Descripción
B38: Cobertura | D38: Esta hoja se utiliza para identificar y detallar la cobertura de la prueba basada en complejidad ciclomática, para asegurar que se diseñen tantos casos de prueba como sean necesarios para que cada condición se ejecute al menos una vez con un valor verdadero, y al menos una vez uno falso.
D40: Criterios de Aceptación
D41: • El documento es utilizado de acuerdo al formato establecido. • El documento no contiene faltas de ortografía. • Cuando no se llene un renglón-columna, se deberá especificar el motivo por el cual no se registra la información. • El documento describe detalladamente los escenarios de prueba necesarios para que cada condición se ejecute al menos una vez con un valor verdadero y al menos una vez uno falso.
B43: Hoja | D43: Descripción
B44: Encabezado_Imagen | D44: En artefactos tipo Excel, la inserción del Encabezado como imagen en el mismo documento, puede hacerse como una alternativa cuando por la naturaleza y cantidad de información registrada en él, se hace necesario ampliar significativamente el tamaño de las celdas, ocasionando con ello distorsión o inadecuada distribución de la estructura del Encabezado del artefacto. Si ese fuera el caso, en esta hoja puede configurarse el Encabezado del artefacto y después insertarlo como imagen en cualquier otra sección del mismo, siguiendo las instrucciones allí descritas.
B46: Hoja | D46: Descripción
B47: Firmas Conformidad_Imagen | D47: En artefactos tipo Excel, la inserción de la Sección FIRMAS DE CONFORMIDAD como imagen en el mismo documento, puede hacerse como una alternativa cuando por la naturaleza y cantidad de información registrada en él, se hace necesario ampliar significativamente el tamaño de las celdas, ocasionando con ello distorsión o inadecuada distribución de la estructura de la sección de firmas localizada en la parte inferior del artefacto. Si ese fuera el caso, en esta hoja puede capturarse la información de las personas que participan en la elaboración y aprobación del artefacto, y después insertarla como imagen en cualquier otra sección del documento, siguiendo los pasos que allí se describen.

Sheet Versionamiento
B12: Tabla de Versiones y Modificaciones
B13: En la tabla siguiente se deben listar las versiones y descripciones hechas a este documento, desde el momento de su creación y cada vez que se llene y/o actualice alguna de sus pestañas. La descripción debe incluir una síntesis del cambio hecho.
B14: Para la Versión, especificar un número entero consecutivo, iniciando con 1 para la creación del documento e incrementar en decimales conforme se actualice (1.1, 1.2, 1.3, Etc.). Al terminarlo, especificar la versión final para firma, en caso necesario.
B15: Para futuros proyectos donde este documento se reutilice, el versionamiento reiniciará en versión 2, incrementando las actualizaciones igualmente con decimales (2.1, 2.2, 2.3, etc.). Posteriores reutilizaciones iniciarían entonces con versión 3, 4, etc.
C18: Versión | D18: Descripción del Cambio | E18: Responsable de la Versión | F18: Fecha
C19: 0.1 | D19: Creación del documento. | E19: Alma Q. Torres González | F19: 45652
C20: 1.1 | D20: Se complementaron los casos de prueba por revisión con el Negocio (Ejemplo)
C21: 0.2 | D21: Ajustes: CC083 Masiva UUID CC084 Descargar acuse de cancelación | E21: Alma Quetzabeth Torres González | F21: 45652
D22: CC083 Masiva UUID
D23: CC084 Descargar acuse de cancelación
C24: 0.3 | D24: Ajustes: Actualizar CP06, CP07, CP08 y CP09 | E24: Alma Quetzabeth Torres González | F24: 45831
C25: 1.0 | D25: Versión aprobada para firma | E25: Roberto Monroy Vargas Mario Alberto Huerta Velázquez

Sheet ListadoCP
B9: Portal Consulta Central CFDI-Retenciones
B10: Casos de Prueba | C10: Rol
B12: CP01 ConsultaCentral_CFDI-Ret_Búsqueda/Folio Fiscal | C12: CFDI01 CFDI02 CFDI03 CFDI04 CFDI05
B13: CP02 ConsultaCentral_CFDI-Ret_Búsqueda/RFCEmisor | C13: CFDI01 CFDI02 CFDI03 CFDI04 CFDI05
B14: CP03 ConsultaCentral_CFDI-Ret_Búsqueda/RFCReceptor | C14: CFDI01 CFDI02 CFDI03 CFDI04 CFDI05
B15: CP04 ConsultaCentral_CFDI-Ret_Búsqueda/RFCReceptor y RFCEmisor | C15: CFDI01 CFDI02 CFDI03 CFDI04 CFDI05
B16: CP05 ConsultaCentral_CFDI-Ret_Búsqueda/Masiva UUID | C16: CFDI01 CFDI02 CFDI03 CFDI04 CFDI05
B17: CP06 ConsultaCentral_CFDI-Ret_Búsqueda/Folio Fiscal/Acciones/Acuse de Cancelación | C17: CFDI01 CFDI02 CFDI04
B18: CP07 ConsultaCentral_CFDI-Ret_Búsqueda/RFCEmisor/Acciones/Acuse de Cancelación | C18: CFDI01 CFDI02 CFDI04
B19: CP08 ConsultaCentral_CFDI-Ret_Búsqueda/RFCReceptor/Acciones/Acuse de Cancelación | C19: CFDI01 CFDI02 CFDI04
B20: CP09 ConsultaCentral_CFDI-Ret_Búsqueda/Masiva UUID/Acciones/Acuse de Cancelación | C20: CFDI01 CFDI02 CFDI04
B21: CP10 ConsultaCentral_CFDI-Ret_Búsqueda/Folio Fiscal/Acciones/Descargar RI | C21: CFDI01 CFDI02 CFDI04
B22: CP11 ConsultaCentral_CFDI-Ret_Búsqueda/RFCEmisor/Acciones/Descargar RI | C22: CFDI01 CFDI02 CFDI04
... B43: CP32 Busqueda Tipo de Comprobante (Complemento) | C43: CFDI01 CFDI02 CFDI03 CFDI04 CFDI05

Sheet Casos de Prueba
D10: Casos de Prueba
A12: Código del Aplicativo:
A13: ID de Requerimiento: | C13: POL 8214
A14: Nombre de Requerimiento: | C14: FE – Servicios Gratuitos – Realizar la actualización del Complemento de CartaPorte y de Comercio Exterior, así como, a los Servicios de Consulta del Empleado (SI)
A15: [Fase: Análisis] [Etapa: Especificación Funcional] (ACSN)
A17: ID del Caso | B17: CP | C17: Nombre del Caso | D17: Paso | E17: Descripción de Paso | F17: Resultado Esperado | G17: Comentarios | H17: Perfil de usuario para su ejecución | I17: Datos de Prueba
A18: Identificador del caso de prueba que se integrará en Quality Center (QC). El ID del caso NO debe contener espacios en blanco. La diagonal debe ser “\”. La nomenclatura estándar es: PPMC_Número\Componente Tecnológico o Aplicativo(ya que ésta es la estructura o ruta de carpetas para almacenar y agrupar los objetos creados para contener la información de los Casos de Prueba y Escenarios de Pruebas). (Ejemplo: PPMC_56124\Juicios de Nulidad) | C18: Nombre completo representativo del Caso asociado a la funcionalidad a probar. Ejemplo de nombre: "Validación de la Fecha Notificación de la Demanda" El Nombre del Caso no debe contener caracteres especiales (\/:%’*?<>|”@, , etc.) y debe tener longitud máxima de 85 caracteres. Si son más de un caso de prueba y tienen un orden de ejecución entonces, antes del nombre, debe estar acompañado de un número consecutivo del caso de prueba, anteponiendo las siglas "CP": CP1_Nombre del Caso CP2_Nombre del Caso CP3_Nombre del Caso Etc. (Si no se requiere un orden de ejecución, no es necesario ordenarlos de esta forma.) | D18: Identificador secuencial de los pasos que sigue el caso de prueba. La información de todos los pasos de un Caso de Prueba debe ser consistente. | E18: Narración detallada del paso a ejecutar. Se deben evitar paréntesis y/o corchetes seguidos "{{..[[..((…))..]]..]]". No dejar en blanco, escribir N/A en caso de que no aplique. | F18: Narración detallada del resultado esperado, dada la ejecución del paso. Se deben evitar paréntesis y/o corchetes seguidos "{{..[[..((…))..]]..]]". No dejar en blanco, escribir N/A en caso de que no aplique. | G18: Anotaciones sobre lo que deba considerarse en forma adicional para la ejecución del Caso (descripción de los prerrequisitos que deben ser cubiertos para la ejecución del caso de prueba, identificación de las entradas requeridas del caso de prueba ). Se deben evitar paréntesis y/o corchetes seguidos "{{..[[..((…))..]]..]]". No dejar en blanco, escribir N/A en caso de que no aplique. | H18: Descripción del Perfil de usuario que se utilizará para la ejecución del Caso de Prueba. No dejar en blanco, escribir N/A en caso de que no aplique | I18: Para indicar los casos prueba y descripción de los elementos donde se emplearán los datos. Indicar el nombre del Dato de Prueba (RFC, Periodo,…) Ejemplos: Indicar el contenido del dato (AAAA790909JN6, 2010-01, …) Indicar el contenido del dato (AAAA790909JN6, 2010-02, …)
B20: CP01 | C20: Folio Fiscal
A21: POL_8214 /PortalEmpleado/ConsultaCentralCFDI-Retenciones | C21: ConsultaCentral_CFDI-Ret_Búsqueda/Folio Fiscal | D21: 1 | E21: Usuario ingresa al Portal Empleados Consulta Central Retenciones | F21: El sistema despliega las siguientes opciones de búsqueda: - Folio Fiscal - Fecha Inicial y Final de Emisión - Masiva UUID | G21: El Usuario previamente se autenticó y accedió al portal Empleados-Consulta Central Retenciones | H21: Rol CFDI01 Rol CFDI02 Rol CFDI03 Rol CFDI04 Rol CFDI05 | I21: Firma Electrónica del Usuario. El Usuario debe tener asignado cualquiera de los roles
A22: POL_8214 /PortalEmpleado/ConsultaCentralCFDI-Retenciones | C22: ConsultaCentral_CFDI-Ret_Búsqueda/Folio Fiscal | D22: 2 | E22: Selecciona la opción Folio Fiscal | F22: El sistema despliega cuadro de texto para incorporar el número de Folio Fiscal que se requiere buscar. Se inhabilita el campo Fecha Inicial de Emisión | G22: (Aplica la Regla de Negocio 01)
A23: POL_8214 /PortalEmpleado/ConsultaCentralCFDI-Retenciones | C23: ConsultaCentral_CFDI-Ret_Búsqueda/Folio Fiscal | D23: 3 | E23: Ingresa los datos del Folio Fiscal | F23: El sistema muestra los datos que se van ingresando del folio fiscal
A24: POL_8214 /PortalEmpleado/ConsultaCentralCFDI-Retenciones | C24: ConsultaCentral_CFDI-Ret_Búsqueda/Folio Fiscal | D24: 4 | E24: Da clic en el botón buscar CFDI | F24: En caso de no encontrar información ir al CP "Sin Resultados" En caso contrario el sistema muestra: Tabla con el encabezado y los datos siguientes: A. Casilla Acciones 1) Seleccionar. 2) Descargar XML. 3) Recuperar Representación Impresa. B. Datos de la Metadata del CFDI. Columnas: • Folio Fiscal • RFC Emisor • Nombre o Razón Social del Emisor • RFC Receptor • Nombre o Razón Social del Receptor • Fecha de Emisión • Fecha de Certificación • PAC que Certificó • Monto Total de la Operación • Estado del Comprobante • Fecha de Cancelación • Motivo de cancelación • Folio de sustitución C. Botones: 1) Descargar Metadata. 2) Exportar Resultados a PDF. 3) Exportar Resultados a CSV. | G24: Al seleccionar el botón de folio fiscal se deben deshabilitar los campos correspondientes a la consulta por periodo de fecha de emisión. a) En una consulta por Folio fiscal o cuando se realice la consulta por periodo de fecha y el resultado sea uno: o Descargar Metadata o Exportar Resultados PDF o Exportar Resultados CSV
A25: POL_8214 /Portal Empleado/ConsultaCentralCFDI-Retenciones | C25: ConsultaCentral_CFDI-Ret_Búsqueda/Folio Fiscal | D25: 5 | E25: Da clic en Cerrar Sesión | F25: Cierra la aplicación y se direcciona a la pantalla de autenticación.
B26: CP02 | C26: RFC Emisor
A27: POL_8214 /Portal Empleado/ConsultaCentralCFDI-Retenciones | C27: ConsultaCentral_CFDI-Ret_Búsqueda/RFCEmisor | D27: 1 | E27: Usuario ingresa al Portal Empleados Consulta Central Retenciones | F27: El sistema despliega las siguientes opciones de búsqueda: - Folio Fiscal - Fecha Inicial y Final de Emisión - Masiva UUID | G27: El Usuario previamente se autenticó y accedió al portal Empleados-Consulta Central Retenciones | H27: Rol CFDI01 Rol CFDI02 Rol CFDI03 Rol CFDI04 Rol CFDI05 | I27: Firma Electrónica del Usuario. El Usuario debe tener asignado cualquiera de los roles
A28: POL_8214 /Portal Empleado/ConsultaCentralCFDI-Retenciones | C28: ConsultaCentral_CFDI-Ret_Búsqueda/RFCEmisor | D28: 2 | E28: Selecciona la opción Fecha Inicial de Emisión | F28: El sistema habilita los siguientes campos: • Fecha Inicial de Emisión (*). • Fecha Final de Emisión (*). (RN04) • RFC Emisor. (RN02) • RFC Receptor. (RN02) • Estado del Comprobante. • Tipo de Comprobante (Complemento) (RN17).* Campos obligatorios | G28: El Usuario previamente se autenticó y accedió al portal Empleados-Consulta Central Retenciones Se debe incorporar el RFC de al menos alguno de los siguientes: - RFC Emisor (RN02) - RFC Receptor (RN02)
A29: POL_8214 /Portal Empleado/ConsultaCentralCFDI-Retenciones | C29: ConsultaCentral_CFDI-Ret_Búsqueda/RFCEmisor | D29: 3 | E29: Ingresa los datos: - *Fecha inicial de emisión - *Fecha final de emisión - RFC Emisor - RFC Receptor De manera opcional: - Estado del Comprobante - Tipo de Comprobante(Complemento)(RN17) * Campos obligatorios | F29: El sistema muestra los datos que se van ingresando | G29: Al seleccionar el botón para la consulta por periodo de fecha de emisión, se debe deshabilitar el campo correspondiente a la consulta de Folio Fiscal. Debe contar con al menos un RFC (Emisor o Receptor) como parámetro de búsqueda, permitiendo los siguientes supuestos: 1) RFC Emisor, 2) RFC Receptor. 3) RFC Emisor y RFC Receptor.
A30: POL_8214 /Portal Empleado/ConsultaCentralCFDI-Retenciones | C30: ConsultaCentral_CFDI-Ret_Búsqueda/RFCEmisor | D30: 4 | E30: Da clic en el botón buscar CFDI | F30: En caso de no encontrar información ir al CP "Sin Resultados" En caso contrario el sistema muestra: Tabla con el encabezado y los datos siguientes: A. Casilla Acciones 1) Seleccionar. 2) Descargar XML. 3) Recuperar Representación Impresa. B. Datos de la Metadata del CFDI. Columnas: • Folio Fiscal • RFC Emisor • Nombre o Razón Social del Emisor • RFC Receptor • Nombre o Razón Social del Receptor • Fecha de Emisión • Fecha de Certificación • PAC que Certificó • Monto Total de la Operación • Estado del Comprobante • Fecha de Cancelación • Motivo de cancelación • Folio de sustitución C. Botones: 1) Descargar Seleccionados XML. 2) Descargas RI. 3) Descargar Metadata. 4) Exportar Resultados a PDF. 5) Exportar Resultados a CSV. D. Paginador. | G30: En caso de que no se tenga información, el aplicativo dejará en blanco la sección que corresponda en la tabla de resultados. (Aplica la Regla de Negocio 06) a) En una consulta por Folio fiscal o cuando se realice la consulta por periodo de fecha y el resultado sea uno: o Descargar Metadata o Exportar Resultados PDF o Exportar Resultados CSV b) En una consulta por periodo de fecha de emisión y el resultado sea más de uno o Descargar RI o Descargar Seleccionados XML o Descargar Metadata o Exportar Resultados PDF o Exportar Resultados CSV
A31: POL_8214 /Portal Empleado/ConsultaCentralCFDI-Retenciones | C31: ConsultaCentral_CFDI-Ret_Búsqueda/RFCEmisor | D31: 5 | E31: Da clic en Cerrar Sesión | F31: Cierra la aplicación y se direcciona a la pantalla de autenticación.
B32: CP03 | C32: RFC Receptor
A33: POL_8214 /Portal Empleado/ConsultaCentralCFDI-Retenciones | C33: ConsultaCentral_CFDI-Ret_Búsqueda/RFCReceptor | D33: 1 | E33: Usuario ingresa al Portal Empleados Consulta Central Retenciones | F33: El sistema despliega las siguientes opciones de búsqueda: - Folio Fiscal - Fecha Inicial y Final de Emisión - Masiva UUID | G33: El Usuario previamente se autenticó y accedió al portal Empleados-Consulta Central Retenciones | H33: Rol CFDI01 Rol CFDI02 Rol CFDI03 Rol CFDI04 Rol CFDI05 | I33: Firma Electrónica del Usuario. El Usuario debe tener asignado cualquiera de los roles
A34: POL_8214 /Portal Empleado/ConsultaCentralCFDI-Retenciones | C34: ConsultaCentral_CFDI-Ret_Búsqueda/RFCReceptor | D34: 2 | E34: Selecciona la opción Fecha Inicial de Emisión | F34: El sistema habilita los siguientes campos: • Fecha Inicial de Emisión (*). • Fecha Final de Emisión (*). (RN04) • RFC Emisor. (RN02) • RFC Receptor. (RN02) • Estado del Comprobante. • Tipo de Comprobante (Complemento) (RN17).* Campos obligatorios
A35: POL_8214 /Portal Empleado/ConsultaCentralCFDI-Retenciones | C35: ConsultaCentral_CFDI-Ret_Búsqueda/RFCReceptor | D35: 3 | E35: Ingresa los datos: - *Fecha inicial de emisión - *Fecha final de emisión - RFC Emisor - RFC Receptor De manera opcional: - Estado del Comprobante - Tipo de Comprobante(Complemento)(RN17) * Campos obligatorios | F35: El sistema muestra los datos que se van ingresando
A36: POL_8214 /Portal Empleado/ConsultaCentralCFDI-Retenciones | C36: ConsultaCentral_CFDI-Ret_Búsqueda/RFCReceptor | D36: 4 | E36: Da clic en el botón buscar CFDI | F36: En caso de no encontrar información ir al CP "Sin Resultados" En caso contrario el sistema muestra: Tabla con el encabezado y los datos siguientes: A. Casilla Acciones 1) Seleccionar. 2) Descargar XML. 3) Recuperar Representación Impresa. B. Datos de la Metadata del CFDI. Columnas: • Folio Fiscal • RFC Emisor • Nombre o Razón Social del Emisor • RFC Receptor • Nombre o Razón Social del Receptor • Fecha de Emisión • Fecha de Certificación • PAC que Certificó • Monto Total de la Operación • Estado del Comprobante • Fecha de Cancelación • Motivo de cancelación • Folio de sustitución C. Botones: 1) Descargar Seleccionados XML. 2) Descargas RI. 3) Descargar Metadata. 4) Exportar Resultados a PDF. 5) Exportar Resultados a CSV. D. Paginador. | G36: En caso de que no se tenga información, el aplicativo dejará en blanco la sección que corresponda en la tabla de resultados. (Aplica la Regla de Negocio 06) a) En una consulta por Folio fiscal o cuando se realice la consulta por periodo de fecha y el resultado sea uno: o Descargar Metadata o Exportar Resultados PDF o Exportar Resultados CSV b) En una consulta por periodo de fecha de emisión y el resultado sea más de uno o Descargar RI o Descargar Seleccionados XML o Descargar Metadata o Exportar Resultados PDF o Exportar Resultados CSV
A37: POL_8214 /Portal Empleado/ConsultaCentralCFDI-Retenciones | C37: ConsultaCentral_CFDI-Ret_Búsqueda/RFCReceptor | D37: 5 | E37: Da clic en Cerrar Sesión | F37: Cierra la aplicación y se direcciona a la pantalla de autenticación.
B38: CP04 | C38: RFC Receptor y RFC Emisor
A39: POL_8214 /Portal Empleado/ConsultaCentralCFDI-Retenciones | C39: ConsultaCentral_CFDI-Ret_Búsqueda/RFCReceptor y RFCEmisor | D39: 1 | E39: Usuario ingresa al Portal Empleados Consulta Central Retenciones | F39: El sistema despliega las siguientes opciones de búsqueda: - Folio Fiscal - Fecha Inicial y Final de Emisión - Masiva UUID | G39: El Usuario previamente se autenticó y accedió al portal Empleados-Consulta Central Retenciones | H39: Rol CFDI01 Rol CFDI02 Rol CFDI03 Rol CFDI04 Rol CFDI05 | I39: Firma Electrónica del Usuario. El Usuario debe tener asignado cualquiera de los roles
A40: POL_8214 /Portal Empleado/ConsultaCentralCFDI-Retenciones | C40: ConsultaCentral_CFDI-Ret_Búsqueda/RFCReceptor y RFCEmisor | D40: 2 | E40: Selecciona la opción Fecha Inicial de Emisión | F40: El sistema habilita los siguientes campos: • Fecha Inicial de Emisión (*). • Fecha Final de Emisión (*). (RN04) • RFC Emisor. (RN02) • RFC Receptor. (RN02) • Estado del Comprobante. • Tipo de Comprobante (Complemento) (RN17).* Campos obligatorios
A41: POL_8214 /Portal Empleado/ConsultaCentralCFDI-Retenciones | C41: ConsultaCentral_CFDI-Ret_Búsqueda/RFCReceptor y RFCEmisor | D41: 3 | E41: Ingresa los datos: - *Fecha inicial de emisión - *Fecha final de emisión - RFC Emisor - RFC Receptor De manera opcional: - Estado del Comprobante - Tipo de Comprobante(Complemento)(RN17) * Campos obligatorios | F41: El sistema muestra los datos que se van ingresando
A42: POL_8214 /Portal Empleado/ConsultaCentralCFDI-Retenciones | C42: ConsultaCentral_CFDI-Ret_Búsqueda/RFCReceptor y RFCEmisor | D42: 4 | E42: Da clic en el botón buscar CFDI | F42: En caso de no encontrar información ir al CP "Sin Resultados" En caso contrario el sistema muestra: Tabla con el encabezado y los datos siguientes: A. Casilla Acciones 1) Seleccionar. 2) Descargar XML. 3) Recuperar Representación Impresa. B. Datos de la Metadata del CFDI. Columnas: • Folio Fiscal • RFC Emisor • Nombre o Razón Social del Emisor • RFC Receptor • Nombre o Razón Social del Receptor • Fecha de Emisión • Fecha de Certificación • PAC que Certificó • Monto Total de la Operación • Estado del Comprobante • Fecha de Cancelación • Motivo de cancelación • Folio de sustitución C. Botones: 1) Descargar Seleccionados XML. 2) Descargas RI. 3) Descargar Metadata. 4) Exportar Resultados a PDF. 5) Exportar Resultados a CSV. D. Paginador. | G42: En caso de que no se tenga información, el aplicativo dejará en blanco la sección que corresponda en la tabla de resultados. (Aplica la Regla de Negocio 06) a) En una consulta por Folio fiscal o cuando se realice la consulta por periodo de fecha y el resultado sea uno: o Descargar Metadata o Exportar Resultados PDF o Exportar Resultados CSV b) En una consulta por periodo de fecha de emisión y el resultado sea más de uno o Descargar RI o Descargar Seleccionados XML o Descargar Metadata o Exportar Resultados PDF o Exportar Resultados CSV
A43: POL_8214 /Portal Empleado/ConsultaCentralCFDI-Retenciones | C43: ConsultaCentral_CFDI-Ret_Búsqueda/RFCReceptor y RFCEmisor | D43: 5 | E43: Da clic en Cerrar Sesión | F43: Cierra la aplicación y se direcciona a la pantalla de autenticación.
B44: CP05 | C44: Masiva UUID
A45: POL_8214 /PortalEmpleado/ConsultaCentralCFDI-Retenciones | C45: ConsultaCentral_CFDI-Ret_Búsqueda/Masiva UUID | D45: 1 | E45: Usuario ingresa al Portal Empleados Consulta Central Retenciones | F45: El sistema despliega las siguientes opciones de búsqueda: - Folio Fiscal - Fecha Inicial y Final de Emisión - Masiva UUID | G45: El Usuario previamente se autenticó y accedió al portal Empleados-Consulta Central Retenciones | H45: Rol CFDI01 Rol CFDI02 Rol CFDI03 Rol CFDI04 Rol CFDI05 | I45: Firma Electrónica del Usuario. El Usuario debe tener asignado cualquiera de los roles
A46: POL_8214 /PortalEmpleado/ConsultaCentralCFDI-Retenciones | C46: ConsultaCentral_CFDI-Ret_Búsqueda/Masiva UUID | D46: 2 | E46: Selecciona la opción Masiva UUID | F46: El sistema despliega las siguientes opciones de búsqueda: - Boton Seleccionar* - Archivos Solicitados - Botón Enviar
A47: POL_8214 /PortalEmpleado/ConsultaCentralCFDI-Retenciones | C47: ConsultaCentral_CFDI-Ret_Búsqueda/Masiva UUID | D47: 3 | E47: Selecciona el archivo(txt) mediante el explorador de Windows. | F47: El aplicativo ejecuta la consulta y arroja el resultado conforme a los UUID definidos en el archivo. | G47: Archivo TXT con distintos UUID
A48: POL_8214 /PortalEmpleado/ConsultaCentralCFDI-Retenciones | C48: ConsultaCentral_CFDI-Ret_Búsqueda/Masiva UUID | D48: 4 | E48: Da clic en el botón buscar CFDI | F48: En caso de no encontrar información ir al CP "Sin Resultados" En caso contrario el sistema muestra: Tabla con el encabezado y los datos siguientes: + Acciones • Descargar.(XML) • Recuperar Representacion Impresa.(RI) Columnas: • Folio Fiscal • RFC Emisor • Nombre o Razón Social del Emisor • RFC Receptor • Nombre o Razón Social del Receptor • Fecha de Emisión • Fecha de Certificación • PAC que Certificó • Monto Total de la Operación • Estado del Comprobante • Fecha de Cancelación • Motivo de cancelación • Folio de sustitución + Botones: 1) Descargar seleccionados XML 2) Exportar resultados a PDF 3) Exportar resultados a CSV | G48: El aplicativo realiza la consulta masiva de esos UUID y se muestra el detalle de los CFDI de Retenciones con las funcionalidades que actualmente existen • El servicio solo permite la consulta a través de archivos de texto plano (.txt). Nota: Para la consulta Masiva UUID cuando el resultado contiene mas de un folio fiscal se mostrarán los botones: 1) Descargar seleccionados XML 2) Exportar resultados a PDF 3) Exportar resultados a CSV Cuando el resultado solo contiene un resultado se mostrarán los botones: 1. Exportar resultados a PDF 2. Exportar resultados a CSV
A49: POL_8214 /Portal Empleado/ConsultaCentralCFDI-Retenciones | C49: ConsultaCentral_CFDI-Ret_Búsqueda/Masiva UUID | D49: 5 | E49: Da clic en Cerrar Sesión | F49: Cierra la aplicación y se direcciona a la pantalla de autenticación.
B50: CP06 | C50: Folio Fiscal/Acuse de Cancelación
A51: POL_8214 /Portal Empleado/ConsultaCentralCFDI-Retenciones | C51: ConsultaCentral_CFDI-Ret_Búsqueda/Folio Fiscal/Acciones/Acuse de Cancelación | D51: 1 | E51: Usuario ingresa al Portal Empleados Consulta Central Retenciones | F51: El sistema despliega las siguientes opciones de búsqueda: - Folio Fiscal - Fecha Inicial y Final de Emisión - Masiva UUID | G51: El Usuario previamente se autenticó y accedió al portal Empleados-Consulta Central Retenciones | H51: Rol CFDI01 Rol CFDI02 Rol CFDI04 | I51: Firma Electrónica del Usuario. El Usuario debe tener asignado cualquiera de los roles Para este caso de prueba el comprobante debe estar cancelado.
A52: POL_8214 /Portal Empleado/ConsultaCentralCFDI-Retenciones | C52: ConsultaCentral_CFDI-Ret_Búsqueda/Folio Fiscal/Acciones/Acuse de Cancelación | D52: 2 | E52: Selecciona la opción Folio Fiscal | F52: El sistema despliega cuadro de texto para incorporar el número de Folio Fiscal que se requiere buscar
...

Sheet Devops
B19: Test Case | C19: =IF('Casos de Prueba'!B20<>0,'Casos de Prueba'!B20&"-"&'Casos de Prueba'!C20:E20,"") -> CP01-Folio Fiscal
A20: =LEN(E20) -> 64 | B20: =LEN(F20) -> 217 | C20: =IF('Casos de Prueba'!B21<>0,'Casos de Prueba'!B21&"-"&'Casos de Prueba'!C21:E21,"") | D20: =IF(LEN($C20)>0,"",'Casos de Prueba'!D21) -> 1 | E20: =IF(LEN($C20)>0,"",'Casos de Prueba'!E21) -> Usuario ingresa al Portal Empleados Consulta Central Retenciones | F20: =IF(LEN($C20)>0,"",'Casos de Prueba'!F21&CHAR(10)&'Casos de Prueba'!G21) -> El sistema despliega las siguientes opciones de búsqueda: - Folio Fiscal - Fecha Inicial y Final de Emisión - Masiva UUID El Usuario previamente se autenticó y accedió al portal Empleados-Consulta Central Retenciones
A21: =LEN(E21) -> 33 | B21: =LEN(F21) -> 183 | C21: =IF('Casos de Prueba'!B22<>0,'Casos de Prueba'!B22&"-"&'Casos de Prueba'!C22:E22,"") | D21: =IF(LEN($C21)>0,"",'Casos de Prueba'!D22) -> 2 | E21: =IF(LEN($C21)>0,"",'Casos de Prueba'!E22) -> Selecciona la opción Folio Fiscal | F21: =IF(LEN($C21)>0,"",'Casos de Prueba'!F22&CHAR(10)&'Casos de Prueba'!G22) -> El sistema despliega cuadro de texto para incorporar el número de Folio Fiscal que se requiere buscar. Se inhabilita el campo Fecha Inicial de Emisión (Aplica la Regla de Negocio 01)
A22: =LEN(E22) -> 35 | B22: =LEN(F22) -> 69 | C22: =IF('Casos de Prueba'!B23<>0,'Casos de Prueba'!B23&"-"&'Casos de Prueba'!C23:E23,"") | D22: =IF(LEN($C22)>0,"",'Casos de Prueba'!D23) -> 3 | E22: =IF(LEN($C22)>0,"",'Casos de Prueba'!E23) -> Ingresa los datos del Folio Fiscal | F22: =IF(LEN($C22)>0,"",'Casos de Prueba'!F23&CHAR(10)&'Casos de Prueba'!G23) -> El sistema muestra los datos que se van ingresando del folio fiscal
A23: =LEN(E23) -> 31 | B23: =LEN(F23) -> 1016 | C23: =IF('Casos de Prueba'!B24<>0,'Casos de Prueba'!B24&"-"&'Casos de Prueba'!C24:E24,"") | D23: =IF(LEN($C23)>0,"",'Casos de Prueba'!D24) -> 4 | E23: =IF(LEN($C23)>0,"",'Casos de Prueba'!E24) -> Da clic en el botón buscar CFDI | F23: =IF(LEN($C23)>0,"",'Casos de Prueba'!F24&CHAR(10)&'Casos de Prueba'!G24) -> En caso de no encontrar información ir al CP "Sin Resultados" En caso contrario el sistema muestra: Tabla con el encabezado y los datos siguientes: A. Casilla Acciones 1) Seleccionar. 2) Descargar XML. 3) Recuperar Representación Impresa. B. Datos de la Metadata del CFDI. Columnas: • Folio Fiscal • RFC Emisor • Nombre o Razón Social del Emisor • RFC Receptor • Nombre o Razón Social del Receptor • Fecha de Emisión • Fecha de Certificación • PAC que Certificó • Monto Total de la Operación • Estado del Comprobante • Fecha de Cancelación • Motivo de cancelación • Folio de sustitución C. Botones: 1) Descargar Metadata. 2) Exportar Resultados a PDF. 3) Exportar Resultados a CSV. Al seleccionar el botón de folio fiscal se deben deshabilitar los campos correspondientes a la consulta por periodo de fecha de emisión. a) En una consulta por Folio fiscal o cuando se realice la consulta por periodo de fecha y el resultado sea uno: o Descargar Metadata o Exportar Resultados PDF o Exportar Resultados CSV
A24: =LEN(E24) -> 24 | B24: =LEN(F24) -> 69 | C24: =IF('Casos de Prueba'!B25<>0,'Casos de Prueba'!B25&"-"&'Casos de Prueba'!C25:E25,"") | D24: =IF(LEN($C24)>0,"",'Casos de Prueba'!D25) -> 5 | E24: =IF(LEN($C24)>0,"",'Casos de Prueba'!E25) -> Da clic en Cerrar Sesión | F24: =IF(LEN($C24)>0,"",'Casos de Prueba'!F25&CHAR(10)&'Casos de Prueba'!G25) -> Cierra la aplicación y se direcciona a la pantalla de autenticación.
A25: =LEN(E25) -> 0 | B25: =LEN(F25) -> 0 | C25: =IF('Casos de Prueba'!B26<>0,'Casos de Prueba'!B26&"-"&'Casos de Prueba'!C26:E26,"") -> CP02-RFC Emisor | D25: =IF(LEN($C25)>0,"",'Casos de Prueba'!D26) | E25: =IF(LEN($C25)>0,"",'Casos de Prueba'!E26) | F25: =IF(LEN($C25)>0,"",'Casos de Prueba'!F26&CHAR(10)&'Casos de Prueba'!G26)
A26: =LEN(E26) -> 64 | B26: =LEN(F26) -> 217 | C26: =IF('Casos de Prueba'!B27<>0,'Casos de Prueba'!B27&"-"&'Casos de Prueba'!C27:E27,"") | D26: =IF(LEN($C26)>0,"",'Casos de Prueba'!D27) -> 1 | E26: =IF(LEN($C26)>0,"",'Casos de Prueba'!E27) -> Usuario ingresa al Portal Empleados Consulta Central Retenciones | F26: =IF(LEN($C26)>0,"",'Casos de Prueba'!F27&CHAR(10)&'Casos de Prueba'!G27) -> El sistema despliega las siguientes opciones de búsqueda: - Folio Fiscal - Fecha Inicial y Final de Emisión - Masiva UUID El Usuario previamente se autenticó y accedió al portal Empleados-Consulta Central Retenciones
A27: =LEN(E27) -> 45 | B27: =LEN(F27) -> 449 | C27: =IF('Casos de Prueba'!B28<>0,'Casos de Prueba'!B28&"-"&'Casos de Prueba'!C28:E28,"") | D27: =IF(LEN($C27)>0,"",'Casos de Prueba'!D28) -> 2 | E27: =IF(LEN($C27)>0,"",'Casos de Prueba'!E28) -> Selecciona la opción Fecha Inicial de Emisión | F27: =IF(LEN($C27)>0,"",'Casos de Prueba'!F28&CHAR(10)&'Casos de Prueba'!G28) -> El sistema habilita los siguientes campos: • Fecha Inicial de Emisión (*). • Fecha Final de Emisión (*). (RN04) • RFC Emisor. (RN02) • RFC Receptor. (RN02) • Estado del Comprobante. • Tipo de Comprobante (Complemento) (RN17).* Campos obligatorios El Usuario previamente se autenticó y accedió al portal Empleados-Consulta Central Retenciones Se debe incorporar el RFC de al menos alguno de los siguientes: - RFC Emisor (RN02) - RFC Receptor (RN02)
A28: =LEN(E28) -> 213 | B28: =LEN(F28) -> 383 | C28: =IF('Casos de Prueba'!B29<>0,'Casos de Prueba'!B29&"-"&'Casos de Prueba'!C29:E29,"") | D28: =IF(LEN($C28)>0,"",'Casos de Prueba'!D29) -> 3 | E28: =IF(LEN($C28)>0,"",'Casos de Prueba'!E29) -> Ingresa los datos: - *Fecha inicial de emisión - *Fecha final de emisión - RFC Emisor - RFC Receptor De manera opcional: - Estado del Comprobante - Tipo de Comprobante(Complemento)(RN17) * Campos obligatorios | F28: =IF(LEN($C28)>0,"",'Casos de Prueba'!F29&CHAR(10)&'Casos de Prueba'!G29) -> El sistema muestra los datos que se van ingresando Al seleccionar el botón para la consulta por periodo de fecha de emisión, se debe deshabilitar el campo correspondiente a la consulta de Folio Fiscal. Debe contar con al menos un RFC (Emisor o Receptor) como parámetro de búsqueda, permitiendo los siguientes supuestos: 1) RFC Emisor, 2) RFC Receptor. 3) RFC Emisor y RFC Receptor.
A29: =LEN(E29) -> 31 | B29: =LEN(F29) -> 1300 | C29: =IF('Casos de Prueba'!B30<>0,'Casos de Prueba'!B30&"-"&'Casos de Prueba'!C30:E30,"") | D29: =IF(LEN($C29)>0,"",'Casos de Prueba'!D30) -> 4 | E29: =IF(LEN($C29)>0,"",'Casos de Prueba'!E30) -> Da clic en el botón buscar CFDI | F29: =IF(LEN($C29)>0,"",'Casos de Prueba'!F30&CHAR(10)&'Casos de Prueba'!G30) -> En caso de no encontrar información ir al CP "Sin Resultados" En caso contrario el sistema muestra: Tabla con el encabezado y los datos siguientes: A. Casilla Acciones 1) Seleccionar. 2) Descargar XML. 3) Recuperar Representación Impresa. B. Datos de la Metadata del CFDI. Columnas: • Folio Fiscal • RFC Emisor • Nombre o Razón Social del Emisor • RFC Receptor • Nombre o Razón Social del Receptor • Fecha de Emisión • Fecha de Certificación • PAC que Certificó • Monto Total de la Operación • Estado del Comprobante • Fecha de Cancelación • Motivo de cancelación • Folio de sustitución C. Botones: 1) Descargar Seleccionados XML. 2) Descargas RI. 3) Descargar Metadata. 4) Exportar Resultados a PDF. 5) Exportar Resultados a CSV. D. Paginador. En caso de que no se tenga información, el aplicativo dejará en blanco la sección que corresponda en la tabla de resultados. (Aplica la Regla de Negocio 06) a) En una consulta por Folio fiscal o cuando se realice la consulta por periodo de fecha y el resultado sea uno: o Descargar Metadata o Exportar Resultados PDF o Exportar Resultados CSV b) En una consulta por periodo de fecha de emisión y el resultado sea más de uno o Descargar RI o Descargar Seleccionados XML o Descargar Metadata o Exportar Resultados PDF o Exportar Resultados CSV
A30: =LEN(E30) -> 24 | B30: =LEN(F30) -> 69 | C30: =IF('Casos de Prueba'!B31<>0,'Casos de Prueba'!B31&"-"&'Casos de Prueba'!C31:E31,"") | D30: =IF(LEN($C30)>0,"",'Casos de Prueba'!D31) -> 5 | E30: =IF(LEN($C30)>0,"",'Casos de Prueba'!E31) -> Da clic en Cerrar Sesión | F30: =IF(LEN($C30)>0,"",'Casos de Prueba'!F31&CHAR(10)&'Casos de Prueba'!G31) -> Cierra la aplicación y se direcciona a la pantalla de autenticación.
A31: =LEN(E31) -> 0 | B31: =LEN(F31) -> 0 | C31: =IF('Casos de Prueba'!B32<>0,'Casos de Prueba'!B32&"-"&'Casos de Prueba'!C32:E32,"") -> CP03-RFC Receptor | D31: =IF(LEN($C31)>0,"",'Casos de Prueba'!D32) | E31: =IF(LEN($C31)>0,"",'Casos de Prueba'!E32) | F31: =IF(LEN($C31)>0,"",'Casos de Prueba'!F32&CHAR(10)&'Casos de Prueba'!G32)
... A181: =LEN(E181) -> 213 | B181: =LEN(F181) -> 52 | C181: =IF('Casos de Prueba'!B182<>0,'Casos de Prueba'!B182&"-"&'Casos de Prueba'!C182:E182,"") | D181: =IF(LEN($C181)>0,"",'Casos de Prueba'!D182) -> 3 | E181: =IF(LEN($C181)>0,"",'Casos de Prueba'!E182) -> Ingresa los datos: - *Fecha inicial de emisión - *Fecha final de emisión - RFC Emisor - RFC Receptor De manera opcional: - Estado del Comprobante - Tipo de Comprobante(Complemento)(RN17) * Campos obligatorios | F181: =IF(LEN($C181)>0,"",'Casos de Prueba'!F182&CHAR(10)&'Casos de Prueba'!G182) -> El sistema muestra los datos que se van ingresando
A182: =LEN(E182) -> 31 | B182: =LEN(F182) -> 728 | C182: =IF('Casos de Prueba'!B183<>0,'Casos de Prueba'!B183&"-"&'Casos de Prueba'!C183:E183,"") | D182: =IF(LEN($C182)>0,"",'Casos de Prueba'!D183) -> 4 | E182: =IF(LEN($C182)>0,"",'Casos de Prueba'!E183) -> Da clic en el botón buscar CFDI | F182: =IF(LEN($C182)>0,"",'Casos de Prueba'!F183&CHAR(10)&'Casos de Prueba'!G184) -> El sistema valida que el usuario tenga permisos para consultar PPE. Si se encuentra en la lista para poder ver los PPE, el sistema muestra los resultados de acuerdo a la consulta, más los registros RFC PPE. Si el usuario no cuenta con permisos, muestrea los resultados de acuerdo a una consulta normal no incluyendo los registros RFC PPE a) En una consulta por Folio fiscal o cuando se realice la consulta por periodo de fecha y el resultado sea uno: o Descargar Metadata o Exportar Resultados PDF o Exportar Resultados CSV b) En una consulta por periodo de fecha de emisión y el resultado sea más de uno o Descargar RI o Descargar Seleccionados XML o Descargar Metadata o Exportar Resultados PDF o Exportar Resultados CSV
A183: =LEN(E183) -> 58 | B183: =LEN(F183) -> #REF! | C183: =IF('Casos de Prueba'!B184<>0,'Casos de Prueba'!B184&"-"&'Casos de Prueba'!C184:E184,"") | D183: =IF(LEN($C183)>0,"",'Casos de Prueba'!D184) -> 5 | E183: =IF(LEN($C183)>0,"",'Casos de Prueba'!E184) -> El usuario valida los registros en la sección "Resultados" | F183: =IF(LEN($C183)>0,"",'Casos de Prueba'!F184&CHAR(10)&'Casos de Prueba'!#REF!) -> #REF!
A184: =LEN(E184) -> 24 | B184: =LEN(F184) -> 69 | C184: =IF('Casos de Prueba'!B185<>0,'Casos de Prueba'!B185&"-"&'Casos de Prueba'!C185:E185,"") | D184: =IF(LEN($C184)>0,"",'Casos de Prueba'!D185) -> 6 | E184: =IF(LEN($C184)>0,"",'Casos de Prueba'!E185) -> Da clic en Cerrar Sesión | F184: =IF(LEN($C184)>0,"",'Casos de Prueba'!F185&CHAR(10)&'Casos de Prueba'!G185) -> Cierra la aplicación y se direcciona a la pantalla de autenticación.
A185: =LEN(E185) -> #REF! | B185: =LEN(F185) -> #REF! | C185: =IF('Casos de Prueba'!#REF!<>0,'Casos de Prueba'!#REF!&"-"&_xlfn.SINGLE('Casos de Prueba'!#REF!),"") -> #REF! | D185: =IF(LEN($C185)>0,"",'Casos de Prueba'!#REF!) -> #REF! | E185: =IF(LEN($C185)>0,"",'Casos de Prueba'!#REF!) -> #REF! | F185: =IF(LEN($C185)>0,"",'Casos de Prueba'!#REF!&CHAR(10)&'Casos de Prueba'!#REF!) -> #REF!
A186: =LEN(E186) -> #REF! | B186: =LEN(F186) -> #REF! | C186: =IF('Casos de Prueba'!#REF!<>0,'Casos de Prueba'!#REF!&"-"&_xlfn.SINGLE('Casos de Prueba'!#REF!),"") -> #REF! | D186: =IF(LEN($C186)>0,"",'Casos de Prueba'!#REF!) -> #REF! | E186: =IF(LEN($C186)>0,"",'Casos de Prueba'!#REF!) -> #REF! | F186: =IF(LEN($C186)>0,"",'Casos de Prueba'!#REF!&CHAR(10)&'Casos de Prueba'!#REF!) -> #REF!
A187: =LEN(E187) -> #REF! | B187: =LEN(F187) -> #REF! | C187: =IF('Casos de Prueba'!#REF!<>0,'Casos de Prueba'!#REF!&"-"&_xlfn.SINGLE('Casos de Prueba'!#REF!),"") -> #REF! | D187: =IF(LEN($C187)>0,"",'Casos de Prueba'!#REF!) -> #REF! | E187: =IF(LEN($C187)>0,"",'Casos de Prueba'!#REF!) -> #REF! | F187: =IF(LEN($C187)>0,"",'Casos de Prueba'!#REF!&CHAR(10)&'Casos de Prueba'!#REF!) -> #REF!
A188: =LEN(E188) -> #REF! | B188: =LEN(F188) -> #REF! | C188: =IF('Casos de Prueba'!#REF!<>0,'Casos de Prueba'!#REF!&"-"&_xlfn.SINGLE('Casos de Prueba'!#REF!),"") -> #REF! | D188: =IF(LEN($C188)>0,"",'Casos de Prueba'!#REF!) -> #REF! | E188: =IF(LEN($C188)>0,"",'Casos de Prueba'!#REF!) -> #REF! | F188: =IF(LEN($C188)>0,"",'Casos de Prueba'!#REF!&CHAR(10)&'Casos de Prueba'!#REF!) -> #REF!
A189: =LEN(E189) -> #REF! | B189: =LEN(F189) -> #REF! | C189: =IF('Casos de Prueba'!#REF!<>0,'Casos de Prueba'!#REF!&"-"&_xlfn.SINGLE('Casos de Prueba'!#REF!),"") -> #REF! | D189: =IF(LEN($C189)>0,"",'Casos de Prueba'!#REF!) -> #REF! | E189: =IF(LEN($C189)>0,"",'Casos de Prueba'!#REF!) -> #REF! | F189: =IF(LEN($C189)>0,"",'Casos de Prueba'!#REF!&CHAR(10)&'Casos de Prueba'!#REF!) -> #REF!
A190: =LEN(E190) -> #REF! | B190: =LEN(F190) -> #REF! | C190: =IF('Casos de Prueba'!#REF!<>0,'Casos de Prueba'!#REF!&"-"&_xlfn.SINGLE('Casos de Prueba'!#REF!),"") -> #REF! | D190: =IF(LEN($C190)>0,"",'Casos de Prueba'!#REF!) -> #REF! | E190: =IF(LEN($C190)>0,"",'Casos de Prueba'!#REF!) -> #REF! | F190: =IF(LEN($C190)>0,"",'Casos de Prueba'!#REF!&CHAR(10)&'Casos de Prueba'!#REF!) -> #REF!
A191: =LEN(E191) -> #REF! | B191: =LEN(F191) -> #REF! | C191: =IF('Casos de Prueba'!#REF!<>0,'Casos de Prueba'!#REF!&"-"&_xlfn.SINGLE('Casos de Prueba'!#REF!),"") -> #REF! | D191: =IF(LEN($C191)>0,"",'Casos de Prueba'!#REF!) -> #REF! | E191: =IF(LEN($C191)>0,"",'Casos de Prueba'!#REF!) -> #REF! | F191: =IF(LEN($C191)>0,"",'Casos de Prueba'!#REF!&CHAR(10)&'Casos de Prueba'!#REF!) -> #REF!
A192: =LEN(E192) -> #REF! | B192: =LEN(F192) -> #REF! | C192: =IF('Casos de Prueba'!#REF!<>0,'Casos de Prueba'!#REF!&"-"&_xlfn.SINGLE('Casos de Prueba'!#REF!),"") -> #REF! | D192: =IF(LEN($C192)>0,"",'Casos de Prueba'!#REF!) -> #REF! | E192: =IF(LEN($C192)>0,"",'Casos de Prueba'!#REF!) -> #REF! | F192: =IF(LEN($C192)>0,"",'Casos de Prueba'!#REF!&CHAR(10)&'Casos de Prueba'!#REF!) -> #REF!
A193: =LEN(E193) -> #REF! | B193: =LEN(F193) -> #REF! | C193: =IF('Casos de Prueba'!#REF!<>0,'Casos de Prueba'!#REF!&"-"&_xlfn.SINGLE('Casos de Prueba'!#REF!),"") -> #REF! | D193: =IF(LEN($C193)>0,"",'Casos de Prueba'!#REF!) -> #REF! | E193: =IF(LEN($C193)>0,"",'Casos de Prueba'!#REF!) -> #REF! | F193: =IF(LEN($C193)>0,"",'Casos de Prueba'!#REF!&CHAR(10)&'Casos de Prueba'!#REF!) -> #REF!
A194: =LEN(E194) -> #REF! | B194: =LEN(F194) -> #REF! | C194: =IF('Casos de Prueba'!#REF!<>0,'Casos de Prueba'!#REF!&"-"&_xlfn.SINGLE('Casos de Prueba'!#REF!),"") -> #REF! | D194: =IF(LEN($C194)>0,"",'Casos de Prueba'!#REF!) -> #REF! | E194: =IF(LEN($C194)>0,"",'Casos de Prueba'!#REF!) -> #REF! | F194: =IF(LEN($C194)>0,"",'Casos de Prueba'!#REF!&CHAR(10)&'Casos de Prueba'!#REF!) -> #REF!
A195: =LEN(E195) -> #REF! | B195: =LEN(F195) -> #REF! | C195: =IF('Casos de Prueba'!#REF!<>0,'Casos de Prueba'!#REF!&"-"&_xlfn.SINGLE('Casos de Prueba'!#REF!),"") -> #REF! | D195: =IF(LEN($C195)>0,"",'Casos de Prueba'!#REF!) -> #REF! | E195: =IF(LEN($C195)>0,"",'Casos de Prueba'!#REF!) -> #REF! | F195: =IF(LEN($C195)>0,"",'Casos de Prueba'!#REF!&CHAR(10)&'Casos de Prueba'!#REF!) -> #REF!
A196: =LEN(E196) -> #REF! | B196: =LEN(F196) -> #REF! | C196: =IF('Casos de Prueba'!#REF!<>0,'Casos de Prueba'!#REF!&"-"&_xlfn.SINGLE('Casos de Prueba'!#REF!),"") -> #REF! | D196: =IF(LEN($C196)>0,"",'Casos de Prueba'!#REF!) -> #REF! | E196: =IF(LEN($C196)>0,"",'Casos de Prueba'!#REF!) -> #REF! | F196: =IF(LEN($C196)>0,"",'Casos de Prueba'!#REF!&CHAR(10)&'Casos de Prueba'!#REF!) -> #REF!
... A205: =LEN(E205) -> #REF! | B205: =LEN(F205) -> #REF! | C205: =IF('Casos de Prueba'!#REF!<>0,'Casos de Prueba'!#REF!&"-"&_xlfn.SINGLE('Casos de Prueba'!#REF!),"") -> #REF! | D205: =IF(LEN($C205)>0,"",'Casos de Prueba'!#REF!) -> #REF! | E205: =IF(LEN($C205)>0,"",'Casos de Prueba'!#REF!) -> #REF! | F205: =IF(LEN($C205)>0,"",'Casos de Prueba'!#REF!&CHAR(10)&'Casos de Prueba'!#REF!) -> #REF!
A206: =LEN(E206) -> 0 | B206: =LEN(F206) -> 0 | C206: =IF('Casos de Prueba'!B186<>0,'Casos de Prueba'!B186&"-"&'Casos de Prueba'!C186:E186,"") -> CP27-Autenticación | D206: =IF(LEN($C206)>0,"",'Casos de Prueba'!D186) | E206: =IF(LEN($C206)>0,"",'Casos de Prueba'!E186) | F206: =IF(LEN($C206)>0,"",'Casos de Prueba'!F186&CHAR(10)&'Casos de Prueba'!G186)
A207: =LEN(E207) -> 23 | B207: =LEN(F207) -> 1 | C207: =IF('Casos de Prueba'!B187<>0,'Casos de Prueba'!B187&"-"&'Casos de Prueba'!C187:E187,"") | D207: =IF(LEN($C207)>0,"",'Casos de Prueba'!D187) -> 1 | E207: =IF(LEN($C207)>0,"",'Casos de Prueba'!E187) -> Usuario abre explorador | F207: =IF(LEN($C207)>0,"",'Casos de Prueba'!F187&CHAR(10)&'Casos de Prueba'!G187)
A208: =LEN(E208) -> 74 | B208: =LEN(F208) -> 131 | C208: =IF('Casos de Prueba'!B188<>0,'Casos de Prueba'!B188&"-"&'Casos de Prueba'!C188:E188,"") | D208: =IF(LEN($C208)>0,"",'Casos de Prueba'!D188) -> 2 | E208: =IF(LEN($C208)>0,"",'Casos de Prueba'!E188) -> Usuario ingresa a la URL correspondiente a la Consulta Central Retenciones | F208: =IF(LEN($C208)>0,"",'Casos de Prueba'!F188&CHAR(10)&'Casos de Prueba'!G188) -> Se muestran los datos para ingresar: Certificado (.cer) Clave privada (.Key) Contraseña de clave privada: Se muestra el campo RFC
A209: =LEN(E209) -> 82 | B209: =LEN(F209) -> 96 | C209: =IF('Casos de Prueba'!B189<>0,'Casos de Prueba'!B189&"-"&'Casos de Prueba'!C189:E189,"") | D209: =IF(LEN($C209)>0,"",'Casos de Prueba'!D189) -> 3 | E209: =IF(LEN($C209)>0,"",'Casos de Prueba'!E189) -> Usuario da clic en buscar y selecciona el archivo correspondiente a su certificado | F209: =IF(LEN($C209)>0,"",'Casos de Prueba'!F189&CHAR(10)&'Casos de Prueba'!G189) -> Se muestra el dato en el campo certificado y en el campo RFC el dato del RFC del contribuyente
A210: =LEN(E210) -> 84 | B210: =LEN(F210) -> 45 | C210: =IF('Casos de Prueba'!B190<>0,'Casos de Prueba'!B190&"-"&'Casos de Prueba'!C190:E190,"") | D210: =IF(LEN($C210)>0,"",'Casos de Prueba'!D190) -> 4 | E210: =IF(LEN($C210)>0,"",'Casos de Prueba'!E190) -> Usuario da clic en buscar y selecciona el archivo correspondiente a su clave privada | F210: =IF(LEN($C210)>0,"",'Casos de Prueba'!F190&CHAR(10)&'Casos de Prueba'!G190) -> Se muestra el dato en el campo clave privada
A211: =LEN(E211) -> 29 | B211: =LEN(F211) -> 49 | C211: =IF('Casos de Prueba'!B191<>0,'Casos de Prueba'!B191&"-"&'Casos de Prueba'!C191:E191,"") | D211: =IF(LEN($C211)>0,"",'Casos de Prueba'!D191) -> 5 | E211: =IF(LEN($C211)>0,"",'Casos de Prueba'!E191) -> Usuario ingresa su contraseña | F211: =IF(LEN($C211)>0,"",'Casos de Prueba'!F191&CHAR(10)&'Casos de Prueba'!G191) -> Se muestra oculto el dato en el campo contraseña
A212: =LEN(E212) -> 17 | B212: =LEN(F212) -> 45 | C212: =IF('Casos de Prueba'!B192<>0,'Casos de Prueba'!B192&"-"&'Casos de Prueba'!C192:E192,"") | D212: =IF(LEN($C212)>0,"",'Casos de Prueba'!D192) -> 6 | E212: =IF(LEN($C212)>0,"",'Casos de Prueba'!E192) -> Da clic en enviar | F212: =IF(LEN($C212)>0,"",'Casos de Prueba'!F192&CHAR(10)&'Casos de Prueba'!G192) -> Se muestra la pantalla principal de consulta
A213: =LEN(E213) -> 0 | B213: =LEN(F213) -> 0 | C213: =IF('Casos de Prueba'!B193<>0,'Casos de Prueba'!B193&"-"&'Casos de Prueba'!C193:E193,"") -> CP28-Cierre Sesión Inactividad | D213: =IF(LEN($C213)>0,"",'Casos de Prueba'!D193) | E213: =IF(LEN($C213)>0,"",'Casos de Prueba'!E193) | F213: =IF(LEN($C213)>0,"",'Casos de Prueba'!F193&CHAR(10)&'Casos de Prueba'!G193)
A214: =LEN(E214) -> 47 | B214: =LEN(F214) -> 217 | C214: =IF('Casos de Prueba'!B194<>0,'Casos de Prueba'!B194&"-"&'Casos de Prueba'!C194:E194,"") | D214: =IF(LEN($C214)>0,"",'Casos de Prueba'!D194) -> 1 | E214: =IF(LEN($C214)>0,"",'Casos de Prueba'!E194) -> Usuario ingresa al Consulta Central Retenciones | F214: =IF(LEN($C214)>0,"",'Casos de Prueba'!F194&CHAR(10)&'Casos de Prueba'!G194) -> El sistema despliega las siguientes opciones de búsqueda: - Folio Fiscal - Fecha Inicial y Final de Emisión - Masiva UUID El Usuario previamente se autenticó y accedió al portal Empleados-Consulta Central Retenciones
A215: =LEN(E215) -> 59 | B215: =LEN(F215) -> 74 | C215: =IF('Casos de Prueba'!B195<>0,'Casos de Prueba'!B195&"-"&'Casos de Prueba'!C195:E195,"") | D215: =IF(LEN($C215)>0,"",'Casos de Prueba'!D195) -> 2 | E215: =IF(LEN($C215)>0,"",'Casos de Prueba'!E195) -> Usuario deja la sesión abierta sin realizar ninguna acción. | F215: =IF(LEN($C215)>0,"",'Casos de Prueba'!F195&CHAR(10)&'Casos de Prueba'!G195) -> Después de 10 minutos de inactividad, se cerrará la sesión en automático.
...

Sheet Devops_Carga
B1: Work Item type | C1: Title | D1: Test Step | E1: Step Action | F1: Step expected
B2: Test Case | C2: CP01-Folio Fiscal
D3: 1 | E3: Usuario ingresa al Portal Empleados Consulta Central Retenciones | F3: El sistema despliega las siguientes opciones de búsqueda: - Folio Fiscal - Fecha Inicial y Final de Emisión - Masiva UUID El Usuario previamente se autenticó y accedió al portal Empleados-Consulta Central Retenciones
D4: 2 | E4: Selecciona la opción Folio Fiscal | F4: El sistema despliega cuadro de texto para incorporar el número de Folio Fiscal que se requiere buscar. Se inhabilita el campo Fecha Inicial de Emisión (Aplica la Regla de Negocio 01)
D5: 3 | E5: Ingresa los datos del Folio Fiscal | F5: El sistema muestra los datos que se van ingresando del folio fiscal
D6: 4 | E6: Da clic en el botón buscar CFDI | F6: En caso de no encontrar información ir al CP "Sin Resultados" En caso contrario el sistema muestra: Tabla con el encabezado y los datos siguientes: + Acciones • Descargar.(XML) • Ver Detalle.(RI) Columnas: • Folio Fiscal • RFC Emisor • Nombre o Razón Social del Emisor • RFC Receptor • Nombre o Razón Social del Receptor • Fecha de Emisión • Fecha de Certificación • Monto Total Retenido • Monto Total de la Operación • Estado del Comprobante • Clave de la retención • Fecha de Cancelación • PAC que Certificó • Motivo de cancelación • Folio de sustitución + Botones: 1)Descargar Metadata. 2)Exportar Resultados a PDF. 3)Exportar Resultados a CSV.
D7: 5 | E7: Da clic en cerrar sesión | F7: Cierra la aplicación y se direcciona a la pantalla de autenticación.
C8: CP02-RFC Emisor
D9: 1 | E9: Usuario ingresa al Portal Empleados Consulta Central Retenciones | F9: El sistema despliega las siguientes opciones de búsqueda: - Folio Fiscal - Fecha Inicial y Final de Emisión - Masiva UUID El Usuario previamente se autenticó y accedió al portal Empleados-Consulta Central Retenciones
D10: 2 | E10: Selecciona la opción Fecha Inicial de Emisión | F10: El sistema habilita los siguientes campos: • Fecha Inicial de Emisión (*). • Fecha Final de Emisión (*). (RN04) • RFC Emisor. (RN02) • RFC Receptor. (RN02) • Estado del Comprobante. • Tipo de Comprobante (RN17).* Campos obligatorios El Usuario previamente se autenticó y accedió al portal Empleados-Consulta Central Retenciones Se debe incorporar el RFC de al menos alguno de los siguientes: - RFC Emisor (RN02) - RFC Receptor (RN02)
D11: 3 | E11: Ingresa los datos: - *Fecha inicial de emisión - *Fecha final de emisión - RFC Emisor De manera opcional: - Estado del Comprobante - Tipo de Comprobante * Campos obligatorios | F11: El sistema muestra los datos que se van ingresando Al seleccionar el botón para la consulta por periodo de fecha de emisión, se debe deshabilitar el campo correspondiente a la consulta de Folio Fiscal.
D12: 4 | E12: Da clic en el botón buscar CFDI | F12: En caso de no encontrar información ir al CP "Sin Resultados" En caso contrario el sistema muestra: Botón Recuperar descargas de CFDI Tabla con el encabezado y los datos siguientes: + Acciones • Descargar.(XML) • Ver Detalle.(RI) Columnas: • Folio Fiscal • RFC Emisor • Nombre o Razón Social del Emisor • RFC Receptor • Nombre o Razón Social del Receptor • Fecha de Emisión • Fecha de Certificación • Monto Total Retenido • Monto Total de la Operación • Estado del Comprobante • Clave de la retención • Fecha de Cancelación • PAC que Certificó • Motivo de cancelación • Folio de sustitución + Botones: 1)Descargar Seleccionados XML. 2)Descargas RI. 3)Descargar Metadata. 4)Exportar Resultados a PDF. 5)Exportar Resultados a CSV. En caso de que no se tenga información, el aplicativo dejará en blanco la sección que corresponda en la tabla de resultados. (Aplica la Regla de Negocio 06)
D13: 5 | E13: Da clic en cerrar sesión | F13: Cierra la aplicación y se direcciona a la pantalla de autenticación.
C14: CP03-RFC Receptor
D15: 1 | E15: Usuario ingresa al Portal Empleados Consulta Central Retenciones | F15: El sistema despliega las siguientes opciones de búsqueda: - Folio Fiscal - Fecha Inicial y Final de Emisión - Masiva UUID El Usuario previamente se autenticó y accedió al portal Empleados-Consulta Central Retenciones
D16: 2 | E16: Selecciona la opción Fecha Inicial de Emisión | F16: El sistema habilita los siguientes campos: • Fecha Inicial de Emisión (*). • Fecha Final de Emisión (*). (RN04) • RFC Emisor. (RN02) • RFC Receptor. (RN02) • Estado del Comprobante. • Tipo de Comprobante (RN17).* Campos obligatorios
D17: 3 | E17: Ingresa los datos: - *Fecha inicial de emisión - *Fecha final de emisión - *RFC Receptor Ingresa los datos: - Estado del Comprobante - Tipo de Comprobante * Campos obligatorios | F17: El sistema muestra los datos que se van ingresando
D18: 4 | E18: Da clic en el botón buscar CFDI | F18: En caso de no encontrar información ir al CP "Sin Resultados" En caso contrario el sistema muestra: Botón Recuperar descargas de CFDI Tabla con el encabezado y los datos siguientes: + Acciones • Descargar.(XML) • Ver Detalle.(RI) Columnas: • Folio Fiscal • RFC Emisor • Nombre o Razón Social del Emisor • RFC Receptor • Nombre o Razón Social del Receptor • Fecha de Emisión • Fecha de Certificación • Monto Total Retenido • Monto Total de la Operación • Estado del Comprobante • Clave de la retención • Fecha de Cancelación • PAC que Certificó • Motivo de cancelación • Folio de sustitución + Botones: 1)Descargar Seleccionados XML. 2)Descargas RI. 3)Descargar Metadata. 4)Exportar Resultados a PDF. 5)Exportar Resultados a CSV. En caso de que no se tenga información, el aplicativo dejará en blanco la sección que corresponda en la tabla de resultados. (Aplica la Regla de Negocio 06)
D19: 5 | E19: Da clic en cerrar sesión | F19: Cierra la aplicación y se direcciona a la pantalla de autenticación.
C20: CP04-RFC Receptor y RFC Emisor
D21: 1 | E21: Usuario ingresa al Portal Empleados Consulta Central Retenciones | F21: El sistema despliega las siguientes opciones de búsqueda: - Folio Fiscal - Fecha Inicial y Final de Emisión - Masiva UUID El Usuario previamente se autenticó y accedió al portal Empleados-Consulta Central Retenciones
D22: 2 | E22: Selecciona la opción Fecha Inicial de Emisión | F22: El sistema habilita los siguientes campos: • Fecha Inicial de Emisión (*). • Fecha Final de Emisión (*). (RN04) • RFC Emisor. (RN02) • RFC Receptor. (RN02) • Estado del Comprobante. • Tipo de Comprobante (RN17).* Campos obligatorios
D23: 3 | E23: Ingresa los datos: - *Fecha inicial de emisión - *Fecha final de emisión - *RFC Emisor - RFC Receptor De manera opcional lo siguiente: - Estado del Comprobante - Tipo de Comprobante * Campos obligatorios | F23: El sistema muestra los datos que se van ingresando
D24: 4 | E24: Da clic en el botón buscar CFDI | F24: En caso de no encontrar información ir al CP "Sin Resultados" En caso contrario el sistema muestra: Botón Recuperar descargas de CFDI Tabla con el encabezado y los datos siguientes: + Acciones • Descargar.(XML) • Ver Detalle.(RI) Columnas: • Folio Fiscal • RFC Emisor • Nombre o Razón Social del Emisor • RFC Receptor • Nombre o Razón Social del Receptor • Fecha de Emisión • Fecha de Certificación • Monto Total Retenido • Monto Total de la Operación • Estado del Comprobante • Clave de la retención • Fecha de Cancelación • PAC que Certificó • Motivo de cancelación • Folio de sustitución + Botones: 1)Descargar Seleccionados XML. 2)Descargas RI. 3)Descargar Metadata. 4)Exportar Resultados a PDF. 5)Exportar Resultados a CSV. En caso de que no se tenga información, el aplicativo dejará en blanco la sección que corresponda en la tabla de resultados. (Aplica la Regla de Negocio 06)
D25: 5 | E25: Da clic en cerrar sesión | F25: Cierra la aplicación y se direcciona a la pantalla de autenticación.
C26: CP05-Masiva UUID
D27: 1 | E27: Usuario ingresa al Portal Empleados Consulta Central Retenciones | F27: El sistema despliega las siguientes opciones de búsqueda: - Folio Fiscal - Fecha Inicial y Final de Emisión - Masiva UUID El Usuario previamente se autenticó y accedió al portal Empleados-Consulta Central Retenciones
