Workbook

Sheet Instrucciones
B15: Objetivo: Identificar los insumos necesarios para pruebas de aceptación de usuario, a través de los casos de prueba, ambientes requeridos, especificación de los datos, cobertura de escenarios y atributos relacionados, a fin de contar con la integración de datos suficientes para la ejecución de las pruebas de la solución tecnológica con el usuario.
B17: Guía de Uso: 1.- Las pestañas "Casos de Prueba" y "Ambientes Requeridos" serán llenadas por la Administración Central de Soluciones de Negocio (ACSN), en la Fase Análisis, Etapa Especificación Funcional. 2.- Las pestañas "Interfaz de Usuario" y "Cobertura" serán llenadas en la Fase Desarrollo por las áreas ténicas que deban participar. En la primera también participará la ACSN en la Fase Pruebas, Etapa Pruebas Funcionales (AVL), por tema de Lineamientos Gráficos del SIAT, y para reflejar resultado de dichas pruebas. 3.- El documento está firmado por los responsables del llenado, incluyendo por el negocio cuando participa en la autorización. 4.- Si la pestaña "Casos de Prueba" incluye varias páginas, debe imprimirse sólo la página que contienen las firmas. Una vez firmado, debe digitalizarse y almacenarse en el repositorio como sustento junto con el archivo de Excel que corresponda a todo el documento. 5.- Si fuera necesario reservar información generada en esta plantilla, se hará bajo lo estipulado en la Ley General de Transparencia y Acceso a la Información Pública vigente (LGTAIP), pudiendo consultar a la ACPPI para su aplicación. (Ver abajo "Nota acerca de Irformación Reservada"). 6.- La aplicación de la sección de Firmas es opcional,dependiendo de las necesidades del consumidor, pero al contener temas de usuario de Negocio es importante la firma de éste.
B18: Nota acerca de Información Reservada Es reponsabilidad de cada requisitador la identificación de la información que se genere en este formato y así determinar si se cuenta con causas que originen la reserva de la misma, apegándose estrictamente a lo señalado en los ordenamientos jurídicos vigentes en materia de Transparencia. En caso de detectar información sensible (Reservada), se tendrá que indicar en la sección u hoja que lo amerite de este documento, en la parte inferior del texto, con la siguiente señalización: [Área dueña de la Información XX, clasificada como Reservada con Fundamento Legal XX, Motivación XX, Fecha de clasificación XX y Periodo de la reserva XX]. Ejemplo: "La información contenida en este documento pertenece a la Administración Central de Soluciones de Negocio, teniendo carácter de Reservada a partir del 01 de abril de 2018, con un periodo de reserva de 5 años, por tratarse de información que de revelarse puede causar un serio perjuicio a la recaudación de las contribuciones. Lo anterior tiene su fundamento en el artículo 113, fracción IV, de la Ley General de Transparencia y Acceso a la Información Pública."
B20: Hoja | D20: Descripción
B21: Casos de Prueba | D21: Esta hoja se utiliza para la documentación detallada de los casos de pruebas que serán utilizados en la ejecución de pruebas.
D22: Registra varios casos de prueba, con la finalidad de agrupar en un solo documento una cantidad suficiente de casos que pueda ser aprovechada para la importación de casos de prueba en alguna herramienta automatizada, o bien, para obtener de ella la información de casos de prueba. También se utiliza para especificar los elementos donde se emplearán los datos (Datos de Prueba)
D23: Criterios de Aceptación
D24: • El documento es utilizado de acuerdo al formato establecido. El documento cumple con el Marco Documental vigente. • El documento no contiene faltas de ortografía. • Cuando no se llene un renglón-columna, se deberá especificar el motivo por el cual no se registra la información, conteniendo al menos un "N/A". Ningún campo debe estar vacío. ●No se combinan celdas (exceptuando la sección de firmas) ●No incluye fórmulas en ningún renglón-columna • El documento describe detalladamente paso a paso las actividades a seguir para la validación de requerimientos del sistema. • El documento describe en cada paso una acción y una respuesta esperada que puede ser evaluada. El documento está firmado por los responsables del llenado, incluyendo por el negocio cuando participa en la autorización.
B26: Hoja | D26: Descripción
B27: Ambientes Requeridos | D27: Registra elementos de información sobre repositorios y ambientes necesarios para las pruebas y sus características, relacionadas con criterios que debe cubrir la información que se requiere para las pruebas; cantidad de datos requeridos para la ejecución de la prueba; datos o campos solicitados; condiciones que se deben cubrir para la extracción de datos y comentarios adicionales.
D28: Criterios de Aceptación
D29: * El documento es utilizado de acuerdo al formato establecido. * El documento cumple con el Marco Documental vigente. * El documento no contiene faltas de ortografía. * Cuando no se llene un renglón-columna, se deberá especificar el motivo por el cual no se registra la información, conteniendo al menos un "N/A". Ningún campo debe estar vacío. * El documento está firmado por los responsables del llenado, incluyendo por el negocio cuando participa en la autorización.
B31: Hoja | D31: Descripción
B32: Interfaz de Usuario | D32: Esta hoja aplica por la naturaleza de la solución tecnológica integrada que haya sido requerida. Se utiliza para validar que se cumplan los criterios definidos para la Interfaz de Usuario, incluyendo la aplicación y verificación de los Lineamientos Gráficos del SIAT, cuando sea el caso.
D33: Se detallan los puntos a validar de interfaz de usuario (interfaz gráfica) de las aplicaciones, como encabezados, pie de página, colores, alineación, etiquetas, listas desplegables, áreas de búsqueda, etc, etc.
D34: Criterios de Aceptación
D35: • El documento es utilizado de acuerdo al formato establecido. • El documento no contiene faltas de ortografía. • Cuando no se llene un renglón-columna, se deberá especificar el motivo por el cual no se registra la información. • Cada una de las características consideradas en esta pestaña estarán asociadas al contenido del artefacto "Especificación de Interacción de Usuario", en caso de ajustes o situaciones que expongan desviación al documento en comento, deberá ajustarse. • Cada defecto detectado deberá registrarse en la herramienta correspondiente para su atención y cierre.
B37: Hoja | D37: Descripción
B38: Cobertura | D38: Esta hoja se utiliza para identificar y detallar la cobertura de la prueba basada en complejidad ciclomática, para asegurar que se diseñen tantos casos de prueba como sean necesarios para que cada condición se ejecute al menos una vez con un valor verdadero, y al menos una vez uno falso.
D40: Criterios de Aceptación
D41: • El documento es utilizado de acuerdo al formato establecido. • El documento no contiene faltas de ortografía. • Cuando no se llene un renglón-columna, se deberá especificar el motivo por el cual no se registra la información. • El documento describe detalladamente los escenarios de prueba necesarios para que cada condición se ejecute al menos una vez con un valor verdadero y al menos una vez uno falso.
B43: Hoja | D43: Descripción
B44: Encabezado_Imagen | D44: En artefactos tipo Excel, la inserción del Encabezado como imagen en el mismo documento, puede hacerse como una alternativa cuando por la naturaleza y cantidad de información registrada en él, se hace necesario ampliar significativamente el tamaño de las celdas, ocasionando con ello distorsión o inadecuada distribución de la estructura del Encabezado del artefacto. Si ese fuera el caso, en esta hoja puede configurarse el Encabezado del artefacto y después insertarlo como imagen en cualquier otra sección del mismo, siguiendo las instrucciones allí descritas.
B46: Hoja | D46: Descripción
B47: Firmas Conformidad_Imagen | D47: En artefactos tipo Excel, la inserción de la Sección FIRMAS DE CONFORMIDAD como imagen en el mismo documento, puede hacerse como una alternativa cuando por la naturaleza y cantidad de información registrada en él, se hace necesario ampliar significativamente el tamaño de las celdas, ocasionando con ello distorsión o inadecuada distribución de la estructura de la sección de firmas localizada en la parte inferior del artefacto. Si ese fuera el caso, en esta hoja puede capturarse la información de las personas que participan en la elaboración y aprobación del artefacto, y después insertarla como imagen en cualquier otra sección del documento, siguiendo los pasos que allí se describen.

Sheet Versionamiento
B12: Tabla de Versiones y Modificaciones
B13: En la tabla siguiente se deben listar las versiones y descripciones hechas a este documento, desde el momento de su creación y cada vez que se llene y/o actualice alguna de sus pestañas. La descripción debe incluir una síntesis del cambio hecho.
B14: Para la Versión, especificar un número entero consecutivo, iniciando con 1 para la creación del documento e incrementar en decimales conforme se actualice (1.1, 1.2, 1.3, Etc.). Al terminarlo, especificar la versión final para firma, en caso necesario.
B15: Para futuros proyectos donde este documento se reutilice, el versionamiento reiniciará en versión 2, incrementando las actualizaciones igualmente con decimales (2.1, 2.2, 2.3, etc.). Posteriores reutilizaciones iniciarían entonces con versión 3, 4, etc.
C18: Versión | D18: Descripción del Cambio | E18: Responsable de la Versión | F18: Fecha
C19: 0.1 | D19: Creación del documento. | E19: Alma Q. Torres González | F19: 45652
C20: 1.1 | D20: Se complementaron los casos de prueba por revisión con el Negocio (Ejemplo)
C21: 2 | D21: Se reutiliza el documento para actualizaciones. (Ejemplo)
C22: 2.1 | D22: Versión aprobada para firma.
C23: 0.2 | D23: Ajustes: CC083 Masiva UUID CC084 Descargar acuse de cancelación | E23: Alma Q. Torres González Nadia Anahí Ortega Nava | F23: 45652
C24: 0.3 | D24: Ajustes: Ajustar RDP de acuerdo a los ajustes de la Narrativa | E24: Alma Q. Torres González | F24: 45820
C25: 0.4 | D25: Ajustes: -Se generar CP30 conforme CC120 – Incorporar Folios relacionados -Se generar CP31 conforme CC121 – Descargar RI Complemento Carta Porte -Actualizar CP07, CP08, CP09 y CP10 relacionados al Acuse de cancelación | E25: Alma Q. Torres González | F25: 45821
C26: 0.5 | D26: CC120 – (punto 5) Agregar columnas en acuse de cancelación: -Motivo de Cancelación -Número de serie de la e.firma o CSD -Fecha de solicitud de la cancelación Actualizar CP07, CP08, CP09 y CP10 | E26: Alma Q. Torres González | F26: 45854
C27: 1.0 | D27: Versión aprobada para firma | E27: Roberto Monroy Vargas Mario Alberto Huerta Velázquez

Sheet ListadoCP
C10: Portal Consulta Central CFDI
C11: Casos de Prueba | D11: Rol
B13: CP01 | C13: ConsultaCentral_CFDI_Búsqueda/FolioFiscal | D13: CFDI01 CFDI02 CFDI03 CFDI04 CFDI05
B14: CP02 | C14: ConsultaCentral_CFDI_Búsqueda/Fecha/RFCEmisor | D14: CFDI01 CFDI02 CFDI03 CFDI04 CFDI05
B15: CP03 | C15: ConsultaCentral_CFDI_Búsqueda/Fecha/RFCReceptor | D15: CFDI01 CFDI02 CFDI03 CFDI04 CFDI05
B16: CP04 | C16: ConsultaCentral_CFDI_Búsqueda/Fecha/RFCTercero | D16: CFDI01 CFDI02 CFDI03 CFDI04 CFDI05
B17: CP05 | C17: ConsultaCentral_CFDI_Búsqueda/ResultadodeConsulta/Sin Resultados | D17: CFDI01 CFDI02 CFDI03 CFDI04 CFDI05
B18: CP06 | C18: ConsultaCentral_CFDI_Búsqueda/Masiva UUID | D18: CFDI01 CFDI02 CFDI03 CFDI04 CFDI05
B19: CP07 | C19: ConsultaCentral_CFDI_Búsqueda/FolioFiscal/Acuse de Cancelación | D19: CFDI01 CFDI02 CFDI04
B20: CP08 | C20: ConsultaCentral_CFDI_Búsqueda/RFCEmisor/Acuse de Cancelación | D20: CFDI01 CFDI02 CFDI04
B21: CP09 | C21: ConsultaCentral_CFDI_Búsqueda/RFCReceptor/Acuse de Cancelación | D21: CFDI01 CFDI02 CFDI04
B22: CP10 | C22: ConsultaCentral_CFDI_Búsqueda/Masiva UUID/Acuse de Cancelación | D22: CFDI01 CFDI02 CFDI04
B23: CP11 | C23: ConsultaCentral_CFDI_Búsqueda/FolioFiscal/Descargar RI | D23: CFDI01 CFDI02 CFDI04
B24: CP12 | C24: ConsultaCentral_CFDI_Búsqueda/RFCEmisor/Descargar RI | D24: CFDI01 CFDI02 CFDI04
... B46: CP34 | C46: Busqueda/Tipo de Comprobante (Complemento) | D46: CFDI01 CFDI02 CFDI03 CFDI04 CFDI05

Sheet Casos de Prueba
D10: Casos de Prueba
A12: Código del Aplicativo:
A13: ID de Requerimiento: | C13: POL 8211
A14: Nombre de Requerimiento: | C14: FE – Servicios Gratuitos – Realizar la actualización del Complemento de CartaPorte y de Comercio Exterior, así como, a los Servicios de Consulta del Empleado
A15: [Fase: Análisis] [Etapa: Especificación Funcional] (ACSN)
A17: ID del Caso | B17: CP | C17: Nombre del Caso | D17: Paso | E17: Descripción de Paso | F17: Resultado Esperado | G17: Comentarios | H17: Perfil de usuario para su ejecución | I17: Datos de Prueba
A18: Identificador del caso de prueba que se integrará en Quality Center (QC). El ID del caso NO debe contener espacios en blanco. La diagonal debe ser “\”. La nomenclatura estándar es: PPMC_Número\Componente Tecnológico o Aplicativo(ya que ésta es la estructura o ruta de carpetas para almacenar y agrupar los objetos creados para contener la información de los Casos de Prueba y Escenarios de Pruebas). (Ejemplo: PPMC_56124\Juicios de Nulidad) | C18: Nombre completo representativo del Caso asociado a la funcionalidad a probar. Ejemplo de nombre: "Validación de la Fecha Notificación de la Demanda" El Nombre del Caso no debe contener caracteres especiales (\/:%’*?<>|”@, , etc.) y debe tener longitud máxima de 85 caracteres. Si son más de un caso de prueba y tienen un orden de ejecución entonces, antes del nombre, debe estar acompañado de un número consecutivo del caso de prueba, anteponiendo las siglas "CP": CP1_Nombre del Caso CP2_Nombre del Caso CP3_Nombre del Caso Etc. (Si no se requiere un orden de ejecución, no es necesario ordenarlos de esta forma.) | D18: Identificador secuencial de los pasos que sigue el caso de prueba. La información de todos los pasos de un Caso de Prueba debe ser consistente. | E18: Narración detallada del paso a ejecutar. Se deben evitar paréntesis y/o corchetes seguidos "{{..[[..((…))..]]..]]". No dejar en blanco, escribir N/A en caso de que no aplique. | F18: Narración detallada del resultado esperado, dada la ejecución del paso. Se deben evitar paréntesis y/o corchetes seguidos "{{..[[..((…))..]]..]]". No dejar en blanco, escribir N/A en caso de que no aplique. | G18: Anotaciones sobre lo que deba considerarse en forma adicional para la ejecución del Caso (descripción de los prerrequisitos que deben ser cubiertos para la ejecución del caso de prueba, identificación de las entradas requeridas del caso de prueba ). Se deben evitar paréntesis y/o corchetes seguidos "{{..[[..((…))..]]..]]". No dejar en blanco, escribir N/A en caso de que no aplique. | H18: Descripción del Perfil de usuario que se utilizará para la ejecución del Caso de Prueba. No dejar en blanco, escribir N/A en caso de que no aplique | I18: Para indicar los casos prueba y descripción de los elementos donde se emplearán los datos. Indicar el nombre del Dato de Prueba (RFC, Periodo,…) Ejemplos: Indicar el contenido del dato (AAAA790909JN6, 2010-01, …) Indicar el contenido del dato (AAAA790909JN6, 2010-02, …)
B19: CP01 | C19: Busqueda/Folio Fiscal
A20: POL_8214 /PortalEmpleado/ConsultaCentralCFDI | D20: 1 | E20: Usuario ingresa al Portal Empleados Consulta Central | F20: El sistema muestra las siguientes opciones de búsqueda: - Folio Fiscal - Masiva UUID - Fecha Inicial y Final de Emisión | G20: El Usuario previamente se autenticó y accedió al portal Empleados-Consulta Central | H20: Rol CFDI01 Rol CFDI02 Rol CFDI03 Rol CFDI04 Rol CFDI05 | I20: Firma Electrónica del Usuario. El Usuario debe tener asignado cualquiera de los roles | J20: {=LEN(F20:G20)} -> 120 | K20: 83 | L20: =+J20+K20 -> 203
A21: POL_8214 /PortalEmpleado/ConsultaCentralCFDI | D21: 2 | E21: Selecciona la opción Folio Fiscal | F21: El sistema muestra cuadro de texto para incorporar el número de Folio Fiscal que se requiere buscar. | G21: Al seleccionar el botón de folio fiscal se deben deshabilitar los campos de la sección Fecha Inicial y Final de Emisión (Aplica la Regla de Negocio 01) | J21: {=LEN(F21:G21)} -> 101 | K21: 152 | L21: =+J21+K21 -> 253
A22: POL_8214 /PortalEmpleado/ConsultaCentralCFDI | D22: 3 | E22: Ingresa los datos del Folio Fiscal | F22: El sistema muestra los datos que se van ingresando del folio fiscal | J22: {=LEN(F22:G22)} -> 68 | K22: 0 | L22: =+J22+K22 -> 68
A23: POL_8214 /PortalEmpleado/ConsultaCentralCFDI | D23: 4 | E23: Da clic en el botón buscar CFDI | F23: Si la petición es correcta, el sistema muestra: A. Casilla Acciones 1) Seleccionar. 2) Descargar. 3) Recuperar Representación Impresa. 4) Recuperar Representacion Impresa Carta Porte. B. Datos de la Metadata del CFDI. • Folio Fiscal • RFC Emisor • Nombre o Razón Social del Emisor • RFC Receptor • Nombre o Razón Social del Receptor • Fecha de Emisión • Fecha de Certificación • Subtotal • Total • Estado del Comprobante • Efecto del Comprobante • Fecha de Cancelación • PAC que Certificó • Estatus de Cancelación • Estatus de Proceso de Cancelación • Fecha de Solicitud de la cancelación • Motivo • Folio de sustitución • RFC a cuenta de terceros C. Botones: 1) Descargar Metadata. 2) Exportar Resultados a PDF. 3) Exportar Resultados a CSV. | G23: El aplicativo debe realizar la búsqueda de todas las versiones del CFDI (3.2, 3.3 y 4.0), de acuerdo a los criterios de búsqueda seleccionados previamente. En caso de no encontrar información ir al Caso de Prueba "Sin Resultados" En una consulta por Folio fiscal o cuando se realice la c onsulta por periodo de fecha y el resultado sea uno: (Aplica la Regla de Negocio 15) *Descargar metadata *Exportar Resultados a PDF *Exportar Resultados a CSV | J23: {=LEN(F23:G23)} -> 748 | K23: 452 | L23: =+J23+K23 -> 1200
A24: POL_8214 /PortalEmpleado/ConsultaCentralCFDI | D24: 5 | E24: Da clic en cerrar sesión | F24: Cierra la aplicación y se direcciona a la pantalla de autenticación. | J24: {=LEN(F24:G24)} -> 68 | K24: 0 | L24: =+J24+K24 -> 68
B25: CP02 | C25: Busqueda/RFC Emisor | J25: {=LEN(F25:G25)} -> 0 | K25: 0 | L25: =+J25+K25 -> 0
A26: POL_8214 /PortalEmpleado/ConsultaCentralCFDI | D26: 1 | E26: Usuario ingresa al Portal Empleados Consulta Central | F26: El sistema muestra las siguientes opciones de búsqueda: - Folio Fiscal - Masiva UUID - Fecha Inicial y Final de Emisión | G26: El Usuario previamente se autenticó y accedió al portal Empleados-Consulta Central | H26: Rol CFDI01 Rol CFDI02 Rol CFDI03 Rol CFDI04 Rol CFDI05 | I26: Firma Electrónica del Usuario. El Usuario debe tener asignado cualquiera de los roles Para este caso de prueba se debe agregar el valor de un RFC Emisor. | J26: {=LEN(F26:G26)} -> 120 | K26: 83 | L26: =+J26+K26 -> 203
A27: POL_8214 /PortalEmpleado/ConsultaCentralCFDI | D27: 2 | E27: Selecciona la opción Fecha Inicial y Final de Emisión | F27: El sistema habilita los siguientes campos: • Fecha Inicial de Emisión (*). • Fecha Final de Emisión (*). • RFC Emisor. • RFC Receptor. • RFC a cuenta terceros. • Tipo de Comprobante. • Estado del Comprobante. • Tipo de Comprobante (Complemento) (RN17). • Estatus Cancelación (Campo condicional). | J27: {=LEN(F27:G27)} -> 295 | K27: 0 | L27: =+J27+K27 -> 295
A28: POL_8214 /PortalEmpleado/ConsultaCentralCFDI | D28: 3 | E28: Ingresa los datos: • Fecha Inicial de Emisión (*). • Fecha Final de Emisión (*). • RFC Emisor. • RFC Receptor. • RFC a cuenta de terceros. • Tipo de Comprobante. • Estado del Comprobante. • Tipo de Comprobante (Complemento) (RN17). • Estatus Cancelación (Campo condicional). Campo obligarorio (*) Nota: Para realizar la búsqueda se debe proporcionar al menos un RFC como parámetro de búsqueda(RFC Emisor, RFC Receptor o RFC a cuenta terceros | F28: El sistema muestra los datos que se van ingresando . | J28: {=LEN(F28:G28)} -> 52 | K28: 0 | L28: =+J28+K28 -> 52
A29: POL_8214 /PortalEmpleado/ConsultaCentralCFDI | D29: 4 | E29: Da clic en el botón buscar CFDI | F29: Si la petición es correcta, el sistema muestra: A. Casilla Acciones 1) Seleccionar. 2) Descargar 3) Recuperar Representacion Impresa. 4) Recuperar Representacion Impresa Carta Porte. B. Datos de la Metadata del CFDI. • Folio Fiscal • RFC Emisor • Nombre o Razón Social del Emisor • RFC Receptor • Nombre o Razón Social del Receptor • Fecha de Emisión • Fecha de Certificación • Subtotal • Total • Estado del Comprobante • Efecto del Comprobante • Fecha de Cancelación • PAC que Certificó • Estatus de Cancelación • Estatus de Proceso de Cancelación • Fecha de Solicitud de la cancelación • Motivo • Folio de sustitución • RFC a cuenta de terceros C. Botones: 1) Descargar Seleccionados XML. 2) Descargas RI. 3) Descargar Metadata. 4) Exportar Resultados a PDF. 5) Exportar Resultados a CSV. D. Paginador. | G29: En una consulta por Folio fiscal o cuando se realice la c onsulta por periodo de fecha y el resultado sea uno: (Aplica la Regla de Negocio 15) *Descargar metadata *Exportar Resultados a PDF *Exportar Resultados a CSV | J29: {=LEN(F29:G29)} -> 810 | K29: 220 | L29: =+J29+K29 -> 1030
A30: POL_8214 /PortalEmpleado/ConsultaCentralCFDI | D30: 5 | E30: Da clic en cerrar sesión | F30: Cierra la aplicación y se direcciona a la pantalla de autenticación. | J30: {=LEN(F30:G30)} -> 68 | K30: 0 | L30: =+J30+K30 -> 68
B31: CP03 | C31: Busqueda/RFC Receptor | J31: {=LEN(F31:G31)} -> 0 | K31: 0 | L31: =+J31+K31 -> 0
A32: POL_8214 /PortalEmpleado/ConsultaCentralCFDI | D32: 1 | E32: Usuario ingresa al Portal Empleados Consulta Central | F32: El sistema muestra las siguientes opciones de búsqueda: - Folio Fiscal - Masiva UUID - Fecha Inicial y Final de Emisión | G32: El Usuario previamente se autenticó y accedió al portal Empleados-Consulta Central | H32: Rol CFDI01 Rol CFDI02 Rol CFDI03 Rol CFDI04 Rol CFDI05 | I32: Firma Electrónica del Usuario. El Usuario debe tener asignado cualquiera de los roles Ingresa el valor de un RFC Receptor. | J32: {=LEN(F32:G32)} -> 120 | K32: 83 | L32: =+J32+K32 -> 203
A33: POL_8214 /PortalEmpleado/ConsultaCentralCFDI | D33: 2 | E33: Selecciona la opción Fecha Inicial y Final de Emisión | F33: El sistema habilita los siguientes campos: • Fecha Inicial de Emisión (*). • Fecha Final de Emisión (*). • RFC Emisor. • RFC Receptor. • RFC a cuenta de terceros. • Tipo de Comprobante. • Estado del Comprobante. • Tipo de Comprobante (Complemento) (RN17). • Estatus Cancelación (Campo condicional). | J33: {=LEN(F33:G33)} -> 298 | K33: 0 | L33: =+J33+K33 -> 298
A34: POL_8214 /PortalEmpleado/ConsultaCentralCFDI | D34: 3 | E34: Ingresa los datos: • Fecha Inicial de Emisión (*). • Fecha Final de Emisión (*). • RFC Emisor. • RFC Receptor. • RFC a cuenta de terceros. • Tipo de Comprobante. • Estado del Comprobante. • Tipo de Comprobante (Complemento) (RN17). • Estatus Cancelación (Campo condicional). Campo obligarorio (*) Nota: Para realizar la búsqueda se debe proporcionar al menos un RFC como parámetro de búsqueda(RFC Emisor, RFC Receptor o RFC a cuenta terceros | F34: El sistema muestra los datos que se van ingresando . | J34: {=LEN(F34:G34)} -> 52 | K34: 0 | L34: =+J34+K34 -> 52
A35: POL_8214 /PortalEmpleado/ConsultaCentralCFDI | D35: 4 | E35: Da clic en el botón buscar CFDI | F35: Si la petición es correcta, el sistema muestra: A. Casilla Acciones 1) Seleccionar. 2) Descargar 3) Recuperar Representacion Impresa. 4) Recuperar Representacion Impresa Carta Porte. B. Datos de la Metadata del CFDI. • Folio Fiscal • RFC Emisor • Nombre o Razón Social del Emisor • RFC Receptor • Nombre o Razón Social del Receptor • Fecha de Emisión • Fecha de Certificación • Subtotal • Total • Estado del Comprobante • Efecto del Comprobante • Fecha de Cancelación • PAC que Certificó • Estatus de Cancelación • Estatus de Proceso de Cancelación • Fecha de Solicitud de la cancelación • Motivo • Folio de sustitución • RFC a cuenta de terceros C. Botones: 1) Descargar Seleccionados XML. 2) Descargas RI. 3) Descargar Metadata. 4) Exportar Resultados a PDF. 5) Exportar Resultados a CSV. D. Paginador. | G35: En una consulta por Folio fiscal o cuando se realice la c onsulta por periodo de fecha y el resultado sea uno: (Aplica la Regla de Negocio 15) *Descargar metadata *Exportar Resultados a PDF *Exportar Resultados a CSV | J35: {=LEN(F35:G35)} -> 810 | K35: 220 | L35: =+J35+K35 -> 1030
A36: POL_8214 /PortalEmpleado/ConsultaCentralCFDI | D36: 5 | E36: Da clic en cerrar sesión | F36: Cierra la aplicación y se direcciona a la pantalla de autenticación. | J36: {=LEN(F36:G36)} -> 68 | K36: 0 | L36: =+J36+K36 -> 68
B37: CP04 | C37: Busqueda/RFC Tercero | J37: {=LEN(F37:G37)} -> 0 | K37: 0 | L37: =+J37+K37 -> 0
A38: POL_8214 /PortalEmpleado/ConsultaCentralCFDI | D38: 1 | E38: Usuario ingresa al Portal Empleados Consulta Central | F38: El sistema muestra las siguientes opciones de búsqueda: - Folio Fiscal - Masiva UUID - Fecha Inicial y Final de Emisión | G38: El Usuario previamente se autenticó y accedió al portal Empleados-Consulta Central | H38: Rol CFDI01 Rol CFDI02 Rol CFDI03 Rol CFDI04 Rol CFDI05 | I38: Firma Electrónica del Usuario. El Usuario debe tener asignado cualquiera de los roles Ingresa el valor de un RFC a cuenta de terceros. | J38: {=LEN(F38:G38)} -> 120 | K38: 83 | L38: =+J38+K38 -> 203
A39: POL_8214 /PortalEmpleado/ConsultaCentralCFDI | D39: 2 | E39: Selecciona la opción Fecha Inicial y Final de Emisión | F39: El sistema habilita los siguientes campos: • Fecha Inicial de Emisión (*). • Fecha Final de Emisión (*). • RFC Emisor. • RFC Receptor. • RFC a cuenta de terceros. • Tipo de Comprobante. • Estado del Comprobante. • Tipo de Comprobante (Complemento) (RN17). • Estatus Cancelación (Campo condicional). | J39: {=LEN(F39:G39)} -> 298 | K39: 0 | L39: =+J39+K39 -> 298
A40: POL_8214 /PortalEmpleado/ConsultaCentralCFDI | D40: 3 | E40: Ingresa los datos: • Fecha Inicial de Emisión (*). • Fecha Final de Emisión (*). • RFC Emisor. • RFC Receptor. • RFC a cuenta de terceros. • Tipo de Comprobante. • Estado del Comprobante. • Tipo de Comprobante (Complemento) (RN17). • Estatus Cancelación (Campo condicional). Campo obligarorio (*) Nota: Para realizar la búsqueda se debe proporcionar al menos un RFC como parámetro de búsqueda(RFC Emisor, RFC Receptor o RFC a cuenta terceros | F40: El sistema muestra los datos que se van ingresando . | J40: {=LEN(F40:G40)} -> 52 | K40: 0 | L40: =+J40+K40 -> 52
A41: POL_8214 /PortalEmpleado/ConsultaCentralCFDI | D41: 4 | E41: Da clic en el botón buscar CFDI | F41: Si la petición es correcta, el sistema muestra: A. Casilla Acciones 1) Seleccionar. 2) Descargar 3) Recuperar Representacion Impresa. 4) Recuperar Representacion Impresa Carta Porte. B. Datos de la Metadata del CFDI. • Folio Fiscal • RFC Emisor • Nombre o Razón Social del Emisor • RFC Receptor • Nombre o Razón Social del Receptor • Fecha de Emisión • Fecha de Certificación • Subtotal • Total • Estado del Comprobante • Efecto del Comprobante • Fecha de Cancelación • PAC que Certificó • Estatus de Cancelación • Estatus de Proceso de Cancelación • Fecha de Solicitud de la cancelación • Motivo • Folio de sustitución • RFC a cuenta de terceros C. Botones: 1) Descargar Seleccionados XML. 2) Descargas RI. 3) Descargar Metadata. 4) Exportar Resultados a PDF. 5) Exportar Resultados a CSV. D. Paginador. | G41: En una consulta por Folio fiscal o cuando se realice la c onsulta por periodo de fecha y el resultado sea uno: (Aplica la Regla de Negocio 15) *Descargar metadata *Exportar Resultados a PDF *Exportar Resultados a CSV | J41: {=LEN(F41:G41)} -> 810 | K41: 220 | L41: =+J41+K41 -> 1030
A42: POL_8214 /PortalEmpleado/ConsultaCentralCFDI | D42: 5 | E42: Da clic en cerrar sesión | F42: Cierra la aplicación y se direcciona a la pantalla de autenticación. | J42: {=LEN(F42:G42)} -> 68 | K42: 0 | L42: =+J42+K42 -> 68
B43: CP05 | C43: Sin Resultados | J43: {=LEN(F43:G43)} -> 0 | K43: 0 | L43: =+J43+K43 -> 0
A44: POL_8214 /PortalEmpleado/ConsultaCentralCFDI | D44: 1 | E44: Da clic en el botón buscar | F44: En caso de que no se encuentre información con los parámetros de búsqueda ingresados, el sistema muestra el siguiente mensaje: “No existen registros que cumplan con los criterios de búsqueda ingresados, intentar nuevamente” | G44: Viene de los Casos de Prueba: - CP01_ConsultaCentral_CFDI_Búsqueda/Folio Fiscal - CP02_ConsultaCentral_CFDI_Búsqueda/RFCEmisor - CP03_ConsultaCentral_CFDI_Búsqueda/RFCReceptor - CP04_ConsultaCentral_CFDI_Búsqueda/RFCTercero | H44: Rol CFDI01 Rol CFDI02 Rol CFDI03 Rol CFDI04 Rol CFDI05 | J44: {=LEN(F44:G44)} -> 223 | K44: 225 | L44: =+J44+K44 -> 448
A45: POL_8214 /PortalEmpleado/ConsultaCentralCFDI | D45: 2 | E45: Da clic en cerrar sesión | F45: Cierra la aplicación y se direcciona a la pantalla de autenticación. | J45: {=LEN(F45:G45)} -> 68 | K45: 0 | L45: =+J45+K45 -> 68
B46: CP06 | C46: Busqueda/Masiva UUID | J46: {=LEN(F46:G46)} -> 0 | K46: 0 | L46: =+J46+K46 -> 0
A47: POL_8214 /PortalEmpleado/ConsultaCentralCFDI | D47: 1 | E47: Usuario ingresa al Portal Empleados Consulta Central | F47: El sistema muestra las siguientes opciones de búsqueda: - Folio Fiscal - Masiva UUID - Fecha Inicial y Final de Emisión | G47: El Usuario previamente se autenticó y accedió al portal Empleados-Consulta Central | H47: Rol CFDI01 Rol CFDI02 Rol CFDI03 Rol CFDI04 Rol CFDI05 | I47: Firma Electrónica del Usuario. El Usuario debe tener asignado cualquiera de los roles Archivo con UUID correctos | J47: {=LEN(F47:G47)} -> 120 | K47: 83 | L47: =+J47+K47 -> 203
A48: POL_8214 /PortalEmpleado/ConsultaCentralCFDI | D48: 2 | E48: Selecciona la opción Masiva UUID | F48: El sistema muestra las siguientes opciones de búsqueda: - *Seleccionar Archivo Botón Enviar | G48: En caso de no seleccionar un archivo El sistema muestra el siguiente mensaje: "Debe seleccionar un archivo .txt que contenga información para continuar." | J48: {=LEN(F48:G48)} -> 91 | K48: 154 | L48: =+J48+K48 -> 245
A49: POL_8214 /PortalEmpleado/ConsultaCentralCFDI | D49: 3 | E49: Selecciona el archivo(txt) mediante el explorador de Windows. | F49: El aplicativo ejecuta la consulta y arroja el resultado conforme a los UUID definidos en el archivo. | G49: Archivo TXT con distintos UUID | J49: {=LEN(F49:G49)} -> 104 | K49: 30 | L49: =+J49+K49 -> 134
A50: POL_8214 /PortalEmpleado/ConsultaCentralCFDI | D50: 4 | E50: Da clic en el botón Enviar | F50: El sistema realiza la petición y si contiene folios correctos los muestra en la sección de resultados: A. Casilla Acciones 1) Seleccionar. 2) Descargar 3) Recuperar Representacion Impresa. 4) Recuperar Representacion Impresa Carta Porte B. Datos de la Metadata del CFDI. • Folio Fiscal • RFC Emisor • Nombre o Razón Social del Emisor • RFC Receptor • Nombre o Razón Social del Receptor • Fecha de Emisión • Fecha de Certificación • Subtotal • Total • Estado del Comprobante • Efecto del Comprobante • Fecha de Cancelación • PAC que Certificó • Estatus de Cancelación • Estatus de Proceso de Cancelación • Fecha de Solicitud de la cancelación • Motivo • Folio de sustitución • RFC a cuenta de terceros C. Botones: Para la consulta Masiva UUID cuando el resultado contiene mas de un folio fiscal se mostrarán los botones: 1) Descargar seleccionados XML 2) Exportar resultados a PDF 3) Exportar resultados a CSV Cuando el resultado solo contiene un resultado se mostrarán los botones: 1. Exportar resultados a PDF 2. Exportar resultados a CSV | G50: • La consulta masiva esta limitada a 1,000 registros de UUID. • El servicio solo permite la consulta a través de archivos de texto plano (.txt) • Si el sistema no encuentra folios válidos ver el caso de prueba CP28 | J50: {=LEN(F50:G50)} -> 1046 | K50: 218 | L50: =+J50+K50 -> 1264
A51: POL_8214 /PortalEmpleado/ConsultaCentralCFDI | D51: 5 | E51: Da clic en Cerrar Sesión | F51: Cierra la aplicación y se direcciona a la pantalla de autenticación. | J51: {=LEN(F51:G51)} -> 68 | K51: 0 | L51: =+J51+K51 -> 68
...

Sheet Devops
C19: Test Case | D19: =IF('Casos de Prueba'!B19<>0,'Casos de Prueba'!B19&"-"&_xlfn.SINGLE('Casos de Prueba'!C19),"") -> CP01-Busqueda/Folio Fiscal | E19: =IF(LEN($D19)>0,"",'Casos de Prueba'!D19) | F19: =IF(LEN($C19)>0,"",'Casos de Prueba'!E19) | G19: =IF(LEN($C19)>0,"",'Casos de Prueba'!F19) | H19: =IF(LEN($C19)>0,"",'Casos de Prueba'!G19&CHAR(10)&'Casos de Prueba'!H19)
D20: =IF('Casos de Prueba'!B20<>0,'Casos de Prueba'!B20&"-"&_xlfn.SINGLE('Casos de Prueba'!C20),"") | E20: =IF(LEN($C20)>0,"",'Casos de Prueba'!D20) -> 1 | F20: =IF(LEN($C20)>0,"",'Casos de Prueba'!E20) -> Usuario ingresa al Portal Empleados Consulta Central | G20: =IF(LEN($C20)>0,"",'Casos de Prueba'!F20&CHAR(10)&'Casos de Prueba'!G20) -> El sistema muestra las siguientes opciones de búsqueda: - Folio Fiscal - Masiva UUID - Fecha Inicial y Final de Emisión El Usuario previamente se autenticó y accedió al portal Empleados-Consulta Central | H20: =+LEN(G20) -> 204
D21: =IF('Casos de Prueba'!B21<>0,'Casos de Prueba'!B21&"-"&_xlfn.SINGLE('Casos de Prueba'!C21),"") | E21: =IF(LEN($D21)>0,"",'Casos de Prueba'!D21) -> 2 | F21: =IF(LEN($C21)>0,"",'Casos de Prueba'!E21) -> Selecciona la opción Folio Fiscal | G21: =IF(LEN($C21)>0,"",'Casos de Prueba'!F21&CHAR(10)&'Casos de Prueba'!G21) -> El sistema muestra cuadro de texto para incorporar el número de Folio Fiscal que se requiere buscar. Al seleccionar el botón de folio fiscal se deben deshabilitar los campos de la sección Fecha Inicial y Final de Emisión (Aplica la Regla de Negocio 01) | H21: =+LEN(G21) -> 254
D22: =IF('Casos de Prueba'!B22<>0,'Casos de Prueba'!B22&"-"&_xlfn.SINGLE('Casos de Prueba'!C22),"") | E22: =IF(LEN($D22)>0,"",'Casos de Prueba'!D22) -> 3 | F22: =IF(LEN($C22)>0,"",'Casos de Prueba'!E22) -> Ingresa los datos del Folio Fiscal | G22: =IF(LEN($C22)>0,"",'Casos de Prueba'!F22&CHAR(10)&'Casos de Prueba'!G22) -> El sistema muestra los datos que se van ingresando del folio fiscal | H22: =+LEN(G22) -> 69
D23: =IF('Casos de Prueba'!B23<>0,'Casos de Prueba'!B23&"-"&_xlfn.SINGLE('Casos de Prueba'!C23),"") | E23: =IF(LEN($D23)>0,"",'Casos de Prueba'!D23) -> 4 | F23: =IF(LEN($C23)>0,"",'Casos de Prueba'!E23) -> Da clic en el botón buscar CFDI | G23: =IF(LEN($C23)>0,"",'Casos de Prueba'!F23&CHAR(10)&'Casos de Prueba'!G23) -> Si la petición es correcta, el sistema muestra: A. Casilla Acciones 1) Seleccionar. 2) Descargar. 3) Recuperar Representación Impresa. 4) Recuperar Representacion Impresa Carta Porte. B. Datos de la Metadata del CFDI. • Folio Fiscal • RFC Emisor • Nombre o Razón Social del Emisor • RFC Receptor • Nombre o Razón Social del Receptor • Fecha de Emisión • Fecha de Certificación • Subtotal • Total • Estado del Comprobante • Efecto del Comprobante • Fecha de Cancelación • PAC que Certificó • Estatus de Cancelación • Estatus de Proceso de Cancelación • Fecha de Solicitud de la cancelación • Motivo • Folio de sustitución • RFC a cuenta de terceros C. Botones: 1) Descargar Metadata. 2) Exportar Resultados a PDF. 3) Exportar Resultados a CSV. El aplicativo debe realizar la búsqueda de todas las versiones del CFDI (3.2, 3.3 y 4.0), de acuerdo a los criterios de búsqueda seleccionados previamente. En caso de no encontrar información ir al Caso de Prueba "Sin Resultados" En una consulta por Folio fiscal o cuando se realice la c onsulta por periodo de fecha y el resultado sea uno: (Aplica la Regla de Negocio 15) *Descargar metadata *Exportar Resultados a PDF *Exportar Resultados a CSV | H23: =+LEN(G23) -> 1201
D24: =IF('Casos de Prueba'!B24<>0,'Casos de Prueba'!B24&"-"&_xlfn.SINGLE('Casos de Prueba'!C24),"") | E24: =IF(LEN($D24)>0,"",'Casos de Prueba'!D24) -> 5 | F24: =IF(LEN($C24)>0,"",'Casos de Prueba'!E24) -> Da clic en cerrar sesión | G24: =IF(LEN($C24)>0,"",'Casos de Prueba'!F24&CHAR(10)&'Casos de Prueba'!G24) -> Cierra la aplicación y se direcciona a la pantalla de autenticación. | H24: =+LEN(G24) -> 69
D25: =IF('Casos de Prueba'!B25<>0,'Casos de Prueba'!B25&"-"&_xlfn.SINGLE('Casos de Prueba'!C25),"") -> CP02-Busqueda/RFC Emisor | E25: =IF(LEN($D25)>0,"",'Casos de Prueba'!D25) | G25: =IF(LEN($C25)>0,"",'Casos de Prueba'!F25&CHAR(10)&'Casos de Prueba'!G25) | H25: =+LEN(G25) -> 1
D26: =IF('Casos de Prueba'!B26<>0,'Casos de Prueba'!B26&"-"&_xlfn.SINGLE('Casos de Prueba'!C26),"") | E26: =IF(LEN($D26)>0,"",'Casos de Prueba'!D26) -> 1 | F26: =IF(LEN($C26)>0,"",'Casos de Prueba'!E26) -> Usuario ingresa al Portal Empleados Consulta Central | G26: =IF(LEN($C26)>0,"",'Casos de Prueba'!F26&CHAR(10)&'Casos de Prueba'!G26) -> El sistema muestra las siguientes opciones de búsqueda: - Folio Fiscal - Masiva UUID - Fecha Inicial y Final de Emisión El Usuario previamente se autenticó y accedió al portal Empleados-Consulta Central | H26: =+LEN(G26) -> 204
D27: =IF('Casos de Prueba'!B27<>0,'Casos de Prueba'!B27&"-"&_xlfn.SINGLE('Casos de Prueba'!C27),"") | E27: =IF(LEN($D27)>0,"",'Casos de Prueba'!D27) -> 2 | F27: =IF(LEN($C27)>0,"",'Casos de Prueba'!E27) -> Selecciona la opción Fecha Inicial y Final de Emisión | G27: =IF(LEN($C27)>0,"",'Casos de Prueba'!F27&CHAR(10)&'Casos de Prueba'!G27) -> El sistema habilita los siguientes campos: • Fecha Inicial de Emisión (*). • Fecha Final de Emisión (*). • RFC Emisor. • RFC Receptor. • RFC a cuenta terceros. • Tipo de Comprobante. • Estado del Comprobante. • Tipo de Comprobante (Complemento) (RN17). • Estatus Cancelación (Campo condicional). | H27: =+LEN(G27) -> 296
D28: =IF('Casos de Prueba'!B28<>0,'Casos de Prueba'!B28&"-"&_xlfn.SINGLE('Casos de Prueba'!C28),"") | E28: =IF(LEN($D28)>0,"",'Casos de Prueba'!D28) -> 3 | F28: =IF(LEN($C28)>0,"",'Casos de Prueba'!E28) -> Ingresa los datos: • Fecha Inicial de Emisión (*). • Fecha Final de Emisión (*). • RFC Emisor. • RFC Receptor. • RFC a cuenta de terceros. • Tipo de Comprobante. • Estado del Comprobante. • Tipo de Comprobante (Complemento) (RN17). • Estatus Cancelación (Campo condicional). Campo obligarorio (*) Nota: Para realizar la búsqueda se debe proporcionar al menos un RFC como parámetro de búsqueda(RFC Emisor, RFC Receptor o RFC a cuenta terceros | G28: =IF(LEN($C28)>0,"",'Casos de Prueba'!F28&CHAR(10)&'Casos de Prueba'!G28) -> El sistema muestra los datos que se van ingresando . | H28: =+LEN(G28) -> 53
D29: =IF('Casos de Prueba'!B29<>0,'Casos de Prueba'!B29&"-"&_xlfn.SINGLE('Casos de Prueba'!C29),"") | E29: =IF(LEN($D29)>0,"",'Casos de Prueba'!D29) -> 4 | F29: =IF(LEN($C29)>0,"",'Casos de Prueba'!E29) -> Da clic en el botón buscar CFDI | G29: =IF(LEN($C29)>0,"",'Casos de Prueba'!F29&CHAR(10)&'Casos de Prueba'!G29) -> Si la petición es correcta, el sistema muestra: A. Casilla Acciones 1) Seleccionar. 2) Descargar 3) Recuperar Representacion Impresa. 4) Recuperar Representacion Impresa Carta Porte. B. Datos de la Metadata del CFDI. • Folio Fiscal • RFC Emisor • Nombre o Razón Social del Emisor • RFC Receptor • Nombre o Razón Social del Receptor • Fecha de Emisión • Fecha de Certificación • Subtotal • Total • Estado del Comprobante • Efecto del Comprobante • Fecha de Cancelación • PAC que Certificó • Estatus de Cancelación • Estatus de Proceso de Cancelación • Fecha de Solicitud de la cancelación • Motivo • Folio de sustitución • RFC a cuenta de terceros C. Botones: 1) Descargar Seleccionados XML. 2) Descargas RI. 3) Descargar Metadata. 4) Exportar Resultados a PDF. 5) Exportar Resultados a CSV. D. Paginador. En una consulta por Folio fiscal o cuando se realice la c onsulta por periodo de fecha y el resultado sea uno: (Aplica la Regla de Negocio 15) *Descargar metadata *Exportar Resultados a PDF *Exportar Resultados a CSV | H29: =+LEN(G29) -> 1031
D30: =IF('Casos de Prueba'!B30<>0,'Casos de Prueba'!B30&"-"&_xlfn.SINGLE('Casos de Prueba'!C30),"") | E30: =IF(LEN($D30)>0,"",'Casos de Prueba'!D30) -> 5 | F30: =IF(LEN($C30)>0,"",'Casos de Prueba'!E30) -> Da clic en cerrar sesión | G30: =IF(LEN($C30)>0,"",'Casos de Prueba'!F30&CHAR(10)&'Casos de Prueba'!G30) -> Cierra la aplicación y se direcciona a la pantalla de autenticación. | H30: =+LEN(G30) -> 69
D31: =IF('Casos de Prueba'!B31<>0,'Casos de Prueba'!B31&"-"&_xlfn.SINGLE('Casos de Prueba'!C31),"") -> CP03-Busqueda/RFC Receptor | E31: =IF(LEN($D31)>0,"",'Casos de Prueba'!D31) | G31: =IF(LEN($C31)>0,"",'Casos de Prueba'!F31&CHAR(10)&'Casos de Prueba'!G31) | H31: =+LEN(G31) -> 1
D32: =IF('Casos de Prueba'!B32<>0,'Casos de Prueba'!B32&"-"&_xlfn.SINGLE('Casos de Prueba'!C32),"") | E32: =IF(LEN($D32)>0,"",'Casos de Prueba'!D32) -> 1 | F32: =IF(LEN($C32)>0,"",'Casos de Prueba'!E32) -> Usuario ingresa al Portal Empleados Consulta Central | G32: =IF(LEN($C32)>0,"",'Casos de Prueba'!F32&CHAR(10)&'Casos de Prueba'!G32) -> El sistema muestra las siguientes opciones de búsqueda: - Folio Fiscal - Masiva UUID - Fecha Inicial y Final de Emisión El Usuario previamente se autenticó y accedió al portal Empleados-Consulta Central | H32: =+LEN(G32) -> 204
D33: =IF('Casos de Prueba'!B33<>0,'Casos de Prueba'!B33&"-"&_xlfn.SINGLE('Casos de Prueba'!C33),"") | E33: =IF(LEN($D33)>0,"",'Casos de Prueba'!D33) -> 2 | F33: =IF(LEN($C33)>0,"",'Casos de Prueba'!E33) -> Selecciona la opción Fecha Inicial y Final de Emisión | G33: =IF(LEN($C33)>0,"",'Casos de Prueba'!F33&CHAR(10)&'Casos de Prueba'!G33) -> El sistema habilita los siguientes campos: • Fecha Inicial de Emisión (*). • Fecha Final de Emisión (*). • RFC Emisor. • RFC Receptor. • RFC a cuenta de terceros. • Tipo de Comprobante. • Estado del Comprobante. • Tipo de Comprobante (Complemento) (RN17). • Estatus Cancelación (Campo condicional). | H33: =+LEN(G33) -> 299
D34: =IF('Casos de Prueba'!B34<>0,'Casos de Prueba'!B34&"-"&_xlfn.SINGLE('Casos de Prueba'!C34),"") | E34: =IF(LEN($D34)>0,"",'Casos de Prueba'!D34) -> 3 | F34: =IF(LEN($C34)>0,"",'Casos de Prueba'!E34) -> Ingresa los datos: • Fecha Inicial de Emisión (*). • Fecha Final de Emisión (*). • RFC Emisor. • RFC Receptor. • RFC a cuenta de terceros. • Tipo de Comprobante. • Estado del Comprobante. • Tipo de Comprobante (Complemento) (RN17). • Estatus Cancelación (Campo condicional). Campo obligarorio (*) Nota: Para realizar la búsqueda se debe proporcionar al menos un RFC como parámetro de búsqueda(RFC Emisor, RFC Receptor o RFC a cuenta terceros | G34: =IF(LEN($C34)>0,"",'Casos de Prueba'!F34&CHAR(10)&'Casos de Prueba'!G34) -> El sistema muestra los datos que se van ingresando . | H34: =+LEN(G34) -> 53
D35: =IF('Casos de Prueba'!B35<>0,'Casos de Prueba'!B35&"-"&_xlfn.SINGLE('Casos de Prueba'!C35),"") | E35: =IF(LEN($D35)>0,"",'Casos de Prueba'!D35) -> 4 | F35: =IF(LEN($C35)>0,"",'Casos de Prueba'!E35) -> Da clic en el botón buscar CFDI | G35: =IF(LEN($C35)>0,"",'Casos de Prueba'!F35&CHAR(10)&'Casos de Prueba'!G35) -> Si la petición es correcta, el sistema muestra: A. Casilla Acciones 1) Seleccionar. 2) Descargar 3) Recuperar Representacion Impresa. 4) Recuperar Representacion Impresa Carta Porte. B. Datos de la Metadata del CFDI. • Folio Fiscal • RFC Emisor • Nombre o Razón Social del Emisor • RFC Receptor • Nombre o Razón Social del Receptor • Fecha de Emisión • Fecha de Certificación • Subtotal • Total • Estado del Comprobante • Efecto del Comprobante • Fecha de Cancelación • PAC que Certificó • Estatus de Cancelación • Estatus de Proceso de Cancelación • Fecha de Solicitud de la cancelación • Motivo • Folio de sustitución • RFC a cuenta de terceros C. Botones: 1) Descargar Seleccionados XML. 2) Descargas RI. 3) Descargar Metadata. 4) Exportar Resultados a PDF. 5) Exportar Resultados a CSV. D. Paginador. En una consulta por Folio fiscal o cuando se realice la c onsulta por periodo de fecha y el resultado sea uno: (Aplica la Regla de Negocio 15) *Descargar metadata *Exportar Resultados a PDF *Exportar Resultados a CSV | H35: =+LEN(G35) -> 1031
D36: =IF('Casos de Prueba'!B36<>0,'Casos de Prueba'!B36&"-"&_xlfn.SINGLE('Casos de Prueba'!C36),"") | E36: =IF(LEN($D36)>0,"",'Casos de Prueba'!D36) -> 5 | F36: =IF(LEN($C36)>0,"",'Casos de Prueba'!E36) -> Da clic en cerrar sesión | G36: =IF(LEN($C36)>0,"",'Casos de Prueba'!F36&CHAR(10)&'Casos de Prueba'!G36) -> Cierra la aplicación y se direcciona a la pantalla de autenticación. | H36: =+LEN(G36) -> 69
D37: =IF('Casos de Prueba'!B37<>0,'Casos de Prueba'!B37&"-"&_xlfn.SINGLE('Casos de Prueba'!C37),"") -> CP04-Busqueda/RFC Tercero | E37: =IF(LEN($D37)>0,"",'Casos de Prueba'!D37) | G37: =IF(LEN($C37)>0,"",'Casos de Prueba'!F37&CHAR(10)&'Casos de Prueba'!G37) | H37: =+LEN(G37) -> 1
D38: =IF('Casos de Prueba'!B38<>0,'Casos de Prueba'!B38&"-"&_xlfn.SINGLE('Casos de Prueba'!C38),"") | E38: =IF(LEN($D38)>0,"",'Casos de Prueba'!D38) -> 1 | F38: =IF(LEN($C38)>0,"",'Casos de Prueba'!E38) -> Usuario ingresa al Portal Empleados Consulta Central | G38: =IF(LEN($C38)>0,"",'Casos de Prueba'!F38&CHAR(10)&'Casos de Prueba'!G38) -> El sistema muestra las siguientes opciones de búsqueda: - Folio Fiscal - Masiva UUID - Fecha Inicial y Final de Emisión El Usuario previamente se autenticó y accedió al portal Empleados-Consulta Central | H38: =+LEN(G38) -> 204
D39: =IF('Casos de Prueba'!B39<>0,'Casos de Prueba'!B39&"-"&_xlfn.SINGLE('Casos de Prueba'!C39),"") | E39: =IF(LEN($D39)>0,"",'Casos de Prueba'!D39) -> 2 | F39: =IF(LEN($C39)>0,"",'Casos de Prueba'!E39) -> Selecciona la opción Fecha Inicial y Final de Emisión | G39: =IF(LEN($C39)>0,"",'Casos de Prueba'!F39&CHAR(10)&'Casos de Prueba'!G39) -> El sistema habilita los siguientes campos: • Fecha Inicial de Emisión (*). • Fecha Final de Emisión (*). • RFC Emisor. • RFC Receptor. • RFC a cuenta de terceros. • Tipo de Comprobante. • Estado del Comprobante. • Tipo de Comprobante (Complemento) (RN17). • Estatus Cancelación (Campo condicional). | H39: =+LEN(G39) -> 299
D40: =IF('Casos de Prueba'!B40<>0,'Casos de Prueba'!B40&"-"&_xlfn.SINGLE('Casos de Prueba'!C40),"") | E40: =IF(LEN($D40)>0,"",'Casos de Prueba'!D40) -> 3 | F40: =IF(LEN($C40)>0,"",'Casos de Prueba'!E40) -> Ingresa los datos: • Fecha Inicial de Emisión (*). • Fecha Final de Emisión (*). • RFC Emisor. • RFC Receptor. • RFC a cuenta de terceros. • Tipo de Comprobante. • Estado del Comprobante. • Tipo de Comprobante (Complemento) (RN17). • Estatus Cancelación (Campo condicional). Campo obligarorio (*) Nota: Para realizar la búsqueda se debe proporcionar al menos un RFC como parámetro de búsqueda(RFC Emisor, RFC Receptor o RFC a cuenta terceros | G40: =IF(LEN($C40)>0,"",'Casos de Prueba'!F40&CHAR(10)&'Casos de Prueba'!G40) -> El sistema muestra los datos que se van ingresando . | H40: =+LEN(G40) -> 53
D41: =IF('Casos de Prueba'!B41<>0,'Casos de Prueba'!B41&"-"&_xlfn.SINGLE('Casos de Prueba'!C41),"") | E41: =IF(LEN($D41)>0,"",'Casos de Prueba'!D41) -> 4 | F41: =IF(LEN($C41)>0,"",'Casos de Prueba'!E41) -> Da clic en el botón buscar CFDI | G41: =IF(LEN($C41)>0,"",'Casos de Prueba'!F41&CHAR(10)&'Casos de Prueba'!G41) -> Si la petición es correcta, el sistema muestra: A. Casilla Acciones 1) Seleccionar. 2) Descargar 3) Recuperar Representacion Impresa. 4) Recuperar Representacion Impresa Carta Porte. B. Datos de la Metadata del CFDI. • Folio Fiscal • RFC Emisor • Nombre o Razón Social del Emisor • RFC Receptor • Nombre o Razón Social del Receptor • Fecha de Emisión • Fecha de Certificación • Subtotal • Total • Estado del Comprobante • Efecto del Comprobante • Fecha de Cancelación • PAC que Certificó • Estatus de Cancelación • Estatus de Proceso de Cancelación • Fecha de Solicitud de la cancelación • Motivo • Folio de sustitución • RFC a cuenta de terceros C. Botones: 1) Descargar Seleccionados XML. 2) Descargas RI. 3) Descargar Metadata. 4) Exportar Resultados a PDF. 5) Exportar Resultados a CSV. D. Paginador. En una consulta por Folio fiscal o cuando se realice la c onsulta por periodo de fecha y el resultado sea uno: (Aplica la Regla de Negocio 15) *Descargar metadata *Exportar Resultados a PDF *Exportar Resultados a CSV | H41: =+LEN(G41) -> 1031
D42: =IF('Casos de Prueba'!B42<>0,'Casos de Prueba'!B42&"-"&_xlfn.SINGLE('Casos de Prueba'!C42),"") | E42: =IF(LEN($D42)>0,"",'Casos de Prueba'!D42) -> 5 | F42: =IF(LEN($C42)>0,"",'Casos de Prueba'!E42) -> Da clic en cerrar sesión | G42: =IF(LEN($C42)>0,"",'Casos de Prueba'!F42&CHAR(10)&'Casos de Prueba'!G42) -> Cierra la aplicación y se direcciona a la pantalla de autenticación. | H42: =+LEN(G42) -> 69
D43: =IF('Casos de Prueba'!B43<>0,'Casos de Prueba'!B43&"-"&_xlfn.SINGLE('Casos de Prueba'!C43),"") -> CP05-Sin Resultados | E43: =IF(LEN($D43)>0,"",'Casos de Prueba'!D43) | G43: =IF(LEN($C43)>0,"",'Casos de Prueba'!F43&CHAR(10)&'Casos de Prueba'!G43) | H43: =+LEN(G43) -> 1
D44: =IF('Casos de Prueba'!B44<>0,'Casos de Prueba'!B44&"-"&_xlfn.SINGLE('Casos de Prueba'!C44),"") | E44: =IF(LEN($D44)>0,"",'Casos de Prueba'!D44) -> 1 | F44: =IF(LEN($C44)>0,"",'Casos de Prueba'!E44) -> Da clic en el botón buscar | G44: =IF(LEN($C44)>0,"",'Casos de Prueba'!F44&CHAR(10)&'Casos de Prueba'!G44) -> En caso de que no se encuentre información con los parámetros de búsqueda ingresados, el sistema muestra el siguiente mensaje: “No existen registros que cumplan con los criterios de búsqueda ingresados, intentar nuevamente” Viene de los Casos de Prueba: - CP01_ConsultaCentral_CFDI_Búsqueda/Folio Fiscal - CP02_ConsultaCentral_CFDI_Búsqueda/RFCEmisor - CP03_ConsultaCentral_CFDI_Búsqueda/RFCReceptor - CP04_ConsultaCentral_CFDI_Búsqueda/RFCTercero | H44: =+LEN(G44) -> 449
D45: =IF('Casos de Prueba'!B45<>0,'Casos de Prueba'!B45&"-"&_xlfn.SINGLE('Casos de Prueba'!C45),"") | E45: =IF(LEN($D45)>0,"",'Casos de Prueba'!D45) -> 2 | F45: =IF(LEN($C45)>0,"",'Casos de Prueba'!E45) -> Da clic en cerrar sesión | G45: =IF(LEN($C45)>0,"",'Casos de Prueba'!F45&CHAR(10)&'Casos de Prueba'!G45) -> Cierra la aplicación y se direcciona a la pantalla de autenticación. | H45: =+LEN(G45) -> 69
D46: =IF('Casos de Prueba'!B46<>0,'Casos de Prueba'!B46&"-"&_xlfn.SINGLE('Casos de Prueba'!C46),"") -> CP06-Busqueda/Masiva UUID | E46: =IF(LEN($D46)>0,"",'Casos de Prueba'!D46) | G46: =IF(LEN($C46)>0,"",'Casos de Prueba'!F46&CHAR(10)&'Casos de Prueba'!G46) | H46: =+LEN(G46) -> 1
D47: =IF('Casos de Prueba'!B47<>0,'Casos de Prueba'!B47&"-"&_xlfn.SINGLE('Casos de Prueba'!C47),"") | E47: =IF(LEN($D47)>0,"",'Casos de Prueba'!D47) -> 1 | F47: =IF(LEN($C47)>0,"",'Casos de Prueba'!E47) -> Usuario ingresa al Portal Empleados Consulta Central | G47: =IF(LEN($C47)>0,"",'Casos de Prueba'!F47&CHAR(10)&'Casos de Prueba'!G47) -> El sistema muestra las siguientes opciones de búsqueda: - Folio Fiscal - Masiva UUID - Fecha Inicial y Final de Emisión El Usuario previamente se autenticó y accedió al portal Empleados-Consulta Central | H47: =+LEN(G47) -> 204
D48: =IF('Casos de Prueba'!B48<>0,'Casos de Prueba'!B48&"-"&_xlfn.SINGLE('Casos de Prueba'!C48),"") | E48: =IF(LEN($D48)>0,"",'Casos de Prueba'!D48) -> 2 | F48: =IF(LEN($C48)>0,"",'Casos de Prueba'!E48) -> Selecciona la opción Masiva UUID | G48: =IF(LEN($C48)>0,"",'Casos de Prueba'!F48&CHAR(10)&'Casos de Prueba'!G48) -> El sistema muestra las siguientes opciones de búsqueda: - *Seleccionar Archivo Botón Enviar En caso de no seleccionar un archivo El sistema muestra el siguiente mensaje: "Debe seleccionar un archivo .txt que contenga información para continuar." | H48: =+LEN(G48) -> 246
D49: =IF('Casos de Prueba'!B49<>0,'Casos de Prueba'!B49&"-"&_xlfn.SINGLE('Casos de Prueba'!C49),"") | E49: =IF(LEN($D49)>0,"",'Casos de Prueba'!D49) -> 3 | F49: =IF(LEN($C49)>0,"",'Casos de Prueba'!E49) -> Selecciona el archivo(txt) mediante el explorador de Windows. | G49: =IF(LEN($C49)>0,"",'Casos de Prueba'!F49&CHAR(10)&'Casos de Prueba'!G49) -> El aplicativo ejecuta la consulta y arroja el resultado conforme a los UUID definidos en el archivo. Archivo TXT con distintos UUID | H49: =+LEN(G49) -> 135
D50: =IF('Casos de Prueba'!B50<>0,'Casos de Prueba'!B50&"-"&_xlfn.SINGLE('Casos de Prueba'!C50),"") | E50: =IF(LEN($D50)>0,"",'Casos de Prueba'!D50) -> 4 | F50: =IF(LEN($C50)>0,"",'Casos de Prueba'!E50) -> Da clic en el botón Enviar | G50: =IF(LEN($C50)>0,"",'Casos de Prueba'!F50&CHAR(10)&'Casos de Prueba'!G50) -> El sistema realiza la petición y si contiene folios correctos los muestra en la sección de resultados: A. Casilla Acciones 1) Seleccionar. 2) Descargar 3) Recuperar Representacion Impresa. 4) Recuperar Representacion Impresa Carta Porte B. Datos de la Metadata del CFDI. • Folio Fiscal • RFC Emisor • Nombre o Razón Social del Emisor • RFC Receptor • Nombre o Razón Social del Receptor • Fecha de Emisión • Fecha de Certificación • Subtotal • Total • Estado del Comprobante • Efecto del Comprobante • Fecha de Cancelación • PAC que Certificó • Estatus de Cancelación • Estatus de Proceso de Cancelación • Fecha de Solicitud de la cancelación • Motivo • Folio de sustitución • RFC a cuenta de terceros C. Botones: Para la consulta Masiva UUID cuando el resultado contiene mas de un folio fiscal se mostrarán los botones: 1) Descargar seleccionados XML 2) Exportar resultados a PDF 3) Exportar resultados a CSV Cuando el resultado solo contiene un resultado se mostrarán los botones: 1. Exportar resultados a PDF 2. Exportar resultados a CSV • La consulta masiva esta limitada a 1,000 registros de UUID. • El servicio solo permite la consulta a través de archivos de texto plano (.txt) • Si el sistema no encuentra folios válidos ver el caso de prueba CP28 | H50: =+LEN(G50) -> 1265
D51: =IF('Casos de Prueba'!B51<>0,'Casos de Prueba'!B51&"-"&_xlfn.SINGLE('Casos de Prueba'!C51),"") | E51: =IF(LEN($D51)>0,"",'Casos de Prueba'!D51) -> 5 | F51: =IF(LEN($C51)>0,"",'Casos de Prueba'!E51) -> Da clic en Cerrar Sesión | G51: =IF(LEN($C51)>0,"",'Casos de Prueba'!F51&CHAR(10)&'Casos de Prueba'!G51) -> Cierra la aplicación y se direcciona a la pantalla de autenticación. | H51: =+LEN(G51) -> 69
D52: =IF('Casos de Prueba'!B52<>0,'Casos de Prueba'!B52&"-"&_xlfn.SINGLE('Casos de Prueba'!C52),"") -> CP07-Folio Fiscal/Acuse de cancelación | E52: =IF(LEN($D52)>0,"",'Casos de Prueba'!D52) | G52: =IF(LEN($C52)>0,"",'Casos de Prueba'!F52&CHAR(10)&'Casos de Prueba'!G52) | H52: =+LEN(G52) -> 1
D53: =IF('Casos de Prueba'!B53<>0,'Casos de Prueba'!B53&"-"&_xlfn.SINGLE('Casos de Prueba'!C53),"") | E53: =IF(LEN($D53)>0,"",'Casos de Prueba'!D53) -> 1 | F53: =IF(LEN($C53)>0,"",'Casos de Prueba'!E53) -> Usuario ingresa al Portal Empleados Consulta Central | G53: =IF(LEN($C53)>0,"",'Casos de Prueba'!F53&CHAR(10)&'Casos de Prueba'!G53) -> El sistema muestra las siguientes opciones de búsqueda: - Folio Fiscal - Masiva UUID - Fecha Inicial y Final de Emisión El Usuario previamente se autenticó y accedió al portal Empleados-Consulta Central | H53: =+LEN(G53) -> 204
D54: =IF('Casos de Prueba'!B54<>0,'Casos de Prueba'!B54&"-"&_xlfn.SINGLE('Casos de Prueba'!C54),"") | E54: =IF(LEN($D54)>0,"",'Casos de Prueba'!D54) -> 2 | F54: =IF(LEN($C54)>0,"",'Casos de Prueba'!E54) -> Selecciona la opción Folio Fiscal | G54: =IF(LEN($C54)>0,"",'Casos de Prueba'!F54&CHAR(10)&'Casos de Prueba'!G54) -> El sistema muestra cuadro de texto para incorporar el número de Folio Fiscal que se requiere buscar. Al seleccionar el botón de folio fiscal se deben deshabilitar los campos de la sección Fecha Inicial y Final de Emisión (Aplica la Regla de Negocio 01) | H54: =+LEN(G54) -> 254
D55: =IF('Casos de Prueba'!B55<>0,'Casos de Prueba'!B55&"-"&_xlfn.SINGLE('Casos de Prueba'!C55),"") | E55: =IF(LEN($D55)>0,"",'Casos de Prueba'!D55) -> 3 | F55: =IF(LEN($C55)>0,"",'Casos de Prueba'!E55) -> Ingresa los datos del Folio Fiscal | G55: =IF(LEN($C55)>0,"",'Casos de Prueba'!F55&CHAR(10)&'Casos de Prueba'!G55) -> El sistema muestra los datos que se van ingresando del folio fiscal | H55: =+LEN(G55) -> 69
D56: =IF('Casos de Prueba'!B56<>0,'Casos de Prueba'!B56&"-"&_xlfn.SINGLE('Casos de Prueba'!C56),"") | E56: =IF(LEN($D56)>0,"",'Casos de Prueba'!D56) -> 4 | F56: =IF(LEN($C56)>0,"",'Casos de Prueba'!E56) -> Da clic en el botón buscar CFDI | G56: =IF(LEN($C56)>0,"",'Casos de Prueba'!F56&CHAR(10)&'Casos de Prueba'!G56) -> Si la petición es correcta, el sistema muestra: A. Casilla Acciones 1) Seleccionar. 2) Descargar. 3) Recuperar Representación Impresa. 4) Recuperar Representacion Impresa Carta Porte. B. Datos de la Metadata del CFDI. • Folio Fiscal • RFC Emisor • Nombre o Razón Social del Emisor • RFC Receptor • Nombre o Razón Social del Receptor • Fecha de Emisión • Fecha de Certificación • Subtotal • Total • Estado del Comprobante • Efecto del Comprobante • Fecha de Cancelación • PAC que Certificó • Estatus de Cancelación • Estatus de Proceso de Cancelación • Fecha de Solicitud de la cancelación • Motivo • Folio de sustitución • RFC a cuenta de terceros C. Botones: 1) Descargar Metadata. 2) Exportar Resultados a PDF. 3) Exportar Resultados a CSV. El aplicativo debe realizar la búsqueda de todas las versiones del CFDI (3.2, 3.3 y 4.0), de acuerdo a los criterios de búsqueda seleccionados previamente. En caso de no encontrar información ir al Caso de Prueba "Sin Resultados" En una consulta por Folio fiscal o cuando se realice la c onsulta por periodo de fecha y el resultado sea uno: (Aplica la Regla de Negocio 15) *Descargar metadata *Exportar Resultados a PDF *Exportar Resultados a CSV | H56: =+LEN(G56) -> 1201
D57: =IF('Casos de Prueba'!B57<>0,'Casos de Prueba'!B57&"-"&_xlfn.SINGLE('Casos de Prueba'!C57),"") | E57: =IF(LEN($D57)>0,"",'Casos de Prueba'!D57) -> 5 | F57: =IF(LEN($C57)>0,"",'Casos de Prueba'!E57) -> El usuario selecciona un folio fiscal (UUID) de la tabla “Resultados” y ubica la columna “Estado del Comprobante” que tenga el valor “Cancelado” y da clic en el hipervinculo para descargar el acuse de cancelación | G57: =IF(LEN($C57)>0,"",'Casos de Prueba'!F57&CHAR(10)&'Casos de Prueba'!G57) -> El sistema abre una ventana emergente y comienza con la descarga del acuse de cancelación en formato PDF. - Datos del Acuse de Cancelación de CFDI • Folio Fiscal • RFC Receptor • RFC Emisor • Estado CFDI • Estado Cancelación • Motivo Cancelación • Número de serie de la e.firma o CSD (RN21) • Fecha de Solicitud de Cancelación (RN19) • Mensaje de Error • Fecha • Sello digital SAT Esta opción solo será visible en la columna “Estado del Comprobante, cuando exista una solicitud de la cancelación asociada al CFDI. Se podrá realizar la descarga del acuse en formato PDF, recuperando el acuse con el estatus final. | H57: =+LEN(G57) -> 613
D58: =IF('Casos de Prueba'!B58<>0,'Casos de Prueba'!B58&"-"&_xlfn.SINGLE('Casos de Prueba'!C58),"") | E58: =IF(LEN($D58)>0,"",'Casos de Prueba'!D58) -> 6 | F58: =IF(LEN($C58)>0,"",'Casos de Prueba'!E58) -> Da clic en cerrar sesión | G58: =IF(LEN($C58)>0,"",'Casos de Prueba'!F58&CHAR(10)&'Casos de Prueba'!G58) -> Cierra la aplicación y se direcciona a la pantalla de autenticación. | H58: =+LEN(G58) -> 69
...

Sheet Devops_Carga
B1: Work Item type | C1: Title | D1: Step Action | E1: Step expected
C2: CP01-Busqueda/Folio Fiscal
D3: Usuario ingresa al Portal Empleados Consulta Central | E3: El sistema muestra las siguientes opciones de búsqueda: - Folio Fiscal - Masiva UUID - Fecha Inicial y Final de Emisión El Usuario previamente se autenticó y accedió al portal Empleados-Consulta Central
D4: Selecciona la opción Folio Fiscal | E4: El sistema muestra cuadro de texto para incorporar el número de Folio Fiscal que se requiere buscar. Al seleccionar el botón de folio fiscal se deben deshabilitar los campos de la sección Fecha Inicial y Final de Emisión (Aplica la Regla de Negocio 01)
D5: Ingresa los datos del Folio Fiscal | E5: El sistema muestra los datos que se van ingresando del folio fiscal
