Workbook
Name _Hlk170121364: 'Casos de Prueba'!$F$53
Name _Toc153985143: 'Firmas Conformidad'!#REF!
Name _Toc180680970: 'Firmas Conformidad'!$B$6

Sheet Instrucciones
B15: Objetivo: Identificar los insumos necesarios para pruebas de aceptación de usuario, a través de los casos de prueba, ambientes requeridos, especificación de los datos, cobertura de escenarios y atributos relacionados, a fin de contar con la integración de datos suficientes para la ejecución de las pruebas de la solución tecnológica con el usuario.
B17: Guía de Uso: 1.- Las pestañas "Casos de Prueba" y "Ambientes Requeridos" serán llenadas por la Administración Central de Soluciones de Negocio (ACSN), en la Fase Análisis, Etapa Especificación Funcional. 2.- Las pestañas "Interfaz de Usuario" y "Cobertura" serán llenadas en la Fase Desarrollo por las áreas técnicas que deban participar. En la primera también participará la ACSN en la Fase Pruebas, Etapa Pruebas Funcionales (AVL), por tema de Lineamientos Gráficos del SIAT, y para reflejar resultado de dichas pruebas. 3.- El documento está firmado por los responsables del llenado, incluyendo por el negocio cuando participa en la autorización. 4.- Si la pestaña "Casos de Prueba" incluye varias páginas, debe imprimirse sólo la página que contienen las firmas. Una vez firmado, debe digitalizarse y almacenarse en el repositorio como sustento junto con el archivo de Excel que corresponda a todo el documento. 5.- Si fuera necesario reservar información generada en esta plantilla, se hará bajo lo estipulado en la Ley General de Transparencia y Acceso a la Información Pública vigente (LGTAIP), pudiendo consultar a la ACPPI para su aplicación. (Ver abajo "Nota acerca de Información Reservada"). 6.- La aplicación de la sección de Firmas es opcional, dependiendo de las necesidades del consumidor, pero al contener temas de usuario de Negocio es importante la firma de éste.
B18: Nota acerca de Información Reservada Es responsabilidad de cada requisitador la identificación de la información que se genere en este formato y así determinar si se cuenta con causas que originen la reserva de la misma, apegándose estrictamente a lo señalado en los ordenamientos jurídicos vigentes en materia de Transparencia. En caso de detectar información sensible (Reservada), se tendrá que indicar en la sección u hoja que lo amerite de este documento, en la parte inferior del texto, con la siguiente señalización: [Área dueña de la Información XX, clasificada como Reservada con Fundamento Legal XX, Motivación XX, Fecha de clasificación XX y Periodo de la reserva XX]. Ejemplo: "La información contenida en este documento pertenece a la Administración Central de Soluciones de Negocio, teniendo carácter de Reservada a partir del 01 de abril de 2018, con un periodo de reserva de 5 años, por tratarse de información que de revelarse puede causar un serio perjuicio a la recaudación de las contribuciones. Lo anterior tiene su fundamento en el artículo 113, fracción IV, de la Ley General de Transparencia y Acceso a la Información Pública."
B20: Hoja | D20: Descripción
B21: Casos de Prueba | D21: Esta hoja se utiliza para la documentación detallada de los casos de pruebas que serán utilizados en la ejecución de pruebas.
D22: Registra varios casos de prueba, con la finalidad de agrupar en un solo documento una cantidad suficiente de casos que pueda ser aprovechada para la importación de casos de prueba en alguna herramienta automatizada, o bien, para obtener de ella la información de casos de prueba. También se utiliza para especificar los elementos donde se emplearán los datos (Datos de Prueba)
D23: Criterios de Aceptación
D24: • El documento es utilizado de acuerdo al formato establecido. El documento cumple con el Marco Documental vigente. • El documento no contiene faltas de ortografía. • Cuando no se llene un renglón-columna, se deberá especificar el motivo por el cual no se registra la información, conteniendo al menos un "N/A". Ningún campo debe estar vacío. ●No se combinan celdas (exceptuando la sección de firmas) ●No incluye fórmulas en ningún renglón-columna • El documento describe detalladamente paso a paso las actividades a seguir para la validación de requerimientos del sistema. • El documento describe en cada paso una acción y una respuesta esperada que puede ser evaluada. El documento está firmado por los responsables del llenado, incluyendo por el negocio cuando participa en la autorización.
B26: Hoja | D26: Descripción
B27: Ambientes Requeridos | D27: Registra elementos de información sobre repositorios y ambientes necesarios para las pruebas y sus características, relacionadas con criterios que debe cubrir la información que se requiere para las pruebas; cantidad de datos requeridos para la ejecución de la prueba; datos o campos solicitados; condiciones que se deben cubrir para la extracción de datos y comentarios adicionales.
D28: Criterios de Aceptación
D29: * El documento es utilizado de acuerdo al formato establecido. * El documento cumple con el Marco Documental vigente. * El documento no contiene faltas de ortografía. * Cuando no se llene un renglón-columna, se deberá especificar el motivo por el cual no se registra la información, conteniendo al menos un "N/A". Ningún campo debe estar vacío. * El documento está firmado por los responsables del llenado, incluyendo por el negocio cuando participa en la autorización.
B31: Hoja | D31: Descripción
B32: Interfaz de Usuario | D32: Esta hoja aplica por la naturaleza de la solución tecnológica integrada que haya sido requerida. Se utiliza para validar que se cumplan los criterios definidos para la Interfaz de Usuario, incluyendo la aplicación y verificación de los Lineamientos Gráficos del SIAT, cuando sea el caso.
D33: Se detallan los puntos a validar de interfaz de usuario (interfaz gráfica) de las aplicaciones, como encabezados, pie de página, colores, alineación, etiquetas, listas desplegables, áreas de búsqueda, etc, etc.
D34: Criterios de Aceptación
D35: • El documento es utilizado de acuerdo al formato establecido. • El documento no contiene faltas de ortografía. • Cuando no se llene un renglón-columna, se deberá especificar el motivo por el cual no se registra la información. • Cada una de las características consideradas en esta pestaña estarán asociadas al contenido del artefacto "Especificación de Interacción de Usuario", en caso de ajustes o situaciones que expongan desviación al documento en comento, deberá ajustarse. • Cada defecto detectado deberá registrarse en la herramienta correspondiente para su atención y cierre.
B37: Hoja | D37: Descripción
B38: Cobertura | D38: Esta hoja se utiliza para identificar y detallar la cobertura de la prueba basada en complejidad ciclomática, para asegurar que se diseñen tantos casos de prueba como sean necesarios para que cada condición se ejecute al menos una vez con un valor verdadero, y al menos una vez uno falso.
D40: Criterios de Aceptación
D41: • El documento es utilizado de acuerdo al formato establecido. • El documento no contiene faltas de ortografía. • Cuando no se llene un renglón-columna, se deberá especificar el motivo por el cual no se registra la información. • El documento describe detalladamente los escenarios de prueba necesarios para que cada condición se ejecute al menos una vez con un valor verdadero y al menos una vez uno falso.
B43: Hoja | D43: Descripción
B44: Encabezado_Imagen | D44: En artefactos tipo Excel, la inserción del Encabezado como imagen en el mismo documento, puede hacerse como una alternativa cuando por la naturaleza y cantidad de información registrada en él, se hace necesario ampliar significativamente el tamaño de las celdas, ocasionando con ello distorsión o inadecuada distribución de la estructura del Encabezado del artefacto. Si ese fuera el caso, en esta hoja puede configurarse el Encabezado del artefacto y después insertarlo como imagen en cualquier otra sección del mismo, siguiendo las instrucciones allí descritas.
B46: Hoja | D46: Descripción
B47: Firmas Conformidad_Imagen | D47: En artefactos tipo Excel, la inserción de la Sección FIRMAS DE CONFORMIDAD como imagen en el mismo documento, puede hacerse como una alternativa cuando por la naturaleza y cantidad de información registrada en él, se hace necesario ampliar significativamente el tamaño de las celdas, ocasionando con ello distorsión o inadecuada distribución de la estructura de la sección de firmas localizada en la parte inferior del artefacto. Si ese fuera el caso, en esta hoja puede capturarse la información de las personas que participan en la elaboración y aprobación del artefacto, y después insertarla como imagen en cualquier otra sección del documento, siguiendo los pasos que allí se describen.

Sheet Versionamiento
B12: Tabla de Versiones y Modificaciones
B13: En la tabla siguiente se deben listar las versiones y descripciones hechas a este documento, desde el momento de su creación y cada vez que se llene y/o actualice alguna de sus pestañas. La descripción debe incluir una síntesis del cambio hecho.
B14: Para la Versión, especificar un número entero consecutivo, iniciando con 1 para la creación del documento e incrementar en decimales conforme se actualice (1.1, 1.2, 1.3, Etc.). Al terminarlo, especificar la versión final para firma, en caso necesario.
B15: Para futuros proyectos donde este documento se reutilice, el versionamiento reiniciará en versión 2, incrementando las actualizaciones igualmente con decimales (2.1, 2.2, 2.3, etc.). Posteriores reutilizaciones iniciarían entonces con versión 3, 4, etc.
C18: Versión | D18: Descripción del Cambio | E18: Responsable de la Versión | F18: Fecha
C19: 0.1 | D19: Creación del documento. | E19: Alma Quetzabeth Torres González | F19: 45609
C20: 0.2 | D20: Ajuste: Aplicar CC104, CC116, CC117 | E20: Alma Quetzabeth Torres González | F20: 45609
C21: 1.0 | D21: Versión aprobada para firma | E21: Alma Quetzabeth Torres González Mario Alberto Huerta Velazquez Roberto Benjamín Monroy Vargas
C22: 1.1 | D22: Ajuste: -Se agrega prueba CP14, CP28 RI Complemento Carta Porte relacionado al CC121. -Se incorpora CP23, CP24. -Actualizar CP20 para incluir RN22 – Servicio de firmado en el proceso de cancelaciones. -Se actualiza númeración. -Ajustes CC120 - Actualizar Acuse y Solicitud de Cancelación | E22: Alma Quetzabeth Torres González | F22: 45825
C23: 1.2 | D23: Negocio comparte observaciones: • Se incorpora una funcionalidad cuando se “Da clic en el botón buscar CFDI” • Se elimina palabra “RESICO” • Se incorpora la palabra “Estatus de cancelación” • Se incorpora la palabra “Total de Impuestos retenidos” en la CP11 numeral 7 | E23: Mario Alberto Huerta Velazquez | F23: 45862
C24: 1.3 | D24: Ajustes: Se agrega CP36 y CP37 | E24: Alma Quetzabeth Torres González | F24: 45862
C25: 1.4 | D25: Ajustes: Se actualiza numeración y se agregan casos de prueba: CP10, CP12, CP14, CP16, CP18, CP20, CP22, CP24, CP27, CP29, CP31, CP35, CP37, CP39, CP41, CP43, CP45, CP47, CP50, CP52 | E25: Alma Quetzabeth Torres González | F25: 45866
C26: 1.5 | D26: Se revisan jbobservaciones | E26: Alma Quetzabeth Torres González | F26: 45922
C27: 2.0 | D27: Versión aprobada para firma | E27: Alma Quetzabeth Torres González Mario Alberto Huerta Velazquez Roberto Benjamín Monroy Vargas

Sheet ListadoCP
C8: Portal Privado Contribuyente CFDI - Fecha Cancelación RI
C10: Portal Privado Contribuyente CFDI
C11: CASOS DE PRUEBA
B12: CP01 | C12: /Autenticación_e.firma
B13: CP02 | C13: /Autenticación_contraseña
B14: CP03 | C14: /Inactividad
B15: CP04 | C15: /Salir
B16: CP05 | C16: /Menu - Contribuyente
B17: CP06 | C17: /Menu - PAC
C19: Facturas Emitidas
B20: CP07 | C20: /Facturas Emitidas/FolioFiscal
B21: CP08 | C21: /Facturas Emitidas/PeriodoFechas
B22: CP09 | C22: /Facturas Emitidas/FolioFiscal/Acciones/ Recuperar Acuse Estatus Final
B23: CP10 | C23: /Facturas Emitidas/Fechas/Acciones/ Recuperar Acuse Estatus Final
B24: CP11 | C24: /Facturas Emitidas/FolioFiscal/Acciones/Recuperar Acuse Solicitud Cancelación
B25: CP12 | C25: /Facturas Emitidas/Fechas/Acciones/Recuperar Acuse Solicitud Cancelación
B26: CP13 | C26: /Facturas Emitidas/FolioFiscal/Acciones/Detalle CFDI (Ver detalle)
B27: CP14 | C27: /Facturas Emitidas/Fechas/Acciones/Detalle CFDI (Ver detalle)
B28: CP15 | C28: /Facturas Emitidas/FolioFiscal/Acciones/Descargar
B29: CP16 | C29: /Facturas Emitidas/Fechas/Acciones/Descargar
B30: CP17 | C30: /Facturas Emitidas/FolioFiscal/Acciones/Recuperar Representación Impresa
B31: CP18 | C31: /Facturas Emitidas/Fechas/Acciones/Recuperar Representación Impresa
... B44: CP31 | C44: /Facturas Emitidas/FolioFiscal/Botón/Cancelar seleccionados - Servicio de firmado en el proceso de cancelaciones.
C46: Facturas Recibidas
B47: CP32 | C47: /Facturas Recibidas/FolioFiscal
B48: CP33 | C48: /Facturas Recibidas/PeriodoFechas
B49: CP34 | C49: /Facturas Recibidas/FolioFiscal/Acción/Recuperar acuse estatus final
B50: CP35 | C50: /Facturas Recibidas/Fechas/Acción/Recuperar acuse estatus final
B51: CP36 | C51: /Facturas Recibidas/FolioFiscal/Acción/Recuperar acuse de solicitud de cancelación
B52: CP37 | C52: /Facturas Recibidas/Fechas/Acción/Recuperar acuse de solicitud de cancelación
B53: CP38 | C53: /Facturas Recibidas/FolioFiscal/Acción/Detalle CFDI (Ver detalle)
B54: CP39 | C54: /Facturas Recibidas/Fechas/Acción/Detalle CFDI (Ver detalle)
B55: CP40 | C55: /Facturas Recibidas/FolioFiscal/Acción/Descargar
B56: CP41 | C56: /Facturas Recibidas/Fechas/Acción/Descargar
B57: CP42 | C57: /Facturas Recibidas/FolioFiscal/Acción/RecuperarRepresentaciónImpresa
B58: CP43 | C58: /Facturas Recibidas/Fechas/Acción/RecuperarRepresentaciónImpresa
... B67: CP52 | C67: /Facturas Recibidas/Fechas/Botón/Exportar Resultados a PDF
C69: Recuperar descargas CFDI
B70: CP53 | C70: /Recuperar Descargas de CFDI/Con registros
B71: CP54 | C71: /Recuperar Descargas de CFDI/Sin registros
...

Sheet Casos de Prueba
D10: Casos de Prueba
A12: Código del Aplicativo:
A13: ID de Requerimiento: | C13: POL 2770
A14: Nombre de Requerimiento: | C14: Portal Privado de Contribuyente CFDI
A15: [Fase: Análisis] [Etapa: Especificación Funcional] (ACSN)
A17: ID del Caso | B17: CP | C17: Nombre del Caso | D17: Paso | E17: Descripción de Paso | F17: Resultado Esperado | G17: Comentarios | H17: Perfil de usuario para su ejecución | I17: Datos de Prueba
A18: Identificador del caso de prueba que se integrará en Quality Center (QC). El ID del caso NO debe contener espacios en blanco. La diagonal debe ser “\”. La nomenclatura estándar es: PPMC_Número\Componente Tecnológico o Aplicativo(ya que ésta es la estructura o ruta de carpetas para almacenar y agrupar los objetos creados para contener la información de los Casos de Prueba y Escenarios de Pruebas). (Ejemplo: PPMC_56124\Juicios de Nulidad) | D18: Identificador secuencial de los pasos que sigue el caso de prueba. La información de todos los pasos de un Caso de Prueba debe ser consistente. | E18: Narración detallada del paso a ejecutar. Se deben evitar paréntesis y/o corchetes seguidos "{{..[[..((…))..]]..]]". No dejar en blanco, escribir N/A en caso de que no aplique. | F18: Narración detallada del resultado esperado, dada la ejecución del paso. Se deben evitar paréntesis y/o corchetes seguidos "{{..[[..((…))..]]..]]". No dejar en blanco, escribir N/A en caso de que no aplique. | G18: Anotaciones sobre lo que deba considerarse en forma adicional para la ejecución del Caso (descripción de los pre-requisitos que deben ser cubiertos para la ejecución del caso de prueba, identificación de las entradas requeridas del caso de prueba ). Se deben evitar paréntesis y/o corchetes seguidos "{{..[[..((…))..]]..]]". No dejar en blanco, escribir N/A en caso de que no aplique. | H18: Descripción del Perfil de usuario que se utilizará para la ejecución del Caso de Prueba. No dejar en blanco, escribir N/A en caso de que no aplique | I18: Para indicar los casos prueba y descripción de los elementos donde se emplearán los datos. Indicar el nombre del Dato de Prueba (RFC, Periodo,…) Ejemplos: Indicar el contenido del dato (AAAA790909JN6, 2010-01, …) Indicar el contenido del dato (AAAA790909JN6, 2010-02, …)
B19: CP01 | C19: Autenticación - e.Firma
A20: POL_2770 /PortalContribuyenteCFDI | C20: /Autenticación_e.firma | D20: 1 | E20: Usuario abre explorador | I20: PF: Firma Electrónica vigente PM: Firma Electrónica vigente Tipo de usuario: Contribuyente | J20: =+LEN(F20) -> 0 | K20: =+LEN(G20) -> 0 | L20: =+J20+K20 -> 0 | M20: =+IF(L20<=1000,0,1) -> 0
A21: POL_2770 /PortalContribuyenteCFDI | C21: /Autenticación_e.firma | D21: 2 | E21: Usuario ingresa a la URL correspondiente del Portal Privado Contribuyente CFDI . -Selecciona la opción por e.firma | F21: Se muestran los datos para ingresar: Certificado (.cer) Clave privada (.Key) Contraseña de clave privada: Se muestra el campo RFC | G21: Se requiere que el usuario al ingresar al aplicativo cuente con una opción que le permita autenticarse mediante su firma electrónica para lo cual: • Se deberá visualizar el componente para el firmado electrónico, el cual debe apegarse a los lineamientos institucionales vigentes por el área de Seguridad del SAT. • Se solicitarán los archivos del certificado, clave privada y contraseña vigentes. • Se mostrarán los mensajes de validación de los campos proporcionados por el Contribuyente conforme a los lineamientos institucionales vigentes por el área de Seguridad del SAT. | J21: =+LEN(F21) -> 130 | K21: =+LEN(G21) -> 577 | L21: =+J21+K21 -> 707 | M21: =+IF(L21<=1000,0,1) -> 0
A22: POL_2770 /PortalContribuyenteCFDI | C22: /Autenticación_e.firma | D22: 3 | E22: Usuario da clic en buscar y selecciona el archivo correspondiente a su certificado | F22: Se muestra el dato en el campo certificado y en el campo RFC el dato del RFC del Contribuyente | J22: =+LEN(F22) -> 95 | K22: =+LEN(G22) -> 0 | L22: =+J22+K22 -> 95 | M22: =+IF(L22<=1000,0,1) -> 0
A23: POL_2770 /PortalContribuyenteCFDI | C23: /Autenticación_e.firma | D23: 4 | E23: Usuario da clic en buscar y selecciona el archivo correspondiente a su clave privada | F23: Se muestra el dato en el campo clave privada | J23: =+LEN(F23) -> 44 | K23: =+LEN(G23) -> 0 | L23: =+J23+K23 -> 44 | M23: =+IF(L23<=1000,0,1) -> 0
A24: POL_2770 /PortalContribuyenteCFDI | C24: /Autenticación_e.firma | D24: 5 | E24: Usuario ingresa su contraseña | F24: Se muestra oculto el dato en el campo contraseña | J24: =+LEN(F24) -> 48 | K24: =+LEN(G24) -> 0 | L24: =+J24+K24 -> 48 | M24: =+IF(L24<=1000,0,1) -> 0
A25: POL_2770 /PortalContribuyenteCFDI | C25: /Autenticación_e.firma | D25: 6 | E25: Da clic en enviar | F25: Si la autenticación es correcta, el aplicativo abre la página principal del Portal Privado Contribuyente CFDI . | G25: En caso de que el Contribuyente no cuente con los permisos, el aplicativo mostrará el mensaje: “El Usuario no cuenta con los privilegios de acceso” y no va a permitir su acceso. | J25: =+LEN(F25) -> 111 | K25: =+LEN(G25) -> 178 | L25: =+J25+K25 -> 289 | M25: =+IF(L25<=1000,0,1) -> 0
B26: CP02 | C26: Autenticación - Contraseña | J26: =+LEN(F26) -> 0 | K26: =+LEN(G26) -> 0 | L26: =+J26+K26 -> 0 | M26: =+IF(L26<=1000,0,1) -> 0
A27: POL_2770 /PortalContribuyenteCFDI | C27: /Autenticación_contraseña | D27: 1 | E27: Usuario abre explorador | I27: Contraseña y RFC Tipo de usuario: Contribuyente | J27: =+LEN(F27) -> 0 | K27: =+LEN(G27) -> 0 | L27: =+J27+K27 -> 0 | M27: =+IF(L27<=1000,0,1) -> 0
A28: POL_2770 /PortalContribuyenteCFDI | C28: /Autenticación_contraseña | D28: 2 | E28: Usuario ingresa a la URL correspondiente del Portal Privado Contribuyente CFDI . -Selecciona la opción por contraseña (Default) | F28: Se muestran los datos para ingresar: .RFC .Contraseña .e.firma portable .Captcha | G28: Se mostrarán los mensajes de validación de los campos proporcionados por el Contribuyente conforme a los lineamientos institucionales vigentes por el área de Seguridad del SAT. | J28: =+LEN(F28) -> 82 | K28: =+LEN(G28) -> 177 | L28: =+J28+K28 -> 259 | M28: =+IF(L28<=1000,0,1) -> 0
A29: POL_2770 /PortalContribuyenteCFDI | C29: /Autenticación_contraseña | D29: 3 | E29: Usuario ingresa los datos requeridos .RFC | J29: =+LEN(F29) -> 0 | K29: =+LEN(G29) -> 0 | L29: =+J29+K29 -> 0 | M29: =+IF(L29<=1000,0,1) -> 0
A30: POL_2770 /PortalContribuyenteCFDI | C30: /Autenticación_contraseña | D30: 4 | E30: Usuario ingresa su contraseña | F30: Se muestra oculto el dato en el campo contraseña | J30: =+LEN(F30) -> 48 | K30: =+LEN(G30) -> 0 | L30: =+J30+K30 -> 48 | M30: =+IF(L30<=1000,0,1) -> 0
A31: POL_2770 /PortalContribuyenteCFDI | C31: /Autenticación_contraseña | D31: 5 | E31: Usuario ingresa el valor del la imagen Captcha | F31: La imagen del campo captcha es dinámico por lo que cambia cada que se actualice la página. Y debe coincidir con los valores ingresados por el usuario | J31: =+LEN(F31) -> 149 | K31: =+LEN(G31) -> 0 | L31: =+J31+K31 -> 149 | M31: =+IF(L31<=1000,0,1) -> 0
A32: POL_2770 /PortalContribuyenteCFDI | C32: /Autenticación_contraseña | D32: 6 | E32: Da clic en enviar | F32: Si la autenticación es correcta, el aplicativo abre la página principal del Portal Privado Contribuyente CFDI . | G32: En caso de que el Contribuyente no cuente con los permisos, el aplicativo mostrará el mensaje: “El Usuario no cuenta con los privilegios de acceso” y no va a permitir su acceso. | J32: =+LEN(F32) -> 111 | K32: =+LEN(G32) -> 178 | L32: =+J32+K32 -> 289 | M32: =+IF(L32<=1000,0,1) -> 0
B33: CP03 | C33: Inactividad | J33: =+LEN(F33) -> 0 | K33: =+LEN(G33) -> 0 | L33: =+J33+K33 -> 0 | M33: =+IF(L33<=1000,0,1) -> 0
A34: POL_2770 /PortalContribuyenteCFDI | C34: /Inactividad | D34: 1 | E34: Usuario ingresa al Portal Privado Contribuyente CFDI | F34: El sistema muestra las siguientes opciones: -Consultar Facturas Emitidas -Consulta Facturas Recibidas -Recuperar Descargas de CFDI -Consultar Solicitudes de Cancelación | G34: El Usuario previamente se autenticó y accedió al Portal Privado Contribuyente CFDI | H34: RFC Autenticado | I34: CFDI ver 3.3, 4.0 Tipo de usuario: Contribuyente | J34: =+LEN(F34) -> 168 | K34: =+LEN(G34) -> 83 | L34: =+J34+K34 -> 251 | M34: =+IF(L34<=1000,0,1) -> 0
A35: POL_2770 /PortalContribuyenteCFDI | C35: /Inactividad | D35: 2 | E35: Da clic en "Consultar Facturas Emitidas" | F35: El sistema muestra las siguientes opciones de búsqueda: - Folio Fiscal - Periodo de Fechas | J35: =+LEN(F35) -> 91 | K35: =+LEN(G35) -> 0 | L35: =+J35+K35 -> 91 | M35: =+IF(L35<=1000,0,1) -> 0
A36: POL_2770 /PortalContribuyenteCFDI | C36: /Inactividad | D36: 3 | E36: Dejar la sesión abierta | F36: Después de 15 minutos de inactividad, se cerrará la sesión en automático. | J36: =+LEN(F36) -> 73 | K36: =+LEN(G36) -> 0 | L36: =+J36+K36 -> 73 | M36: =+IF(L36<=1000,0,1) -> 0
B37: CP04 | C37: Salir | J37: =+LEN(F37) -> 0 | K37: =+LEN(G37) -> 0 | L37: =+J37+K37 -> 0 | M37: =+IF(L37<=1000,0,1) -> 0
A38: POL_2770 /PortalContribuyenteCFDI | C38: /Salir | D38: 1 | E38: Usuario ingresa al Portal de Contribuyente - Servicio de Factura Electrónica | F38: El sistema muestra las siguientes opciones: -Consultar Facturas Emitidas -Consulta Facturas Recibidas -Recuperar Descargas de CFDI -Consultar Solicitudes de Cancelación | G38: El Usuario previamente se autenticó y accedió al Portal Privado Contribuyente CFDI | H38: RFC Autenticado | I38: CFDI ver 3.3, 4.0 Tipo de usuario: Contribuyente | J38: =+LEN(F38) -> 168 | K38: =+LEN(G38) -> 83 | L38: =+J38+K38 -> 251 | M38: =+IF(L38<=1000,0,1) -> 0
A39: POL_2770 /PortalContribuyenteCFDI | C39: /Salir | D39: 2 | E39: Da clic en "Consultar Facturas Emitidas" | F39: El sistema muestra las siguientes opciones de búsqueda: - Folio Fiscal - Periodo de Fechas | J39: =+LEN(F39) -> 91 | K39: =+LEN(G39) -> 0 | L39: =+J39+K39 -> 91 | M39: =+IF(L39<=1000,0,1) -> 0
A40: POL_2770 /PortalContribuyenteCFDI | C40: /Salir | D40: 3 | E40: Da clic en Salir | F40: Cierra la sesión del RFC | J40: =+LEN(F40) -> 24 | K40: =+LEN(G40) -> 0 | L40: =+J40+K40 -> 24 | M40: =+IF(L40<=1000,0,1) -> 0
B41: CP05 | C41: Menú - Contribuyente | J41: =+LEN(F41) -> 0 | K41: =+LEN(G41) -> 0 | L41: =+J41+K41 -> 0 | M41: =+IF(L41<=1000,0,1) -> 0
A42: POL_2770 /PortalContribuyenteCFDI | C42: /Menú - Contribuyente | D42: 1 | E42: Usuario ingresa al Portal de Contribuyente - Servicio de Factura Electrónica | F42: El sistema muestra las siguientes opciones del menú: -Consultar Facturas Emitidas -Consultar Facturas Recibidas -Recuperar Descargas de CFDI -Consultar Solicitudes de Cancelación | G42: El Usuario previamente se autenticó como un contribuyente y accedió al Portal Privado Contribuyente CFDI | H42: RFC Autenticado | I42: CFDI ver 3.3, 4.0 Tipo de usuario: Contribuyente | J42: =+LEN(F42) -> 179 | K42: =+LEN(G42) -> 104 | L42: =+J42+K42 -> 283 | M42: =+IF(L42<=1000,0,1) -> 0
A43: POL_2770 /PortalContribuyenteCFDI | C43: /Menú - Contribuyente | D43: 2 | E43: Da clic en Salir | F43: Cierra la sesión del RFC | J43: =+LEN(F43) -> 24 | K43: =+LEN(G43) -> 0 | L43: =+J43+K43 -> 24 | M43: =+IF(L43<=1000,0,1) -> 0
B44: CP06 | C44: Menú - PAC | J44: =+LEN(F44) -> 0 | K44: =+LEN(G44) -> 0 | L44: =+J44+K44 -> 0 | M44: =+IF(L44<=1000,0,1) -> 0
A45: POL_2770 /PortalContribuyenteCFDI | C45: /Menú - PAC | D45: 1 | E45: Usuario ingresa al Portal de Contribuyente - Servicio de Factura Electrónica | F45: El sistema muestra las siguientes opciones del menú: -Consultar Facturas Emitidas -Consultar Facturas Recibidas -Recuperar Descargas de CFDI -Consultar Solicitudes de Cancelación -Consulta Incidentes CFDI -Consulta Incidentes CFDI de Retenciones | G45: El Usuario previamente se autenticó como un PAC y accedió al Portal Privado Contribuyente CFDI | H45: RFC Autenticado | I45: CFDI ver 3.3, 4.0 Tipo de usuario: PAC | J45: =+LEN(F45) -> 245 | K45: =+LEN(G45) -> 94 | L45: =+J45+K45 -> 339 | M45: =+IF(L45<=1000,0,1) -> 0
A46: POL_2770 /PortalContribuyenteCFDI | C46: /Menú - PAC | D46: 2 | E46: Da clic en Salir | F46: Cierra la sesión del RFC | J46: =+LEN(F46) -> 24 | K46: =+LEN(G46) -> 0 | L46: =+J46+K46 -> 24 | M46: =+IF(L46<=1000,0,1) -> 0
B47: CP07 | C47: Facturas Emitidas - Por Folio Fiscal | J47: =+LEN(F47) -> 0 | K47: =+LEN(G47) -> 0 | L47: =+J47+K47 -> 0 | M47: =+IF(L47<=1000,0,1) -> 0
A48: POL_2770 /PortalContribuyenteCFDI | C48: /Facturas Emitidas/FolioFiscal | D48: 1 | E48: Seleccionar la opción Consulta CFDI | F48: El sistema muestra las opciones: - Factura Electrónica - Retenciones e Inf. de Pagos | G48: El Usuario previamente se autenticó y accedió al Portal Privado Contribuyente CFDI | H48: RFC Autenticado RFC Emisor | I48: PF: Firma Electrónica vigente PM: Firma Electrónica vigente El Usuario ingresa el folio fiscal de tipo: .Nómina .Ingreso .Egreso .Pago .Traslado CFDI versión 3.3 o 4.0 | J48: =+LEN(F48) -> 86 | K48: =+LEN(G48) -> 84 | L48: =+J48+K48 -> 170 | M48: =+IF(L48<=1000,0,1) -> 0
A49: POL_2770 /PortalContribuyenteCFDI | C49: /Facturas Emitidas/FolioFiscal | D49: 2 | E49: Selecciona la opción Factura Electrónica | F49: El sistema muestra las siguientes opciones: -Consultar Facturas Emitidas -Consulta Facturas Recibidas -Recuperar Descargas de CFDI -Consultar Solicitudes de Cancelación | J49: =+LEN(F49) -> 168 | K49: =+LEN(G49) -> 0 | L49: =+J49+K49 -> 168 | M49: =+IF(L49<=1000,0,1) -> 0
A50: POL_2770 /PortalContribuyenteCFDI | C50: /Facturas Emitidas/FolioFiscal | D50: 3 | E50: Da clic en "Consultar Facturas Emitidas" | F50: El sistema muestra las opciones: - Folio Fiscal * (está opción esta habilitada por default)(RN02) Los siguientes campos se muestran deshabilitados: - Fecha Inicial de Emisión* - Fecha Final de Emisión* (RN06) - RFC Receptor (RN04) - RFC a cuenta de terceros (RN04) - Estado del Comprobante - Tipo de Comprobante (Complemento) - Estatus cancelación *campos obligatorios Opción: Buscar CFDI (RN08 - Inciso a, d). | J50: =+LEN(F50) -> 411 | K50: =+LEN(G50) -> 0 | L50: =+J50+K50 -> 411 | M50: =+IF(L50<=1000,0,1) -> 0
A51: POL_2770 /PortalContribuyenteCFDI | C51: /Facturas Emitidas/FolioFiscal | D51: 4 | E51: Selecciona la opción Folio Fiscal | F51: El sistema habilita el campo de FOLIO FISCAL | G51: Aplica las Reglas de Negocio: (RN02) | J51: =+LEN(F51) -> 44 | K51: =+LEN(G51) -> 39 | L51: =+J51+K51 -> 83 | M51: =+IF(L51<=1000,0,1) -> 0
...

Sheet Devops
C19: Test Case | D19: =IF('Casos de Prueba'!B19<>0,'Casos de Prueba'!B19&"-"&'Casos de Prueba'!C19,"") -> CP01-Autenticación - e.Firma
D20: =IF('Casos de Prueba'!B20<>0,'Casos de Prueba'!B20&"-"&'Casos de Prueba'!C20,"") | E20: =IF(LEN($C20)>0,"",'Casos de Prueba'!D20) -> 1 | F20: =IF(LEN($C20)>0,"",'Casos de Prueba'!E20) -> Usuario abre explorador | G20: =IF(LEN($C20)>0,"",'Casos de Prueba'!F20&CHAR(10)&'Casos de Prueba'!G20)
D21: =IF('Casos de Prueba'!B21<>0,'Casos de Prueba'!B21&"-"&'Casos de Prueba'!C21,"") | E21: =IF(LEN($C21)>0,"",'Casos de Prueba'!D21) -> 2 | F21: =IF(LEN($C21)>0,"",'Casos de Prueba'!E21) -> Usuario ingresa a la URL correspondiente del Portal Privado Contribuyente CFDI . -Selecciona la opción por e.firma | G21: =IF(LEN($C21)>0,"",'Casos de Prueba'!F21&CHAR(10)&'Casos de Prueba'!G21) -> Se muestran los datos para ingresar: Certificado (.cer) Clave privada (.Key) Contraseña de clave privada: Se muestra el campo RFC Se requiere que el usuario al ingresar al aplicativo cuente con una opción que le permita autenticarse mediante su firma electrónica para lo cual: • Se deberá visualizar el componente para el firmado electrónico, el cual debe apegarse a los lineamientos institucionales vigentes por el área de Seguridad del SAT. • Se solicitarán los archivos del certificado, clave privada y contraseña vigentes. • Se mostrarán los mensajes de validación de los campos proporcionados por el Contribuyente conforme a los lineamientos institucionales vigentes por el área de Seguridad del SAT.
D22: =IF('Casos de Prueba'!B22<>0,'Casos de Prueba'!B22&"-"&'Casos de Prueba'!C22,"") | E22: =IF(LEN($C22)>0,"",'Casos de Prueba'!D22) -> 3 | F22: =IF(LEN($C22)>0,"",'Casos de Prueba'!E22) -> Usuario da clic en buscar y selecciona el archivo correspondiente a su certificado | G22: =IF(LEN($C22)>0,"",'Casos de Prueba'!F22&CHAR(10)&'Casos de Prueba'!G22) -> Se muestra el dato en el campo certificado y en el campo RFC el dato del RFC del Contribuyente
D23: =IF('Casos de Prueba'!B23<>0,'Casos de Prueba'!B23&"-"&'Casos de Prueba'!C23,"") | E23: =IF(LEN($C23)>0,"",'Casos de Prueba'!D23) -> 4 | F23: =IF(LEN($C23)>0,"",'Casos de Prueba'!E23) -> Usuario da clic en buscar y selecciona el archivo correspondiente a su clave privada | G23: =IF(LEN($C23)>0,"",'Casos de Prueba'!F23&CHAR(10)&'Casos de Prueba'!G23) -> Se muestra el dato en el campo clave privada
D24: =IF('Casos de Prueba'!B24<>0,'Casos de Prueba'!B24&"-"&'Casos de Prueba'!C24,"") | E24: =IF(LEN($C24)>0,"",'Casos de Prueba'!D24) -> 5 | F24: =IF(LEN($C24)>0,"",'Casos de Prueba'!E24) -> Usuario ingresa su contraseña | G24: =IF(LEN($C24)>0,"",'Casos de Prueba'!F24&CHAR(10)&'Casos de Prueba'!G24) -> Se muestra oculto el dato en el campo contraseña
D25: =IF('Casos de Prueba'!B25<>0,'Casos de Prueba'!B25&"-"&'Casos de Prueba'!C25,"") | E25: =IF(LEN($C25)>0,"",'Casos de Prueba'!D25) -> 6 | F25: =IF(LEN($C25)>0,"",'Casos de Prueba'!E25) -> Da clic en enviar | G25: =IF(LEN($C25)>0,"",'Casos de Prueba'!F25&CHAR(10)&'Casos de Prueba'!G25) -> Si la autenticación es correcta, el aplicativo abre la página principal del Portal Privado Contribuyente CFDI . En caso de que el Contribuyente no cuente con los permisos, el aplicativo mostrará el mensaje: “El Usuario no cuenta con los privilegios de acceso” y no va a permitir su acceso.
D26: =IF('Casos de Prueba'!B26<>0,'Casos de Prueba'!B26&"-"&'Casos de Prueba'!C26,"") -> CP02-Autenticación - Contraseña
D27: =IF('Casos de Prueba'!B27<>0,'Casos de Prueba'!B27&"-"&'Casos de Prueba'!C27,"") | E27: =IF(LEN($C27)>0,"",'Casos de Prueba'!D27) -> 1 | F27: =IF(LEN($C27)>0,"",'Casos de Prueba'!E27) -> Usuario abre explorador | G27: =IF(LEN($C27)>0,"",'Casos de Prueba'!F27&CHAR(10)&'Casos de Prueba'!G27)
D28: =IF('Casos de Prueba'!B28<>0,'Casos de Prueba'!B28&"-"&'Casos de Prueba'!C28,"") | E28: =IF(LEN($C28)>0,"",'Casos de Prueba'!D28) -> 2 | F28: =IF(LEN($C28)>0,"",'Casos de Prueba'!E28) -> Usuario ingresa a la URL correspondiente del Portal Privado Contribuyente CFDI . -Selecciona la opción por contraseña (Default) | G28: =IF(LEN($C28)>0,"",'Casos de Prueba'!F28&CHAR(10)&'Casos de Prueba'!G28) -> Se muestran los datos para ingresar: .RFC .Contraseña .e.firma portable .Captcha Se mostrarán los mensajes de validación de los campos proporcionados por el Contribuyente conforme a los lineamientos institucionales vigentes por el área de Seguridad del SAT.
D29: =IF('Casos de Prueba'!B29<>0,'Casos de Prueba'!B29&"-"&'Casos de Prueba'!C29,"") | E29: =IF(LEN($C29)>0,"",'Casos de Prueba'!D29) -> 3 | F29: =IF(LEN($C29)>0,"",'Casos de Prueba'!E29) -> Usuario ingresa los datos requeridos .RFC | G29: =IF(LEN($C29)>0,"",'Casos de Prueba'!F29&CHAR(10)&'Casos de Prueba'!G29)
D30: =IF('Casos de Prueba'!B30<>0,'Casos de Prueba'!B30&"-"&'Casos de Prueba'!C30,"") | E30: =IF(LEN($C30)>0,"",'Casos de Prueba'!D30) -> 4 | F30: =IF(LEN($C30)>0,"",'Casos de Prueba'!E30) -> Usuario ingresa su contraseña | G30: =IF(LEN($C30)>0,"",'Casos de Prueba'!F30&CHAR(10)&'Casos de Prueba'!G30) -> Se muestra oculto el dato en el campo contraseña
D31: =IF('Casos de Prueba'!B31<>0,'Casos de Prueba'!B31&"-"&'Casos de Prueba'!C31,"") | E31: =IF(LEN($C31)>0,"",'Casos de Prueba'!D31) -> 5 | F31: =IF(LEN($C31)>0,"",'Casos de Prueba'!E31) -> Usuario ingresa el valor del la imagen Captcha | G31: =IF(LEN($C31)>0,"",'Casos de Prueba'!F31&CHAR(10)&'Casos de Prueba'!G31) -> La imagen del campo captcha es dinámico por lo que cambia cada que se actualice la página. Y debe coincidir con los valores ingresados por el usuario
D32: =IF('Casos de Prueba'!B32<>0,'Casos de Prueba'!B32&"-"&'Casos de Prueba'!C32,"") | E32: =IF(LEN($C32)>0,"",'Casos de Prueba'!D32) -> 6 | F32: =IF(LEN($C32)>0,"",'Casos de Prueba'!E32) -> Da clic en enviar | G32: =IF(LEN($C32)>0,"",'Casos de Prueba'!F32&CHAR(10)&'Casos de Prueba'!G32) -> Si la autenticación es correcta, el aplicativo abre la página principal del Portal Privado Contribuyente CFDI . En caso de que el Contribuyente no cuente con los permisos, el aplicativo mostrará el mensaje: “El Usuario no cuenta con los privilegios de acceso” y no va a permitir su acceso.
D33: =IF('Casos de Prueba'!B33<>0,'Casos de Prueba'!B33&"-"&'Casos de Prueba'!C33,"") -> CP03-Inactividad
D34: =IF('Casos de Prueba'!B34<>0,'Casos de Prueba'!B34&"-"&'Casos de Prueba'!C34,"") | E34: =IF(LEN($C34)>0,"",'Casos de Prueba'!D34) -> 1 | F34: =IF(LEN($C34)>0,"",'Casos de Prueba'!E34) -> Usuario ingresa al Portal Privado Contribuyente CFDI | G34: =IF(LEN($C34)>0,"",'Casos de Prueba'!F34&CHAR(10)&'Casos de Prueba'!G34) -> El sistema muestra las siguientes opciones: -Consultar Facturas Emitidas -Consulta Facturas Recibidas -Recuperar Descargas de CFDI -Consultar Solicitudes de Cancelación El Usuario previamente se autenticó y accedió al Portal Privado Contribuyente CFDI
D35: =IF('Casos de Prueba'!B35<>0,'Casos de Prueba'!B35&"-"&'Casos de Prueba'!C35,"") | E35: =IF(LEN($C35)>0,"",'Casos de Prueba'!D35) -> 2 | F35: =IF(LEN($C35)>0,"",'Casos de Prueba'!E35) -> Da clic en "Consultar Facturas Emitidas" | G35: =IF(LEN($C35)>0,"",'Casos de Prueba'!F35&CHAR(10)&'Casos de Prueba'!G35) -> El sistema muestra las siguientes opciones de búsqueda: - Folio Fiscal - Periodo de Fechas
D36: =IF('Casos de Prueba'!B36<>0,'Casos de Prueba'!B36&"-"&'Casos de Prueba'!C36,"") | E36: =IF(LEN($C36)>0,"",'Casos de Prueba'!D36) -> 3 | F36: =IF(LEN($C36)>0,"",'Casos de Prueba'!E36) -> Dejar la sesión abierta | G36: =IF(LEN($C36)>0,"",'Casos de Prueba'!F36&CHAR(10)&'Casos de Prueba'!G36) -> Después de 15 minutos de inactividad, se cerrará la sesión en automático.
D37: =IF('Casos de Prueba'!B37<>0,'Casos de Prueba'!B37&"-"&'Casos de Prueba'!C37,"") -> CP04-Salir
D38: =IF('Casos de Prueba'!B38<>0,'Casos de Prueba'!B38&"-"&'Casos de Prueba'!C38,"") | E38: =IF(LEN($C38)>0,"",'Casos de Prueba'!D38) -> 1 | F38: =IF(LEN($C38)>0,"",'Casos de Prueba'!E38) -> Usuario ingresa al Portal de Contribuyente - Servicio de Factura Electrónica | G38: =IF(LEN($C38)>0,"",'Casos de Prueba'!F38&CHAR(10)&'Casos de Prueba'!G38) -> El sistema muestra las siguientes opciones: -Consultar Facturas Emitidas -Consulta Facturas Recibidas -Recuperar Descargas de CFDI -Consultar Solicitudes de Cancelación El Usuario previamente se autenticó y accedió al Portal Privado Contribuyente CFDI
D39: =IF('Casos de Prueba'!B39<>0,'Casos de Prueba'!B39&"-"&'Casos de Prueba'!C39,"") | E39: =IF(LEN($C39)>0,"",'Casos de Prueba'!D39) -> 2 | F39: =IF(LEN($C39)>0,"",'Casos de Prueba'!E39) -> Da clic en "Consultar Facturas Emitidas" | G39: =IF(LEN($C39)>0,"",'Casos de Prueba'!F39&CHAR(10)&'Casos de Prueba'!G39) -> El sistema muestra las siguientes opciones de búsqueda: - Folio Fiscal - Periodo de Fechas
D40: =IF('Casos de Prueba'!B40<>0,'Casos de Prueba'!B40&"-"&'Casos de Prueba'!C40,"") | E40: =IF(LEN($C40)>0,"",'Casos de Prueba'!D40) -> 3 | F40: =IF(LEN($C40)>0,"",'Casos de Prueba'!E40) -> Da clic en Salir | G40: =IF(LEN($C40)>0,"",'Casos de Prueba'!F40&CHAR(10)&'Casos de Prueba'!G40) -> Cierra la sesión del RFC
D41: =IF('Casos de Prueba'!B41<>0,'Casos de Prueba'!B41&"-"&'Casos de Prueba'!C41,"") -> CP05-Menú - Contribuyente
D42: =IF('Casos de Prueba'!B42<>0,'Casos de Prueba'!B42&"-"&'Casos de Prueba'!C42,"") | E42: =IF(LEN($C42)>0,"",'Casos de Prueba'!D42) -> 1 | F42: =IF(LEN($C42)>0,"",'Casos de Prueba'!E42) -> Usuario ingresa al Portal de Contribuyente - Servicio de Factura Electrónica | G42: =IF(LEN($C42)>0,"",'Casos de Prueba'!F42&CHAR(10)&'Casos de Prueba'!G42) -> El sistema muestra las siguientes opciones del menú: -Consultar Facturas Emitidas -Consultar Facturas Recibidas -Recuperar Descargas de CFDI -Consultar Solicitudes de Cancelación El Usuario previamente se autenticó como un contribuyente y accedió al Portal Privado Contribuyente CFDI
D43: =IF('Casos de Prueba'!B43<>0,'Casos de Prueba'!B43&"-"&'Casos de Prueba'!C43,"") | E43: =IF(LEN($C43)>0,"",'Casos de Prueba'!D43) -> 2 | F43: =IF(LEN($C43)>0,"",'Casos de Prueba'!E43) -> Da clic en Salir | G43: =IF(LEN($C43)>0,"",'Casos de Prueba'!F43&CHAR(10)&'Casos de Prueba'!G43) -> Cierra la sesión del RFC
D44: =IF('Casos de Prueba'!B44<>0,'Casos de Prueba'!B44&"-"&'Casos de Prueba'!C44,"") -> CP06-Menú - PAC
D45: =IF('Casos de Prueba'!B45<>0,'Casos de Prueba'!B45&"-"&'Casos de Prueba'!C45,"") | E45: =IF(LEN($C45)>0,"",'Casos de Prueba'!D45) -> 1 | F45: =IF(LEN($C45)>0,"",'Casos de Prueba'!E45) -> Usuario ingresa al Portal de Contribuyente - Servicio de Factura Electrónica | G45: =IF(LEN($C45)>0,"",'Casos de Prueba'!F45&CHAR(10)&'Casos de Prueba'!G45) -> El sistema muestra las siguientes opciones del menú: -Consultar Facturas Emitidas -Consultar Facturas Recibidas -Recuperar Descargas de CFDI -Consultar Solicitudes de Cancelación -Consulta Incidentes CFDI -Consulta Incidentes CFDI de Retenciones El Usuario previamente se autenticó como un PAC y accedió al Portal Privado Contribuyente CFDI
D46: =IF('Casos de Prueba'!B46<>0,'Casos de Prueba'!B46&"-"&'Casos de Prueba'!C46,"") | E46: =IF(LEN($C46)>0,"",'Casos de Prueba'!D46) -> 2 | F46: =IF(LEN($C46)>0,"",'Casos de Prueba'!E46) -> Da clic en Salir | G46: =IF(LEN($C46)>0,"",'Casos de Prueba'!F46&CHAR(10)&'Casos de Prueba'!G46) -> Cierra la sesión del RFC
D47: =IF('Casos de Prueba'!B47<>0,'Casos de Prueba'!B47&"-"&'Casos de Prueba'!C47,"") -> CP07-Facturas Emitidas - Por Folio Fiscal
D48: =IF('Casos de Prueba'!B48<>0,'Casos de Prueba'!B48&"-"&'Casos de Prueba'!C48,"") | E48: =IF(LEN($C48)>0,"",'Casos de Prueba'!D48) -> 1 | F48: =IF(LEN($C48)>0,"",'Casos de Prueba'!E48) -> Seleccionar la opción Consulta CFDI | G48: =IF(LEN($C48)>0,"",'Casos de Prueba'!F48&CHAR(10)&'Casos de Prueba'!G48) -> El sistema muestra las opciones: - Factura Electrónica - Retenciones e Inf. de Pagos El Usuario previamente se autenticó y accedió al Portal Privado Contribuyente CFDI
D49: =IF('Casos de Prueba'!B49<>0,'Casos de Prueba'!B49&"-"&'Casos de Prueba'!C49,"") | E49: =IF(LEN($C49)>0,"",'Casos de Prueba'!D49) -> 2 | F49: =IF(LEN($C49)>0,"",'Casos de Prueba'!E49) -> Selecciona la opción Factura Electrónica | G49: =IF(LEN($C49)>0,"",'Casos de Prueba'!F49&CHAR(10)&'Casos de Prueba'!G49) -> El sistema muestra las siguientes opciones: -Consultar Facturas Emitidas -Consulta Facturas Recibidas -Recuperar Descargas de CFDI -Consultar Solicitudes de Cancelación
D50: =IF('Casos de Prueba'!B50<>0,'Casos de Prueba'!B50&"-"&'Casos de Prueba'!C50,"") | E50: =IF(LEN($C50)>0,"",'Casos de Prueba'!D50) -> 3 | F50: =IF(LEN($C50)>0,"",'Casos de Prueba'!E50) -> Da clic en "Consultar Facturas Emitidas" | G50: =IF(LEN($C50)>0,"",'Casos de Prueba'!F50&CHAR(10)&'Casos de Prueba'!G50) -> El sistema muestra las opciones: - Folio Fiscal * (está opción esta habilitada por default)(RN02) Los siguientes campos se muestran deshabilitados: - Fecha Inicial de Emisión* - Fecha Final de Emisión* (RN06) - RFC Receptor (RN04) - RFC a cuenta de terceros (RN04) - Estado del Comprobante - Tipo de Comprobante (Complemento) - Estatus cancelación *campos obligatorios Opción: Buscar CFDI (RN08 - Inciso a, d).
D51: =IF('Casos de Prueba'!B51<>0,'Casos de Prueba'!B51&"-"&'Casos de Prueba'!C51,"") | E51: =IF(LEN($C51)>0,"",'Casos de Prueba'!D51) -> 4 | F51: =IF(LEN($C51)>0,"",'Casos de Prueba'!E51) -> Selecciona la opción Folio Fiscal | G51: =IF(LEN($C51)>0,"",'Casos de Prueba'!F51&CHAR(10)&'Casos de Prueba'!G51) -> El sistema habilita el campo de FOLIO FISCAL Aplica las Reglas de Negocio: (RN02)
D52: =IF('Casos de Prueba'!B52<>0,'Casos de Prueba'!B52&"-"&'Casos de Prueba'!C52,"") | E52: =IF(LEN($C52)>0,"",'Casos de Prueba'!D52) -> 5 | F52: =IF(LEN($C52)>0,"",'Casos de Prueba'!E52) -> Ingresa los datos del número de Folio Fiscal a buscar | G52: =IF(LEN($C52)>0,"",'Casos de Prueba'!F52&CHAR(10)&'Casos de Prueba'!G52) -> El sistema muestra los datos que se van ingresando
D53: =IF('Casos de Prueba'!B53<>0,'Casos de Prueba'!B53&"-"&'Casos de Prueba'!C53,"") | E53: =IF(LEN($C53)>0,"",'Casos de Prueba'!D53) -> 6 | F53: =IF(LEN($C53)>0,"",'Casos de Prueba'!E53) -> Da clic en el botón Buscar CFDI | G53: =IF(LEN($C53)>0,"",'Casos de Prueba'!F53&CHAR(10)&'Casos de Prueba'!G53) -> El sistema muestra la sección de resultados que está compuesta: 1. Casilla Acciones • Seleccionar. • Recuperar acuse estatus final. (Visible solo cuando contenga acuse) • Recuperar acuse de solicitud de cancelación. (Visible solo cuando contenga acuse) • Ver detalle. • Descargar. • Recuperar Representación Impresa. • Recuperar Representación Impresa Complemento Carta Porte (Visible solo cuando contenga Complemento Carta Porte) • Integrar Addenda 2. Columnas y resultados de los registros Algunas columnas pueden no contener información, lo cual va a depender de la situación en la que se encuentre el CFDI. • Acciones. • Folio Fiscal. • RFC Emisor. • Nombre o Razón Social del Emisor. • RFC Receptor. • Nombre o Razón Social del Receptor. • Fecha de Emisión. • Fecha de Certificación. • PAC que Certificó. • Total. • Efecto del Comprobante. • Estatus de cancelación. • Estado del Comprobante. • Estatus de Proceso de Cancelación. • Fecha de Solicitud de la Cancelación • Fecha de Cancelación. • RFC a cuenta de terceros. • Motivo. • Folio de Sustitución. 3. Paginador. (Solo aplica para búsqueda por periodo) (RN10, RN11). 4. Botones: • Descargar Seleccionados. • Descargar Seleccionados RI. • Descargar Metadata. • Exportar Resultados a PDF. • Cancelar Seleccionados. Nota: El atributo “Fecha de Cancelación” va a mostrar el valor de la fecha cuando se haya realizado la cancelación del comprobante en caso contrario va a mostrar el valor en blanco. Aplica las Reglas de Negocio: (RN08 - Inciso a,d). Si la búsqueda es correcta va a mostrar la sección de “Sección de Resultados” Esta opción muestra un registro como resultado. En dado caso que el sistema detecta una inconsistencia cuando el contribuyente presiona el botón “Buscar CFDI” mostrará los siguientes mensajes: • En caso de que el Folio Fiscal a buscar se encuentre vacío, el sistema deberá mostrar el siguiente mensaje: “ERROR: Favor de ingresar el folio fiscal”. • En caso de un Folio Fiscal inválido o incompleto, el sistema deberá mostrar el siguiente mensaje: “El folio fiscal no cumple con el formato correcto, favor de ingresarlo nuevamente”. • En caso de que no se encuentre información con los parámetros de búsqueda ingresados, el sistema deberá mostrar el siguiente mensaje: “No existen registros que cumplan con los criterios de búsqueda ingresados, intentar nuevamente”. Nota: Al seleccionar el botón de folio fiscal se deben deshabilitar los campos correspondientes a la consulta por periodo de fecha de emisión.
D54: =IF('Casos de Prueba'!B54<>0,'Casos de Prueba'!B54&"-"&'Casos de Prueba'!C54,"") | E54: =IF(LEN($C54)>0,"",'Casos de Prueba'!D54) -> 7 | F54: =IF(LEN($C54)>0,"",'Casos de Prueba'!E54) -> Da clic en Salir | G54: =IF(LEN($C54)>0,"",'Casos de Prueba'!F54&CHAR(10)&'Casos de Prueba'!G54) -> Cierra la sesión del RFC
D55: =IF('Casos de Prueba'!B55<>0,'Casos de Prueba'!B55&"-"&'Casos de Prueba'!C55,"") -> CP08-Facturas Emitidas -Periodo Fechas
D56: =IF('Casos de Prueba'!B56<>0,'Casos de Prueba'!B56&"-"&'Casos de Prueba'!C56,"") | E56: =IF(LEN($C56)>0,"",'Casos de Prueba'!D56) -> 1 | F56: =IF(LEN($C56)>0,"",'Casos de Prueba'!E56) -> Seleccionar la opción Consulta CFDI | G56: =IF(LEN($C56)>0,"",'Casos de Prueba'!F56&CHAR(10)&'Casos de Prueba'!G56) -> El sistema muestra las opciones: - Factura Electrónica - Retenciones e Inf. de Pagos El Usuario previamente se autenticó y accedió al Portal Privado Contribuyente CFDI
D57: =IF('Casos de Prueba'!B57<>0,'Casos de Prueba'!B57&"-"&'Casos de Prueba'!C57,"") | E57: =IF(LEN($C57)>0,"",'Casos de Prueba'!D57) -> 2 | F57: =IF(LEN($C57)>0,"",'Casos de Prueba'!E57) -> Selecciona la opción Factura Electrónica | G57: =IF(LEN($C57)>0,"",'Casos de Prueba'!F57&CHAR(10)&'Casos de Prueba'!G57) -> El sistema muestra las siguientes opciones: -Consultar Facturas Emitidas -Consulta Facturas Recibidas -Recuperar Descargas de CFDI -Consultar Solicitudes de Cancelación
D58: =IF('Casos de Prueba'!B58<>0,'Casos de Prueba'!B58&"-"&'Casos de Prueba'!C58,"") | E58: =IF(LEN($C58)>0,"",'Casos de Prueba'!D58) -> 3 | F58: =IF(LEN($C58)>0,"",'Casos de Prueba'!E58) -> Da clic en "Consultar Facturas Emitidas" | G58: =IF(LEN($C58)>0,"",'Casos de Prueba'!F58&CHAR(10)&'Casos de Prueba'!G58) -> El sistema muestra las opciones: - Folio Fiscal * (está opción esta habilitada por default) Los siguientes campos se muestran deshabilitados: - Fecha Inicial de Emisión* - Fecha Final de Emisión* - RFC Receptor -RFC a cuenta de terceros - Estado del Comprobante - Tipo de Comprobante (Complemento) - Estatus Cancelación *campos obligatorios Opción: Buscar CFDI
...

Sheet Devops_Carga
B1: Work Item type | C1: Title | D1: Step Action | E1: Step expected
B2: Test Case | C2: CP01-Autenticación - e.Firma
D3: 1 | E3: Usuario abre explorador
D4: 2 | E4: Usuario ingresa a la URL correspondiente del Portal Privado Contribuyente CFDI . -Selecciona la opción por e.firma | F4: Se muestran los datos para ingresar: Certificado (.cer) Clave privada (.Key) Contraseña de clave privada: Se muestra el campo RFC Se requiere que el usuario al ingresar al aplicativo cuente con una opción que le permita autenticarse mediante su firma electrónica para lo cual: • Se deberá visualizar el componente para el firmado electrónico, el cual debe apegarse a los lineamientos institucionales vigentes por el área de Seguridad del SAT. • Se solicitarán los archivos del certificado, clave privada y contraseña vigentes. • Se mostrarán los mensajes de validación de los campos proporcionados por el Contribuyente conforme a los lineamientos institucionales vigentes por el área de Seguridad del SAT.
D5: 3 | E5: Usuario da clic en buscar y selecciona el archivo correspondiente a su certificado | F5: Se muestra el dato en el campo certificado y en el campo RFC el dato del RFC del Contribuyente
D6: 4 | E6: Usuario da clic en buscar y selecciona el archivo correspondiente a su clave privada | F6: Se muestra el dato en el campo clave privada
D7: 5 | E7: Usuario ingresa su contraseña | F7: Se muestra oculto el dato en el campo contraseña
D8: 6 | E8: Da clic en enviar | F8: Si la autenticación es correcta, el aplicativo abre la página principal del Portal Privado Contribuyente CFDI . En caso de que el Contribuyente no cuente con los permisos, el aplicativo mostrará el mensaje: “El Usuario no cuenta con los privilegios de acceso” y no va a permitir su acceso.
C9: CP02-Autenticación - Contraseña
D10: 1 | E10: Usuario abre explorador
D11: 2 | E11: Usuario ingresa a la URL correspondiente del Portal Privado Contribuyente CFDI . -Selecciona la opción por contraseña (Default) | F11: Se muestran los datos para ingresar: .RFC .Contraseña .e.firma portable .Captcha Se mostrarán los mensajes de validación de los campos proporcionados por el Contribuyente conforme a los lineamientos institucionales vigentes por el área de Seguridad del SAT.
D12: 3 | E12: Usuario ingresa los datos requeridos .RFC
D13: 4 | E13: Usuario ingresa su contraseña | F13: Se muestra oculto el dato en el campo contraseña
D14: 5 | E14: Usuario ingresa el valor del la imagen Captcha | F14: La imagen del campo captcha es dinámico por lo que cambia cada que se actualice la página. Y debe coincidir con los valores ingresados por el usuario
D15: 6 | E15: Da clic en enviar | F15: Si la autenticación es correcta, el aplicativo abre la página principal del Portal Privado Contribuyente CFDI . En caso de que el Contribuyente no cuente con los permisos, el aplicativo mostrará el mensaje: “El Usuario no cuenta con los privilegios de acceso” y no va a permitir su acceso.
C16: CP03-Inactividad
D17: 1 | E17: Usuario ingresa al Portal Privado Contribuyente CFDI | F17: El sistema muestra las siguientes opciones: -Consultar Facturas Emitidas -Consulta Facturas Recibidas -Recuperar Descargas de CFDI -Consultar Solicitudes de Cancelación El Usuario previamente se autenticó y accedió al Portal Privado Contribuyente CFDI
D18: 2 | E18: Da clic en "Consultar Facturas Emitidas" | F18: El sistema muestra las siguientes opciones de búsqueda: - Folio Fiscal - Periodo de Fechas
D19: 3 | E19: Dejar la sesión abierta | F19: Después de 15 minutos de inactividad, se cerrará la sesión en automático.
C20: CP04-Salir
D21: 1 | E21: Usuario ingresa al Portal de Contribuyente - Servicio de Factura Electrónica | F21: El sistema muestra las siguientes opciones: -Consultar Facturas Emitidas -Consulta Facturas Recibidas -Recuperar Descargas de CFDI -Consultar Solicitudes de Cancelación El Usuario previamente se autenticó y accedió al Portal Privado Contribuyente CFDI
D22: 2 | E22: Da clic en "Consultar Facturas Emitidas" | F22: El sistema muestra las siguientes opciones de búsqueda: - Folio Fiscal - Periodo de Fechas
D23: 3 | E23: Da clic en Salir | F23: Cierra la sesión del RFC
C24: CP05-Menú - Contribuyente
D25: 1 | E25: Usuario ingresa al Portal de Contribuyente - Servicio de Factura Electrónica | F25: El sistema muestra las siguientes opciones del menú: -Consultar Facturas Emitidas -Consulta Facturas Recibidas -Recuperar Descargas de CFDI -Consultar Solicitudes de Cancelación El Usuario previamente se autenticó como un contribuyente y accedió al Portal Privado Contribuyente CFDI
D26: 2 | E26: Da clic en Salir | F26: Cierra la sesión del RFC
C27: CP06-Menú - PAC
D28: 1 | E28: Usuario ingresa al Portal de Contribuyente - Servicio de Factura Electrónica | F28: El sistema muestra las siguientes opciones del menú: -Consultar Facturas Emitidas -Consulta Facturas Recibidas -Recuperar Descargas de CFDI -Consultar Solicitudes de Cancelación -Consulta Incidentes CFDI -Consulta Incidentes CFDI de Retenciones El Usuario previamente se autenticó como un PAC y accedió al Portal Privado Contribuyente CFDI
D29: 2 | E29: Da clic en Salir | F29: Cierra la sesión del RFC
C30: CP07-Facturas Emitidas - Por Folio Fiscal
D31: 1 | E31: Seleccionar la opción Consulta CFDI | F31: El sistema muestra las opciones: - Factura Electrónica - Retenciones e Inf. de Pagos El Usuario previamente se autenticó y accedió al Portal Privado Contribuyente CFDI
D32: 2 | E32: Selecciona la opción Factura Electrónica | F32: El sistema muestra las siguientes opciones: -Consultar Facturas Emitidas -Consulta Facturas Recibidas -Recuperar Descargas de CFDI -Consultar Solicitudes de Cancelación
D33: 3 | E33: Da clic en "Consultar Facturas Emitidas" | F33: El sistema muestra las opciones: - Folio Fiscal * (está opción esta habilitada por default)(RN02) Los siguientes campos se muestran deshabilitados: - Fecha Inicial de Emisión* - Fecha Final de Emisión* (RN06) - RFC Receptor (RN04) - RFC a cuenta de terceros (RN04) - Estado del Comprobante - Tipo de Comprobante (Complemento) - Estatus cancelación *campos obligatorios Opción: Buscar CFDI (RN08 - Inciso a, d).
D34: 4 | E34: Selecciona la opción Folio Fiscal | F34: El sistema habilita el campo de FOLIO FISCAL Aplica las Reglas de Negocio: (RN02)
D35: 5 | E35: Ingresa los datos del número de Folio Fiscal a buscar | F35: El sistema muestra los datos que se van ingresando
D36: 6 | E36: Da clic en el botón Buscar CFDI | F36: El sistema muestra la sección de resultados que está compuesta: 1. Casilla Acciones • Seleccionar. • Recuperar acuse estatus final. (Visible solo cuando contenga acuse) • Recuperar acuse de solicitud de cancelación. (Visible solo cuando contenga acuse) • Ver detalle. • Descargar. • Recuperar Representación Impresa. • Recuperar Representación Impresa Complemento Carta Porte (Visible solo cuando contenga Complemento Carta Porte) • Integrar Addenda 2. Columnas y resultados de los registros Algunas columnas pueden no contener información, lo cual va a depender de la situación en la que se encuentre el CFDI. • Acciones. • Folio Fiscal. • RFC Emisor. • Nombre o Razón Social del Emisor. • RFC Receptor. • Nombre o Razón Social del Receptor. • Fecha de Emisión. • Fecha de Certificación. • PAC que Certificó. • Total. • Efecto del Comprobante. • Estatus de cancelación. • Estado del Comprobante. • Estatus de Proceso de Cancelación. • Fecha de Solicitud de la Cancelación • Fecha de Cancelación. • RFC a cuenta de terceros. • Motivo. • Folio de Sustitución. 3. Paginador. (Solo aplica para búsqueda por periodo) (RN10, RN11). 4. Botones: • Descargar Seleccionados. • Descargar Seleccionados RI. • Descargar Metadata. • Exportar Resultados a PDF. • Cancelar Seleccionados. Nota: El atributo “Fecha de Cancelación” va a mostrar el valor de la fecha cuando se haya realizado la cancelación del comprobante en caso contrario va a mostrar el valor en blanco. Aplica las Reglas de Negocio: (RN08 - Inciso a,d). Si la búsqueda es correcta va a mostrar la sección de “Sección de Resultados” Esta opción muestra un registro como resultado. En dado caso que el sistema detecta una inconsistencia cuando el contribuyente presiona el botón “Buscar CFDI” mostrará los siguientes mensajes: • En caso de que el Folio Fiscal a buscar se encuentre vacío, el sistema deberá mostrar el siguiente mensaje: “ERROR: Favor de ingresar el folio fiscal”. • En caso de un Folio Fiscal inválido o incompleto, el sistema deberá mostrar el siguiente mensaje: “El folio fiscal no cumple con el formato correcto, favor de ingresarlo nuevamente”. • En caso de que no se encuentre información con los parámetros de búsqueda ingresados, el sistema deberá mostrar el siguiente mensaje: “No existen registros que cumplan con los criterios de búsqueda ingresados, intentar nuevamente”. Nota: Al seleccionar el botón de folio fiscal se deben deshabilitar los campos correspondientes a la consulta por periodo de fecha de emisión.
D37: 7 | E37: Da clic en Salir | F37: Cierra la sesión del RFC
C38: CP08-Facturas Emitidas -Periodo Fechas
D39: 1 | E39: Seleccionar la opción Consulta CFDI | F39: El sistema muestra las opciones: - Factura Electrónica - Retenciones e Inf. de Pagos El Usuario previamente se autenticó y accedió al Portal Privado Contribuyente CFDI
D40: 2 | E40: Selecciona la opción Factura Electrónica | F40: El sistema muestra las siguientes opciones: -Consultar Facturas Emitidas -Consulta Facturas Recibidas -Recuperar Descargas de CFDI -Consultar Solicitudes de Cancelación
...

Sheet Firmas Conformidad
B2: El uso de la siguiente Sección de Firmas de Conformidad es opcional, dependiendo de la necesidad del consumidor de la información.
B3: Instrucciones:
B4: Registrar en la tabla la información de los participantes en la elaboración, revisión, aprobación, etc. del artefacto.
B6: FIRMAS DE CONFORMIDAD
B7: Autorizó | C7: Autorizó
B8: Nombre: Pedro López Bernal. | C8: Nombre: Diana Maribel Velazquez Barroso
B9: Puesto: Administrador de Gestión de Servicios y Trámites con Medios Electrónicos 3 | C9: Puesto: Administradora de Soluciones de Negocio 3
B10: Fecha: | C10: Fecha:
B12: Revisó | C12: Revisó
B13: Nombre: Mario Alberto Huerta Velazquez | C13: Nombre: Roberto Benjamín Monroy Vargas
B14: Puesto: Subadministrador de Gestión de Servicios y Trámites con Medios Electrónicos | C14: Puesto: Subadministrador de Soluciones de Negocio
B15: Fecha: | C15: Fecha:
B17: Revisó | C17: Revisó
B18: Nombre: Maria Luisa Flores Barrón | C18: Nombre: Marlen Hernández Luna
B19: Puesto: Subadministrador de Gestión de Servicios y Trámites con Medios Electrónicos | C19: Puesto: Jefe de Departamento de Gestión de Servicios y Trámites con Medios Electrónicos
B20: Fecha: | C20: Fecha:
... B25: Fecha: | C25: Fecha:

Sheet Encabezado
C1: Tomar como referencia el siguiente Encabezado para edición:
H4: Administración General de Comunicaciones y Tecnologías de la Información
H6: Marco Documental 7.0
C7: Fecha de aprobación del Template: 01/11/2021 | E7: Requerimientos de Pruebas Clave del Documento XX_RDP_REQPRUEBAS.xlsx [Nomenclatura del artefacto, punto, extensión del archivo actual] Servicio Administración del Ciclo de Vida de Aplicaciones de TIC Central Dueña: Administración Central de Soluciones de Negocio (ACSN) Central que Elabora: ACSN Central Consumidora: ACDMA | J7: Versión del template: 7.00
H13: Administración General de Comunicaciones y Tecnologías de la Información
H15: Marco Documental 7.0
C16: Fecha de aprobación del Template: 01/11/2021 | E16: Requerimientos de Pruebas RDP Portal_Contribuyente_CFDI.xlsx | J16: Versión del template: 7.00
